<?xml version="1.0" ?>

<sdf version="1.6">
  <world name="SRC_finals">

    <physics type="ode">
      <real_time_update_rate>1000.0</real_time_update_rate>
      <max_step_size>0.001</max_step_size>
      <real_time_factor>1</real_time_factor>
      <ode>
        <solver>
          <type>quick</type>
          <iters>150</iters>
          <precon_iters>0</precon_iters>
          <sor>1.400000</sor>
          <use_dynamic_moi_rescaling>1</use_dynamic_moi_rescaling>
        </solver>
        <constraints>
          <cfm>0.000000</cfm>
          <erp>0.800000</erp>
          <contact_max_correcting_vel>2000.000000</contact_max_correcting_vel>
          <contact_surface_layer>0.01000</contact_surface_layer>
        </constraints>
      </ode>
    </physics>

    <!-- GUI -->
    <gui fullscreen='0'>
      <camera name='user_camera'>
        <pose>-4.1 -0.2 3.3 0 0.37 0</pose>
      </camera>
    </gui>

    <!-- Scene -->
    <scene>
      <background>0.968627451 0.690196078 0.384313725 1.0</background>
      <grid>0</grid>
      <origin_visual>0</origin_visual>
    </scene>

    <!-- A global light source -->
    <light type="directional" name="sun">
      <cast_shadows>true</cast_shadows>
      <pose>0 0 1000 0.04526742687440399 -1.4579058166242975 0</pose>
      <diffuse>0.8 0.8 0.8 1</diffuse>
      <specular>0.2 0.2 0.2 1</specular>
      <attenuation>
        <range>1000</range>
        <constant>0.9</constant>
        <linear>0.01</linear>
        <quadratic>0.001</quadratic>
      </attenuation>
      <direction>-0.5 0.1 -0.9</direction>
    </light>

    <!-- Background -->
    <include>
      <uri>model://heightmap_mars</uri>
    </include>

    <!-- START WALKWAY -->

    <!-- Walkway -->
    <include>
      <name>walkway_1</name>
      <pose>
      -0.3
      0
      -0.052151
      0
      0
      -1.5707963267948968
      </pose>
      <uri>model://walkway_metal_straight</uri>
    </include>


    <!-- Bling -->
    <include>
      <name>mars_rock_1_1</name>
      <pose>
      0.46199999999999986
      -1.1620000000000001
      0
      0
      0
      3.141592653589793
      </pose>
      <uri>model://mars_rock_1</uri>
    </include>


    <!-- Bling -->
    <include>
      <name>mars_crate_long_2</name>
      <pose>
      0.46200000000000035
      1.5619999999999998
      0
      0
      0
      0.785398163397448
      </pose>
      <uri>model://mars_crate_long</uri>
    </include>


    

    <!-- TASK 1 -->

    <!-- Walkway -->
    <include>
      <name>walkway_2</name>
      <pose>
      1.9860000000000002
      0.7619999999999996
      -0.052151
      0
      0
      3.141592653589793
      </pose>
      <uri>model://walkway_metal_90</uri>
    </include>


    <!-- Satellite -->
    

    

<model name="satellite_dish">

  <pose>
    4.748
    -9.225055520567841e-16
    0
    0
    0
    -1.5707963267948968
  </pose>

  <link name="base">
    <inertial>
      <pose>0 -0.6077 0.3193 0 0 0</pose>
      <inertia>
        <ixx>165.1022</ixx>
        <ixy>0</ixy>
        <ixz>0</ixz>
        <iyy>13.8377</iyy>
        <iyz>0</iyz>
        <izz>170.3359</izz>
      </inertia>
      <mass>400</mass>
    </inertial>
    <collision name="collision">
      <geometry>
        <mesh>
          <uri>model://satellite_dish/meshes/satellite_dish.dae</uri>
          <submesh>
            <name>Base</name>
          </submesh>
        </mesh>
      </geometry>
    </collision>
    <visual name="visual">
      <geometry>
        <mesh>
          <uri>model://satellite_dish/meshes/satellite_dish.dae</uri>
          <submesh>
            <name>Base</name>
          </submesh>
        </mesh>
      </geometry>
    </visual>
  </link>

  <link name="pivot">
    <pose>0 0 1.595 0 0 0</pose>
    <inertial>
      <inertia>
        <ixx>0.00073</ixx>
        <ixy>0</ixy>
        <ixz>0</ixz>
        <iyy>0.000598</iyy>
        <iyz>0</iyz>
        <izz>0.00057</izz>
      </inertia>
      <mass>0.82</mass>
    </inertial>
    <collision name="collision">
      <pose>0 0 -1.595 0 0 0</pose>
      <geometry>
        <mesh>
          <uri>model://satellite_dish/meshes/satellite_dish.dae</uri>
          <submesh>
            <name>Pivot</name>
          </submesh>
        </mesh>
      </geometry>
    </collision>
    <visual name="visual">
      <pose>0 0 -1.595 0 0 0</pose>
      <geometry>
        <mesh>
          <uri>model://satellite_dish/meshes/satellite_dish.dae</uri>
          <submesh>
            <name>Pivot</name>
          </submesh>
        </mesh>
      </geometry>
    </visual>
  </link>

  <link name="dish">
    <pose>0 0 1.595 0.43 0 0</pose>
    <inertial>
      <pose>0 0.2 0 0 0 0</pose>
      <inertia>
        <ixx>0.92468</ixx>
        <ixy>0</ixy>
        <ixz>0</ixz>
        <iyy>1.87729</iyy>
        <iyz>0</iyz>
        <izz>0.97826</izz>
      </inertia>
      <mass>17.0</mass>
    </inertial>
    <collision name="collision">
      <pose>0 -0.6519041 -1.451541 -0.43 0 0</pose>
      <geometry>
        <mesh>
          <uri>model://satellite_dish/meshes/satellite_dish.dae</uri>
          <submesh>
            <name>Dish</name>
          </submesh>
        </mesh>
      </geometry>
    </collision>
    <visual name="visual">
      <pose>0 -0.6519041 -1.451541 -0.43 0 0</pose>
      <geometry>
        <mesh>
          <uri>model://satellite_dish/meshes/satellite_dish.dae</uri>
          <submesh>
            <name>Dish</name>
          </submesh>
        </mesh>
      </geometry>
    </visual>
  </link>

  <link name="wheel_yaw">
    <pose>-0.2 -1.725 0.91 0.52 0 0</pose>
    <inertial>
      <inertia>
        <ixx>0.0123</ixx>
        <ixy>0</ixy>
        <ixz>0</ixz>
        <iyy>0.01295</iyy>
        <iyz>0</iyz>
        <izz>0.02500</izz>
      </inertia>
      <mass>2.0</mass>
    </inertial>
    <collision name="collision">
      <pose>0.2 1.060 -1.64 -0.52 0 0</pose>
      <geometry>
        <mesh>
          <uri>model://satellite_dish/meshes/satellite_dish.dae</uri>
          <submesh>
            <name>Wheel_01</name>
          </submesh>
        </mesh>
      </geometry>
    </collision>
    <collision name="collision_sphere">
      <pose>0.002 -0.123 0.082 0 0 0</pose>
      <geometry>
        <sphere>
          <radius>0.029</radius>
        </sphere>
      </geometry>
    </collision>
    <collision name="collision_cylinder">
      <pose>0.002 -0.122 0.025 0 0 0</pose>
      <geometry>
        <cylinder>
          <length>0.06</length>
          <radius>0.0125</radius>
        </cylinder>
      </geometry>
    </collision>
    <visual name="visual">
      <pose>0.2 1.060 -1.64 -0.52 0 0</pose>
      <geometry>
        <mesh>
          <uri>model://satellite_dish/meshes/satellite_dish.dae</uri>
          <submesh>
            <name>Wheel_01</name>
          </submesh>
        </mesh>
      </geometry>
    </visual>
  </link>

  <link name="wheel_pitch">
    <pose>0.2 -1.725 0.91 0.52 0 0</pose>
    <inertial>
      <inertia>
        <ixx>0.0123</ixx>
        <ixy>0</ixy>
        <ixz>0</ixz>
        <iyy>0.01295</iyy>
        <iyz>0</iyz>
        <izz>0.02500</izz>
      </inertia>
      <mass>2.0</mass>
    </inertial>
    <collision name="collision">
      <pose>-0.2 1.060 -1.64 -0.52 0 0</pose>
      <geometry>
        <mesh>
          <uri>model://satellite_dish/meshes/satellite_dish.dae</uri>
          <submesh>
            <name>Wheel_02</name>
          </submesh>
        </mesh>
      </geometry>
    </collision>
    <collision name="collision_sphere">
      <pose>-0.002 -0.123 0.082 0 0 0</pose>
      <geometry>
        <sphere>
          <radius>0.029</radius>
        </sphere>
      </geometry>
    </collision>
    <collision name="collision_cylinder">
      <pose>-0.002 -0.122 0.025 0 0 0</pose>
      <geometry>
        <cylinder>
          <length>0.06</length>
          <radius>0.0125</radius>
        </cylinder>
      </geometry>
    </collision>
    <visual name="visual">
      <pose>-0.2 1.060 -1.64 -0.52 0 0</pose>
      <geometry>
        <mesh>
          <uri>model://satellite_dish/meshes/satellite_dish.dae</uri>
          <submesh>
            <name>Wheel_02</name>
          </submesh>
        </mesh>
      </geometry>
    </visual>
  </link>

  <joint name="dish_yaw" type="revolute">
    <parent>base</parent>
    <child>pivot</child>
    <axis>
      <xyz>0 0 1</xyz>
      <dynamics>
        <damping>1000</damping>
      </dynamics>
    </axis>
  </joint>

  <joint name="dish_pitch" type="revolute">
    <parent>pivot</parent>
    <child>dish</child>
    <axis>
      <xyz>1 0 0</xyz>
      <limit>
        <lower>-0.2</lower>
        <upper>1.57</upper>
      </limit>
      <dynamics>
        <damping>100</damping>
      </dynamics>
    </axis>
  </joint>

  <joint name="wheel_yaw" type="revolute">
    <parent>base</parent>
    <child>wheel_yaw</child>
    <axis>
      <xyz>0 0 1</xyz>
      <dynamics>
        <friction>2.118062029710349</friction>
      </dynamics>
    </axis>
  </joint>

  <joint name="wheel_pitch" type="revolute">
    <parent>base</parent>
    <child>wheel_pitch</child>
    <axis>
      <xyz>0 0 1</xyz>
      <dynamics>
        <friction>2.832760567829501</friction>
      </dynamics>
    </axis>
  </joint>

  <joint name="satellite_world" type="fixed">
    <parent>world</parent>
    <child>base</child>
  </joint>

  <plugin name="satellite_plugin" filename="libSatellitePlugin.so">

    <yaw_ratio>0.1</yaw_ratio>
    <yaw_pid>1000 0 10</yaw_pid>
    <yaw_target>-0.8248220637911257</yaw_target>

    <pitch_ratio>0.1</pitch_ratio>
    <pitch_pid>1000 100 10</pitch_pid>
    <pitch_target>0.3628962916653741</pitch_target>

    <!-- Tolerance in degrees -->
    <tolerance>5</tolerance>

    <!-- Target time to hold position in seconds -->
    <time>5</time>

    <topic>/task1/checkpoint2/satellite</topic>
    <frequency>100</frequency>

  </plugin>

</model>


    <!-- Checkpoint 1 - Box plugin -->
    

    <plugin name="boxT1CP1" filename="libBoxContainsPlugin.so">
      <entity>valkyrie</entity>
      <namespace>task1/checkpoint1</namespace>
      <pose>
        2.548
        -5.183721083381576e-16
        2.5
        0
        0
        -2.4492935982947064e-16
      </pose>
      <size>1 1 5.0</size>
    </plugin>

    <!-- Bling -->
    <include>
      <name>mars_rock_3_3</name>
      <pose>
      1.9859999999999998
      -1.8620000000000005
      0
      0
      0
      3.141592653589793
      </pose>
      <uri>model://mars_rock_3</uri>
    </include>


    <!-- Walkway -->
    <include>
      <name>walkway_3</name>
      <pose>
      1.9860000000000002
      0.7619999999999996
      -0.052151
      0
      0
      -2.449293598294706e-16
      </pose>
      <uri>model://walkway_metal_straight</uri>
    </include>


    <!-- Bling -->
    <include>
      <name>mars_rock_1_4</name>
      <pose>
      3.148
      1.5239999999999994
      0
      0
      0
      -1.5707963267948968
      </pose>
      <uri>model://mars_rock_1</uri>
    </include>


    <!-- Bling -->
    <include>
      <name>mars_crate_5</name>
      <pose>
      0.8240000000000004
      1.524
      0
      0
      0
      1.5707963267948963
      </pose>
      <uri>model://mars_crate</uri>
    </include>


    <!-- Final box 1 -->
    <include>
      <name>walkway_4</name>
      <pose>
      1.986000000000001
      3.8099999999999996
      -0.052151
      0
      0
      -1.5707963267948968
      </pose>
      <uri>model://walkway_finish_adjacent</uri>
    </include>


    <!-- Checkpoint 3 - Box plugin -->
    <plugin name="boxT1CP3" filename="libBoxContainsPlugin.so">
      <entity>valkyrie</entity>
      <namespace>task1/checkpoint3</namespace>
      <pose>
        1.986000000000001
        3.8099999999999996
        2.5
        0
        0
        -1.5707963267948968
      </pose>
      <size>3.048 3.048 5.0</size>
    </plugin>

    <!-- Bling -->
    <include>
      <name>mars_crate_long_6</name>
      <pose>
      -0.33799999999999897
      3.8100000000000005
      0
      0
      0
      2.3561944901923444
      </pose>
      <uri>model://mars_crate_long</uri>
    </include>


    <!-- Bling -->
    <include>
      <name>mars_rock_1_7</name>
      <pose>
      1.9860000000000013
      5.734
      0
      0
      0
      -2.449293598294706e-16
      </pose>
      <uri>model://mars_rock_1</uri>
    </include>


    

    <!-- /TASK 1 -->
    

    

    <!-- TASK 2 -->

    <!-- Walkway -->
    <include>
      <name>walkway_5</name>
      <pose>
      3.510000000000001
      3.809999999999999
      -0.052151
      0
      0
      -1.5707963267948968
      </pose>
      <uri>model://walkway_metal_straight</uri>
    </include>


    <!-- Walkway -->
    <include>
      <name>walkway_6</name>
      <pose>
      6.334734000000001
      4.349470091999999
      -0.052151
      0
      0
      2.356194490192345
      </pose>
      <uri>model://walkway_metal_45</uri>
    </include>


    <!-- Rover -->
    

    <include>
      <pose>
        9.516714515339466
        0.08985884213223638
        0
        0
        0
        0.7853981633974481
      </pose>
      <uri>model://mars_explorer</uri>
    </include>

    <!-- Solar panel -->
    

    

<model name="solar_panel">

  <pose>
    6.193312643762692
    3.4132607137090103
    0.46
    0
    0
    -0.21877283023220448
  </pose>

  <link name="base">

    <inertial>
      <pose>
      0
      0
      0.04
      0
      0
      0
      </pose>
      <inertia>
        <ixx>0.0041666666666666675</ixx>
        <iyy>0.05577866666666667</iyy>
        <izz>0.05827866666666667</izz>
      </inertia>
      <mass>4.0</mass>
    </inertial>


    <collision name="collision">
      <geometry>
        <mesh>
          <uri>model://solar_panel/meshes/solar_panel.obj</uri>
          <submesh>
            <name>Base</name>
          </submesh>
          <scale>0.001 0.001 0.001</scale>
        </mesh>
      </geometry>
      <surface>
        <contact>
          <ode>
            <kp>1e5</kp>
            <kd>1</kd>
            <max_vel>0.1</max_vel>
            <min_depth>0.0015</min_depth>
          </ode>
        </contact>
      </surface>
    </collision>
    <visual name="visual">
      <geometry>
        <mesh>
          <uri>model://solar_panel/meshes/solar_panel.obj</uri>
          <submesh>
            <name>Base</name>
          </submesh>
          <scale>0.001 0.001 0.001</scale>
        </mesh>
      </geometry>
    </visual>

    <sensor name="base_sensor" type="contact">
      <contact>
        <collision>collision</collision>
      </contact>
    </sensor>

  </link>

  <link name="panel_01">

    <inertial>
      <pose>
      0
      0.05
      0.24
      0
      0
      0
      </pose>
      <inertia>
        <ixx>0.00237075</ixx>
        <iyy>0.005786083333333334</iyy>
        <izz>0.003452833333333334</izz>
      </inertia>
      <mass>0.25</mass>
    </inertial>


    <collision name="panel_collision">
      <geometry>
        <mesh>
          <uri>model://solar_panel/meshes/solar_panel.obj</uri>
          <submesh>
            <name>Panel_Large_01</name>
          </submesh>
          <scale>0.001 0.001 0.001</scale>
        </mesh>
      </geometry>
      <surface>
        <contact>
          <ode>
            <kp>1e5</kp>
            <kd>1</kd>
            <max_vel>0.1</max_vel>
            <min_depth>0.0015</min_depth>
          </ode>
        </contact>
      </surface>
    </collision>
    <visual name="panel_visual">
      <geometry>
        <mesh>
          <uri>model://solar_panel/meshes/solar_panel.obj</uri>
          <submesh>
            <name>Panel_Large_01</name>
          </submesh>
          <scale>0.001 0.001 0.001</scale>
        </mesh>
      </geometry>
    </visual>
    <collision name="button_housing_collision">
      <geometry>
        <mesh>
          <uri>model://solar_panel/meshes/solar_panel.obj</uri>
          <submesh>
            <name>ButtonHousing</name>
          </submesh>
          <scale>0.001 0.001 0.001</scale>
        </mesh>
      </geometry>
      <surface>
        <contact>
          <ode>
            <kp>1e5</kp>
            <kd>1</kd>
            <max_vel>0.1</max_vel>
            <min_depth>0.0015</min_depth>
          </ode>
        </contact>
      </surface>
    </collision>
    <visual name="button_housing_visual">
      <geometry>
        <mesh>
          <uri>model://solar_panel/meshes/solar_panel.obj</uri>
          <submesh>
            <name>ButtonHousing</name>
          </submesh>
          <scale>0.001 0.001 0.001</scale>
        </mesh>
      </geometry>
    </visual>

    <sensor name="panel1_sensor" type="contact">
      <contact>
        <collision>panel_collision</collision>
      </contact>
    </sensor>

  </link>


  <link name="panel_02">

    <inertial>
      <pose>
      0
      -0.05
      0.24
      0
      0
      0
      </pose>
      <inertia>
        <ixx>0.00237075</ixx>
        <iyy>0.005786083333333334</iyy>
        <izz>0.003452833333333334</izz>
      </inertia>
      <mass>0.25</mass>
    </inertial>


    <collision name="collision">
      <geometry>
        <mesh>
          <uri>model://solar_panel/meshes/solar_panel.obj</uri>
          <submesh>
            <name>Panel_Large_02</name>
          </submesh>
          <scale>0.001 0.001 0.001</scale>
        </mesh>
      </geometry>
      <surface>
        <contact>
          <ode>
            <kp>1e5</kp>
            <kd>1</kd>
            <max_vel>0.1</max_vel>
            <min_depth>0.0015</min_depth>
          </ode>
        </contact>
      </surface>
    </collision>
    <visual name="visual">
      <geometry>
        <mesh>
          <uri>model://solar_panel/meshes/solar_panel.obj</uri>
          <submesh>
            <name>Panel_Large_02</name>
          </submesh>
          <scale>0.001 0.001 0.001</scale>
        </mesh>
      </geometry>
    </visual>

    <collision name="outlet">
      <pose>0.13675 0 0.369 1.5707963267948966 0 0</pose>
      <geometry>
        <cylinder>
          <length>0.003222</length>
          <radius>0.018693</radius>
        </cylinder>
      </geometry>
      <surface>
        <contact>
          <ode>
            <kp>1e5</kp>
            <kd>1</kd>
            <max_vel>0.1</max_vel>
            <min_depth>0.0015</min_depth>
          </ode>
        </contact>
      </surface>
    </collision>

    <sensor name="panel2_sensor" type="contact">
      <contact>
        <collision>collision</collision>
      </contact>
    </sensor>

    <sensor name="outlet_sensor" type="contact">
      <contact>
        <collision>outlet</collision>
      </contact>
    </sensor>

  </link>

  <link name="panel_small_01">

    <pose>0.2 0.03 0.2 0 0 0</pose>

    <inertial>
      <pose>
      -0.1
      -0.015
      0.005
      0
      0
      0
      </pose>
      <inertia>
        <ixx>0.0004852083333333333</ixx>
        <iyy>0.0008133333333333333</iyy>
        <izz>0.00033854166666666673</izz>
      </inertia>
      <mass>0.1</mass>
    </inertial>


    <collision name="collision">
      <pose>-0.2 -0.03 -0.2 0 0 0</pose>
      <geometry>
        <mesh>
          <uri>model://solar_panel/meshes/solar_panel.obj</uri>
          <submesh>
            <name>Panel_Small_01</name>
          </submesh>
          <scale>0.001 0.001 0.001</scale>
        </mesh>
      </geometry>
      <surface>
        <contact>
          <ode>
            <kp>1e5</kp>
            <kd>1</kd>
            <max_vel>0.1</max_vel>
            <min_depth>0.0015</min_depth>
          </ode>
        </contact>
      </surface>
    </collision>
    <visual name="visual">
      <pose>-0.2 -0.03 -0.2 0 0 0</pose>
      <geometry>
        <mesh>
          <uri>model://solar_panel/meshes/solar_panel.obj</uri>
          <submesh>
            <name>Panel_Small_01</name>
          </submesh>
          <scale>0.001 0.001 0.001</scale>
        </mesh>
      </geometry>
    </visual>
  </link>

  <link name="panel_small_02">

    <pose>0.2 -0.03 0.2 0 0 0</pose>

    <inertial>
      <pose>
      -0.1
      0.015
      0.005
      0
      0
      0
      </pose>
      <inertia>
        <ixx>0.0004852083333333333</ixx>
        <iyy>0.0008133333333333333</iyy>
        <izz>0.00033854166666666673</izz>
      </inertia>
      <mass>0.1</mass>
    </inertial>


    <collision name="collision">
      <pose>-0.2 0.03 -0.2 0 0 0</pose>
      <geometry>
        <mesh>
          <uri>model://solar_panel/meshes/solar_panel.obj</uri>
          <submesh>
            <name>Panel_Small_02</name>
          </submesh>
          <scale>0.001 0.001 0.001</scale>
        </mesh>
      </geometry>
      <surface>
        <contact>
          <ode>
            <kp>1e5</kp>
            <kd>1</kd>
            <max_vel>0.1</max_vel>
            <min_depth>0.0015</min_depth>
          </ode>
        </contact>
      </surface>
    </collision>
    <visual name="visual">
      <pose>-0.2 0.03 -0.2 0 0 0</pose>
      <geometry>
        <mesh>
          <uri>model://solar_panel/meshes/solar_panel.obj</uri>
          <submesh>
            <name>Panel_Small_02</name>
          </submesh>
          <scale>0.001 0.001 0.001</scale>
        </mesh>
      </geometry>
    </visual>
  </link>

  <link name="panel_small_03">

    <pose>-0.2 0.03 0.2 0 0 0</pose>

    <inertial>
      <pose>
      0.1
      -0.015
      0.005
      0
      0
      0
      </pose>
      <inertia>
        <ixx>0.0004852083333333333</ixx>
        <iyy>0.0008133333333333333</iyy>
        <izz>0.00033854166666666673</izz>
      </inertia>
      <mass>0.1</mass>
    </inertial>


    <collision name="collision">
      <pose>0.2 -0.03 -0.2 0 0 0</pose>
      <geometry>
        <mesh>
          <uri>model://solar_panel/meshes/solar_panel.obj</uri>
          <submesh>
            <name>Panel_Small_03</name>
          </submesh>
          <scale>0.001 0.001 0.001</scale>
        </mesh>
      </geometry>
      <surface>
        <contact>
          <ode>
            <kp>1e5</kp>
            <kd>1</kd>
            <max_vel>0.1</max_vel>
            <min_depth>0.0015</min_depth>
          </ode>
        </contact>
      </surface>
    </collision>
    <visual name="visual">
      <pose>0.2 -0.03 -0.2 0 0 0</pose>
      <geometry>
        <mesh>
          <uri>model://solar_panel/meshes/solar_panel.obj</uri>
          <submesh>
            <name>Panel_Small_03</name>
          </submesh>
          <scale>0.001 0.001 0.001</scale>
        </mesh>
      </geometry>
    </visual>
  </link>

  <link name="panel_small_04">

    <pose>-0.2 -0.03 0.2 0 0 0</pose>

    <inertial>
      <pose>
      0.1
      0.015
      0.005
      0
      0
      0
      </pose>
      <inertia>
        <ixx>0.0004852083333333333</ixx>
        <iyy>0.0008133333333333333</iyy>
        <izz>0.00033854166666666673</izz>
      </inertia>
      <mass>0.1</mass>
    </inertial>


    <collision name="collision">
      <pose>0.2 0.03 -0.2 0 0 0</pose>
      <geometry>
        <mesh>
          <uri>model://solar_panel/meshes/solar_panel.obj</uri>
          <submesh>
            <name>Panel_Small_04</name>
          </submesh>
          <scale>0.001 0.001 0.001</scale>
        </mesh>
      </geometry>
      <surface>
        <contact>
          <ode>
            <kp>1e5</kp>
            <kd>1</kd>
            <max_vel>0.1</max_vel>
            <min_depth>0.0015</min_depth>
          </ode>
        </contact>
      </surface>
    </collision>
    <visual name="visual">
      <pose>0.2 0.03 -0.2 0 0 0</pose>
      <geometry>
        <mesh>
          <uri>model://solar_panel/meshes/solar_panel.obj</uri>
          <submesh>
            <name>Panel_Small_04</name>
          </submesh>
          <scale>0.001 0.001 0.001</scale>
        </mesh>
      </geometry>
    </visual>
  </link>


  <link name="button">

    <pose>-0.155 0 0.4 0 0 0</pose>

    <inertial>
      <pose>
      0
      0
      0.017
      0
      0
      0
      </pose>
      <inertia>
        <ixx>4.8333333333333334e-05</ixx>
        <iyy>4.8333333333333334e-05</iyy>
        <izz>8.166666666666668e-05</izz>
      </inertia>
      <mass>0.1</mass>
    </inertial>


    <collision name="collision">
      <pose>0.155 0 -0.4 0 0 0</pose>
      <geometry>
        <mesh>
          <uri>model://solar_panel/meshes/solar_panel.obj</uri>
          <submesh>
            <name>Button</name>
          </submesh>
          <scale>0.001 0.001 0.001</scale>
        </mesh>
      </geometry>
      <surface>
        <contact>
          <ode>
            <kp>1e5</kp>
            <kd>1</kd>
            <max_vel>0.1</max_vel>
            <min_depth>0.0015</min_depth>
          </ode>
        </contact>
      </surface>
    </collision>
    <visual name="visual">
      <pose>0.155 0 -0.4 0 0 0</pose>
      <geometry>
        <mesh>
          <uri>model://solar_panel/meshes/solar_panel.obj</uri>
          <submesh>
            <name>Button</name>
          </submesh>
          <scale>0.001 0.001 0.001</scale>
        </mesh>
      </geometry>
    </visual>

    <sensor name="button_contact" type="contact">
      <contact>
        <collision>collision</collision>
      </contact>
    </sensor>

  </link>

  

  <joint name="base_panel_01" type="revolute">
    <pose>0 0.0455 0.095 0 0 0</pose>
    <parent>base</parent>
    <child>panel_01</child>
    <axis>
      <xyz>1 0 0</xyz>
      <limit>
       <lower>-1.5707963267948966</lower>
       <upper>0</upper>
      </limit>
      <dynamics>
        <damping>0.1</damping>
      </dynamics>
    </axis>
  </joint>

  <joint name="base_panel_02" type="revolute">
    <pose>0 -0.0455 0.095 0 0 0</pose>
    <parent>base</parent>
    <child>panel_02</child>
    <axis>
      <xyz>1 0 0</xyz>
      <limit>
       <lower>0</lower>
       <upper>1.5707963267948966</upper>
      </limit>
      <dynamics>
        <damping>0.1</damping>
      </dynamics>
    </axis>
  </joint>

  <joint name="panel_01_panel_small_01" type="revolute">
    <parent>panel_01</parent>
    <child>panel_small_01</child>
    <axis>
      <xyz>0 0 1</xyz>
      <limit>
       <lower>0</lower>
       <upper>3.141592653589793</upper>
      </limit>
      <dynamics>
        <damping>0.1</damping>
      </dynamics>
    </axis>
  </joint>

  <joint name="panel_02_panel_small_02" type="revolute">
    <parent>panel_02</parent>
    <child>panel_small_02</child>
    <axis>
      <xyz>0 0 1</xyz>
      <limit>
       <lower>-3.141592653589793</lower>
       <upper>0</upper>
      </limit>
      <dynamics>
        <damping>0.1</damping>
      </dynamics>
    </axis>
  </joint>

  <joint name="panel_01_panel_small_03" type="revolute">
    <parent>panel_01</parent>
    <child>panel_small_03</child>
    <axis>
      <xyz>0 0 1</xyz>
      <limit>
       <lower>-3.141592653589793</lower>
       <upper>0</upper>
      </limit>
      <dynamics>
        <damping>0.1</damping>
      </dynamics>
    </axis>
  </joint>

  <joint name="panel_02_panel_small_04" type="revolute">
    <parent>panel_02</parent>
    <child>panel_small_04</child>
    <axis>
      <xyz>0 0 1</xyz>
      <limit>
       <lower>0</lower>
       <upper>3.141592653589793</upper>
      </limit>
      <dynamics>
        <damping>0.1</damping>
      </dynamics>
    </axis>
  </joint>

  
  <joint name="button" type="prismatic">
    <pose>0 0 0.005 0 0 0</pose>
    <parent>panel_01</parent>
    <child>button</child>
    <axis>
      <xyz>0 0 1</xyz>
      <limit>
       <lower>-0.005</lower>
       <upper>0</upper>
      </limit>
      <dynamics>
        <damping>10</damping>
        <spring_stiffness>1000</spring_stiffness>
        <spring_reference>0</spring_reference>
      </dynamics>
    </axis>
  </joint>

  <joint name="lock_1" type="fixed">
    <parent>panel_01</parent>
    <child>panel_02</child>
  </joint>

  <joint name="lock_2" type="fixed">
    <parent>panel_small_01</parent>
    <child>panel_small_03</child>
  </joint>

  <joint name="lock_3" type="fixed">
    <parent>panel_small_02</parent>
    <child>panel_small_04</child>
  </joint>

  <plugin name="solar_panel_plugin" filename="libSolarPanelPlugin.so">
  </plugin>

  <plugin name="touch_valkyrie_panel" filename="libTouchPlugin.so">
    <sensor>base_sensor</sensor>
    <sensor>panel1_sensor</sensor>
    <sensor>panel2_sensor</sensor>
    <target>valkyrie</target>
    <time>5</time>
    <namespace>task2/checkpoint1</namespace>
  </plugin>

</model>


    <!-- Bling -->
    

    <!-- Walkway -->
    <include>
      <name>walkway_7</name>
      <pose>
      6.334734000000001
      4.349470091999999
      -0.052151
      0
      0
      -0.7853981633974485
      </pose>
      <uri>model://walkway_metal_45</uri>
    </include>


    <!-- Walkway -->
    <include>
      <name>walkway_8</name>
      <pose>
      7.635954792220435
      4.887764963619371
      -0.052151
      0
      0
      -1.5707963267948968
      </pose>
      <uri>model://walkway_metal_straight</uri>
    </include>


    <!-- Bling -->
    <include>
      <name>mars_rock_1_8</name>
      <pose>
      8.397954792220435
      6.049764963619371
      0
      0
      0
      -2.83276944882399e-16
      </pose>
      <uri>model://mars_rock_1</uri>
    </include>


    <!-- Bling -->
    <include>
      <name>mars_rock_2_9</name>
      <pose>
      8.397954792220435
      3.6257649636193703
      0
      0
      0
      3.141592653589793
      </pose>
      <uri>model://mars_rock_2</uri>
    </include>


    <!-- Walkway -->
    <include>
      <name>walkway_9</name>
      <pose>
      10.460688792220436
      5.42723505561937
      -0.052151
      0
      0
      2.356194490192345
      </pose>
      <uri>model://walkway_metal_45</uri>
    </include>


    <!-- Solar Array -->
    

    <include>
      <pose>
        10.849597521873036
        3.96069559143847
        0
        0
        0
        -2.356194490192345
      </pose>
      <uri>model://solar_array</uri>
    </include>

    <!-- Cable -->
    

    

<model name="solar_panel_cable">

  <self_collide>true</self_collide>

  <pose>
    10.991018878110346
    3.2535888102519226
    0.85
    0
    0
    2.356194490192345
  </pose>

  <link name="link_0">
    <inertial>
      <mass>0.05</mass>
      <inertia>
        <ixx>0.0001</ixx>
        <iyy>0.0001</iyy>
        <izz>0.0001</izz>
      </inertia>
    </inertial>
    <visual name="visual">
      <geometry>
        <sphere>
          <radius>0.02</radius>
        </sphere>
      </geometry>
      <material>
        <ambient>0 0 0 1</ambient>
        <emissive>0 0 0 1</emissive>
        <diffuse>0 0 0 1</diffuse>
        <specular>1 1 1 1</specular>
      </material>
    </visual>
  </link>

  

  <link name="link_1">
    <pose>0.0 0 0 0 1.5707963267948966 0.9424777960769379</pose>
    <inertial>
      <pose>0 0 0.05 0 0 0</pose>
      <mass>0.05</mass>
      <inertia>
        <ixx>0.0001</ixx>
        <iyy>0.0001</iyy>
        <izz>0.0001</izz>
      </inertia>
    </inertial>
    <collision name="cylinder">
      <pose>0 0 0.05 0 0 0</pose>
      <geometry>
        <cylinder>
          <length>0.1</length>
          <radius>0.01</radius>
        </cylinder>
      </geometry>
      <surface>
        <contact>
          <ode>
            <kp>1e5</kp>
            <kd>1</kd>
            <max_vel>0.1</max_vel>
            <min_depth>0.0015</min_depth>
          </ode>
        </contact>
        <friction>
          <ode>
            <mu>1.0</mu>
            <mu2>1.0</mu2>
          </ode>
        </friction>
      </surface>
    </collision>
    <collision name="sphere">
      <geometry>
        <sphere>
          <radius>0.01</radius>
        </sphere>
      </geometry>
      <surface>
        <contact>
          <ode>
            <kp>1e5</kp>
            <kd>1</kd>
            <max_vel>0.1</max_vel>
            <min_depth>0.0015</min_depth>
          </ode>
        </contact>
        <friction>
          <ode>
            <mu>1.0</mu>
            <mu2>1.0</mu2>
          </ode>
        </friction>
      </surface>
    </collision>
    <visual name="cylinder">
      <pose>0 0 0.05 0 0 0</pose>
      <geometry>
        <cylinder>
          <length>0.1</length>
          <radius>0.01</radius>
        </cylinder>
      </geometry>
      <material>
        <ambient>0 0 0 1</ambient>
        <emissive>0 0 0 1</emissive>
        <diffuse>0.1 0.1 0.1 1</diffuse>
        <specular>1 1 1 1</specular>
      </material>
    </visual>
    <visual name="sphere">
      <geometry>
        <sphere>
          <radius>0.01</radius>
        </sphere>
      </geometry>
      <material>
        <ambient>0 0 0 1</ambient>
        <emissive>0 0 0 1</emissive>
        <diffuse>0.1 0.1 0.1 1</diffuse>
        <specular>1 1 1 1</specular>
      </material>
    </visual>

    

  </link>

  <joint name="joint_1" type="universal">
    <child>link_1</child>
    <parent>link_0</parent>
    <axis>
      <xyz>0 1 0</xyz>
      <limit>
        <lower>-1.5707963267948966</lower>
        <upper>1.5707963267948966</upper>
      </limit>
    </axis>
    <axis2>
      <xyz>-1 0 0</xyz>
      <limit>
        <lower>-1.5707963267948966</lower>
        <upper>1.5707963267948966</upper>
      </limit>
    </axis2>
    <physics>
      <ode>
        <cfm_damping>1</cfm_damping>
      </ode>
    </physics>
  </joint>

  

  <link name="link_2">
    <pose>0.058778525229247314 0.08090169943749476 0 0 1.5707963267948966 -0.9424777960769379</pose>
    <inertial>
      <pose>0 0 0.05 0 0 0</pose>
      <mass>0.05</mass>
      <inertia>
        <ixx>0.0001</ixx>
        <iyy>0.0001</iyy>
        <izz>0.0001</izz>
      </inertia>
    </inertial>
    <collision name="cylinder">
      <pose>0 0 0.05 0 0 0</pose>
      <geometry>
        <cylinder>
          <length>0.1</length>
          <radius>0.01</radius>
        </cylinder>
      </geometry>
      <surface>
        <contact>
          <ode>
            <kp>1e5</kp>
            <kd>1</kd>
            <max_vel>0.1</max_vel>
            <min_depth>0.0015</min_depth>
          </ode>
        </contact>
        <friction>
          <ode>
            <mu>1.0</mu>
            <mu2>1.0</mu2>
          </ode>
        </friction>
      </surface>
    </collision>
    <collision name="sphere">
      <geometry>
        <sphere>
          <radius>0.01</radius>
        </sphere>
      </geometry>
      <surface>
        <contact>
          <ode>
            <kp>1e5</kp>
            <kd>1</kd>
            <max_vel>0.1</max_vel>
            <min_depth>0.0015</min_depth>
          </ode>
        </contact>
        <friction>
          <ode>
            <mu>1.0</mu>
            <mu2>1.0</mu2>
          </ode>
        </friction>
      </surface>
    </collision>
    <visual name="cylinder">
      <pose>0 0 0.05 0 0 0</pose>
      <geometry>
        <cylinder>
          <length>0.1</length>
          <radius>0.01</radius>
        </cylinder>
      </geometry>
      <material>
        <ambient>0 0 0 1</ambient>
        <emissive>0 0 0 1</emissive>
        <diffuse>0.1 0.1 0.1 1</diffuse>
        <specular>1 1 1 1</specular>
      </material>
    </visual>
    <visual name="sphere">
      <geometry>
        <sphere>
          <radius>0.01</radius>
        </sphere>
      </geometry>
      <material>
        <ambient>0 0 0 1</ambient>
        <emissive>0 0 0 1</emissive>
        <diffuse>0.1 0.1 0.1 1</diffuse>
        <specular>1 1 1 1</specular>
      </material>
    </visual>

    

  </link>

  <joint name="joint_2" type="universal">
    <child>link_2</child>
    <parent>link_1</parent>
    <axis>
      <xyz>0 1 0</xyz>
      <limit>
        <lower>-1.5707963267948966</lower>
        <upper>1.5707963267948966</upper>
      </limit>
    </axis>
    <axis2>
      <xyz>-1 0 0</xyz>
      <limit>
        <lower>-1.5707963267948966</lower>
        <upper>1.5707963267948966</upper>
      </limit>
    </axis2>
    <physics>
      <ode>
        <cfm_damping>1</cfm_damping>
      </ode>
    </physics>
  </joint>

  

  <link name="link_3">
    <pose>0.11755705045849463 0 0 0 1.5707963267948966 -0.9424777960769379</pose>
    <inertial>
      <pose>0 0 0.05 0 0 0</pose>
      <mass>0.05</mass>
      <inertia>
        <ixx>0.0001</ixx>
        <iyy>0.0001</iyy>
        <izz>0.0001</izz>
      </inertia>
    </inertial>
    <collision name="cylinder">
      <pose>0 0 0.05 0 0 0</pose>
      <geometry>
        <cylinder>
          <length>0.1</length>
          <radius>0.01</radius>
        </cylinder>
      </geometry>
      <surface>
        <contact>
          <ode>
            <kp>1e5</kp>
            <kd>1</kd>
            <max_vel>0.1</max_vel>
            <min_depth>0.0015</min_depth>
          </ode>
        </contact>
        <friction>
          <ode>
            <mu>1.0</mu>
            <mu2>1.0</mu2>
          </ode>
        </friction>
      </surface>
    </collision>
    <collision name="sphere">
      <geometry>
        <sphere>
          <radius>0.01</radius>
        </sphere>
      </geometry>
      <surface>
        <contact>
          <ode>
            <kp>1e5</kp>
            <kd>1</kd>
            <max_vel>0.1</max_vel>
            <min_depth>0.0015</min_depth>
          </ode>
        </contact>
        <friction>
          <ode>
            <mu>1.0</mu>
            <mu2>1.0</mu2>
          </ode>
        </friction>
      </surface>
    </collision>
    <visual name="cylinder">
      <pose>0 0 0.05 0 0 0</pose>
      <geometry>
        <cylinder>
          <length>0.1</length>
          <radius>0.01</radius>
        </cylinder>
      </geometry>
      <material>
        <ambient>0 0 0 1</ambient>
        <emissive>0 0 0 1</emissive>
        <diffuse>0.1 0.1 0.1 1</diffuse>
        <specular>1 1 1 1</specular>
      </material>
    </visual>
    <visual name="sphere">
      <geometry>
        <sphere>
          <radius>0.01</radius>
        </sphere>
      </geometry>
      <material>
        <ambient>0 0 0 1</ambient>
        <emissive>0 0 0 1</emissive>
        <diffuse>0.1 0.1 0.1 1</diffuse>
        <specular>1 1 1 1</specular>
      </material>
    </visual>

    

  </link>

  <joint name="joint_3" type="universal">
    <child>link_3</child>
    <parent>link_2</parent>
    <axis>
      <xyz>0 1 0</xyz>
      <limit>
        <lower>-1.5707963267948966</lower>
        <upper>1.5707963267948966</upper>
      </limit>
    </axis>
    <axis2>
      <xyz>-1 0 0</xyz>
      <limit>
        <lower>-1.5707963267948966</lower>
        <upper>1.5707963267948966</upper>
      </limit>
    </axis2>
    <physics>
      <ode>
        <cfm_damping>1</cfm_damping>
      </ode>
    </physics>
  </joint>

  

  <link name="link_4">
    <pose>0.17633557568774197 -0.08090169943749476 0 0 1.5707963267948966 0.9424777960769379</pose>
    <inertial>
      <pose>0 0 0.05 0 0 0</pose>
      <mass>0.05</mass>
      <inertia>
        <ixx>0.0001</ixx>
        <iyy>0.0001</iyy>
        <izz>0.0001</izz>
      </inertia>
    </inertial>
    <collision name="cylinder">
      <pose>0 0 0.05 0 0 0</pose>
      <geometry>
        <cylinder>
          <length>0.1</length>
          <radius>0.01</radius>
        </cylinder>
      </geometry>
      <surface>
        <contact>
          <ode>
            <kp>1e5</kp>
            <kd>1</kd>
            <max_vel>0.1</max_vel>
            <min_depth>0.0015</min_depth>
          </ode>
        </contact>
        <friction>
          <ode>
            <mu>1.0</mu>
            <mu2>1.0</mu2>
          </ode>
        </friction>
      </surface>
    </collision>
    <collision name="sphere">
      <geometry>
        <sphere>
          <radius>0.01</radius>
        </sphere>
      </geometry>
      <surface>
        <contact>
          <ode>
            <kp>1e5</kp>
            <kd>1</kd>
            <max_vel>0.1</max_vel>
            <min_depth>0.0015</min_depth>
          </ode>
        </contact>
        <friction>
          <ode>
            <mu>1.0</mu>
            <mu2>1.0</mu2>
          </ode>
        </friction>
      </surface>
    </collision>
    <visual name="cylinder">
      <pose>0 0 0.05 0 0 0</pose>
      <geometry>
        <cylinder>
          <length>0.1</length>
          <radius>0.01</radius>
        </cylinder>
      </geometry>
      <material>
        <ambient>0 0 0 1</ambient>
        <emissive>0 0 0 1</emissive>
        <diffuse>0.1 0.1 0.1 1</diffuse>
        <specular>1 1 1 1</specular>
      </material>
    </visual>
    <visual name="sphere">
      <geometry>
        <sphere>
          <radius>0.01</radius>
        </sphere>
      </geometry>
      <material>
        <ambient>0 0 0 1</ambient>
        <emissive>0 0 0 1</emissive>
        <diffuse>0.1 0.1 0.1 1</diffuse>
        <specular>1 1 1 1</specular>
      </material>
    </visual>

    

  </link>

  <joint name="joint_4" type="universal">
    <child>link_4</child>
    <parent>link_3</parent>
    <axis>
      <xyz>0 1 0</xyz>
      <limit>
        <lower>-1.5707963267948966</lower>
        <upper>1.5707963267948966</upper>
      </limit>
    </axis>
    <axis2>
      <xyz>-1 0 0</xyz>
      <limit>
        <lower>-1.5707963267948966</lower>
        <upper>1.5707963267948966</upper>
      </limit>
    </axis2>
    <physics>
      <ode>
        <cfm_damping>1</cfm_damping>
      </ode>
    </physics>
  </joint>

  

  <link name="link_5">
    <pose>0.23511410091698925 0 0 0 1.5707963267948966 0.9424777960769379</pose>
    <inertial>
      <pose>0 0 0.05 0 0 0</pose>
      <mass>0.05</mass>
      <inertia>
        <ixx>0.0001</ixx>
        <iyy>0.0001</iyy>
        <izz>0.0001</izz>
      </inertia>
    </inertial>
    <collision name="cylinder">
      <pose>0 0 0.05 0 0 0</pose>
      <geometry>
        <cylinder>
          <length>0.1</length>
          <radius>0.01</radius>
        </cylinder>
      </geometry>
      <surface>
        <contact>
          <ode>
            <kp>1e5</kp>
            <kd>1</kd>
            <max_vel>0.1</max_vel>
            <min_depth>0.0015</min_depth>
          </ode>
        </contact>
        <friction>
          <ode>
            <mu>1.0</mu>
            <mu2>1.0</mu2>
          </ode>
        </friction>
      </surface>
    </collision>
    <collision name="sphere">
      <geometry>
        <sphere>
          <radius>0.01</radius>
        </sphere>
      </geometry>
      <surface>
        <contact>
          <ode>
            <kp>1e5</kp>
            <kd>1</kd>
            <max_vel>0.1</max_vel>
            <min_depth>0.0015</min_depth>
          </ode>
        </contact>
        <friction>
          <ode>
            <mu>1.0</mu>
            <mu2>1.0</mu2>
          </ode>
        </friction>
      </surface>
    </collision>
    <visual name="cylinder">
      <pose>0 0 0.05 0 0 0</pose>
      <geometry>
        <cylinder>
          <length>0.1</length>
          <radius>0.01</radius>
        </cylinder>
      </geometry>
      <material>
        <ambient>0 0 0 1</ambient>
        <emissive>0 0 0 1</emissive>
        <diffuse>0.1 0.1 0.1 1</diffuse>
        <specular>1 1 1 1</specular>
      </material>
    </visual>
    <visual name="sphere">
      <geometry>
        <sphere>
          <radius>0.01</radius>
        </sphere>
      </geometry>
      <material>
        <ambient>0 0 0 1</ambient>
        <emissive>0 0 0 1</emissive>
        <diffuse>0.1 0.1 0.1 1</diffuse>
        <specular>1 1 1 1</specular>
      </material>
    </visual>

    

  </link>

  <joint name="joint_5" type="universal">
    <child>link_5</child>
    <parent>link_4</parent>
    <axis>
      <xyz>0 1 0</xyz>
      <limit>
        <lower>-1.5707963267948966</lower>
        <upper>1.5707963267948966</upper>
      </limit>
    </axis>
    <axis2>
      <xyz>-1 0 0</xyz>
      <limit>
        <lower>-1.5707963267948966</lower>
        <upper>1.5707963267948966</upper>
      </limit>
    </axis2>
    <physics>
      <ode>
        <cfm_damping>1</cfm_damping>
      </ode>
    </physics>
  </joint>

  

  <link name="link_6">
    <pose>0.29389262614623657 0.08090169943749476 0 0 1.5707963267948966 -0.9424777960769379</pose>
    <inertial>
      <pose>0 0 0.05 0 0 0</pose>
      <mass>0.05</mass>
      <inertia>
        <ixx>0.0001</ixx>
        <iyy>0.0001</iyy>
        <izz>0.0001</izz>
      </inertia>
    </inertial>
    <collision name="cylinder">
      <pose>0 0 0.05 0 0 0</pose>
      <geometry>
        <cylinder>
          <length>0.1</length>
          <radius>0.01</radius>
        </cylinder>
      </geometry>
      <surface>
        <contact>
          <ode>
            <kp>1e5</kp>
            <kd>1</kd>
            <max_vel>0.1</max_vel>
            <min_depth>0.0015</min_depth>
          </ode>
        </contact>
        <friction>
          <ode>
            <mu>1.0</mu>
            <mu2>1.0</mu2>
          </ode>
        </friction>
      </surface>
    </collision>
    <collision name="sphere">
      <geometry>
        <sphere>
          <radius>0.01</radius>
        </sphere>
      </geometry>
      <surface>
        <contact>
          <ode>
            <kp>1e5</kp>
            <kd>1</kd>
            <max_vel>0.1</max_vel>
            <min_depth>0.0015</min_depth>
          </ode>
        </contact>
        <friction>
          <ode>
            <mu>1.0</mu>
            <mu2>1.0</mu2>
          </ode>
        </friction>
      </surface>
    </collision>
    <visual name="cylinder">
      <pose>0 0 0.05 0 0 0</pose>
      <geometry>
        <cylinder>
          <length>0.1</length>
          <radius>0.01</radius>
        </cylinder>
      </geometry>
      <material>
        <ambient>0 0 0 1</ambient>
        <emissive>0 0 0 1</emissive>
        <diffuse>0.1 0.1 0.1 1</diffuse>
        <specular>1 1 1 1</specular>
      </material>
    </visual>
    <visual name="sphere">
      <geometry>
        <sphere>
          <radius>0.01</radius>
        </sphere>
      </geometry>
      <material>
        <ambient>0 0 0 1</ambient>
        <emissive>0 0 0 1</emissive>
        <diffuse>0.1 0.1 0.1 1</diffuse>
        <specular>1 1 1 1</specular>
      </material>
    </visual>

    

  </link>

  <joint name="joint_6" type="universal">
    <child>link_6</child>
    <parent>link_5</parent>
    <axis>
      <xyz>0 1 0</xyz>
      <limit>
        <lower>-1.5707963267948966</lower>
        <upper>1.5707963267948966</upper>
      </limit>
    </axis>
    <axis2>
      <xyz>-1 0 0</xyz>
      <limit>
        <lower>-1.5707963267948966</lower>
        <upper>1.5707963267948966</upper>
      </limit>
    </axis2>
    <physics>
      <ode>
        <cfm_damping>1</cfm_damping>
      </ode>
    </physics>
  </joint>

  

  <link name="link_7">
    <pose>0.35267115137548394 0 0 0 1.5707963267948966 -0.9424777960769379</pose>
    <inertial>
      <pose>0 0 0.05 0 0 0</pose>
      <mass>0.05</mass>
      <inertia>
        <ixx>0.0001</ixx>
        <iyy>0.0001</iyy>
        <izz>0.0001</izz>
      </inertia>
    </inertial>
    <collision name="cylinder">
      <pose>0 0 0.05 0 0 0</pose>
      <geometry>
        <cylinder>
          <length>0.1</length>
          <radius>0.01</radius>
        </cylinder>
      </geometry>
      <surface>
        <contact>
          <ode>
            <kp>1e5</kp>
            <kd>1</kd>
            <max_vel>0.1</max_vel>
            <min_depth>0.0015</min_depth>
          </ode>
        </contact>
        <friction>
          <ode>
            <mu>1.0</mu>
            <mu2>1.0</mu2>
          </ode>
        </friction>
      </surface>
    </collision>
    <collision name="sphere">
      <geometry>
        <sphere>
          <radius>0.01</radius>
        </sphere>
      </geometry>
      <surface>
        <contact>
          <ode>
            <kp>1e5</kp>
            <kd>1</kd>
            <max_vel>0.1</max_vel>
            <min_depth>0.0015</min_depth>
          </ode>
        </contact>
        <friction>
          <ode>
            <mu>1.0</mu>
            <mu2>1.0</mu2>
          </ode>
        </friction>
      </surface>
    </collision>
    <visual name="cylinder">
      <pose>0 0 0.05 0 0 0</pose>
      <geometry>
        <cylinder>
          <length>0.1</length>
          <radius>0.01</radius>
        </cylinder>
      </geometry>
      <material>
        <ambient>0 0 0 1</ambient>
        <emissive>0 0 0 1</emissive>
        <diffuse>0.1 0.1 0.1 1</diffuse>
        <specular>1 1 1 1</specular>
      </material>
    </visual>
    <visual name="sphere">
      <geometry>
        <sphere>
          <radius>0.01</radius>
        </sphere>
      </geometry>
      <material>
        <ambient>0 0 0 1</ambient>
        <emissive>0 0 0 1</emissive>
        <diffuse>0.1 0.1 0.1 1</diffuse>
        <specular>1 1 1 1</specular>
      </material>
    </visual>

    

  </link>

  <joint name="joint_7" type="universal">
    <child>link_7</child>
    <parent>link_6</parent>
    <axis>
      <xyz>0 1 0</xyz>
      <limit>
        <lower>-1.5707963267948966</lower>
        <upper>1.5707963267948966</upper>
      </limit>
    </axis>
    <axis2>
      <xyz>-1 0 0</xyz>
      <limit>
        <lower>-1.5707963267948966</lower>
        <upper>1.5707963267948966</upper>
      </limit>
    </axis2>
    <physics>
      <ode>
        <cfm_damping>1</cfm_damping>
      </ode>
    </physics>
  </joint>

  

  <link name="link_8">
    <pose>0.41144967660473125 -0.08090169943749476 0 0 1.5707963267948966 0.9424777960769379</pose>
    <inertial>
      <pose>0 0 0.05 0 0 0</pose>
      <mass>0.05</mass>
      <inertia>
        <ixx>0.0001</ixx>
        <iyy>0.0001</iyy>
        <izz>0.0001</izz>
      </inertia>
    </inertial>
    <collision name="cylinder">
      <pose>0 0 0.05 0 0 0</pose>
      <geometry>
        <cylinder>
          <length>0.1</length>
          <radius>0.01</radius>
        </cylinder>
      </geometry>
      <surface>
        <contact>
          <ode>
            <kp>1e5</kp>
            <kd>1</kd>
            <max_vel>0.1</max_vel>
            <min_depth>0.0015</min_depth>
          </ode>
        </contact>
        <friction>
          <ode>
            <mu>1.0</mu>
            <mu2>1.0</mu2>
          </ode>
        </friction>
      </surface>
    </collision>
    <collision name="sphere">
      <geometry>
        <sphere>
          <radius>0.01</radius>
        </sphere>
      </geometry>
      <surface>
        <contact>
          <ode>
            <kp>1e5</kp>
            <kd>1</kd>
            <max_vel>0.1</max_vel>
            <min_depth>0.0015</min_depth>
          </ode>
        </contact>
        <friction>
          <ode>
            <mu>1.0</mu>
            <mu2>1.0</mu2>
          </ode>
        </friction>
      </surface>
    </collision>
    <visual name="cylinder">
      <pose>0 0 0.05 0 0 0</pose>
      <geometry>
        <cylinder>
          <length>0.1</length>
          <radius>0.01</radius>
        </cylinder>
      </geometry>
      <material>
        <ambient>0 0 0 1</ambient>
        <emissive>0 0 0 1</emissive>
        <diffuse>0.1 0.1 0.1 1</diffuse>
        <specular>1 1 1 1</specular>
      </material>
    </visual>
    <visual name="sphere">
      <geometry>
        <sphere>
          <radius>0.01</radius>
        </sphere>
      </geometry>
      <material>
        <ambient>0 0 0 1</ambient>
        <emissive>0 0 0 1</emissive>
        <diffuse>0.1 0.1 0.1 1</diffuse>
        <specular>1 1 1 1</specular>
      </material>
    </visual>

    

  </link>

  <joint name="joint_8" type="universal">
    <child>link_8</child>
    <parent>link_7</parent>
    <axis>
      <xyz>0 1 0</xyz>
      <limit>
        <lower>-1.5707963267948966</lower>
        <upper>1.5707963267948966</upper>
      </limit>
    </axis>
    <axis2>
      <xyz>-1 0 0</xyz>
      <limit>
        <lower>-1.5707963267948966</lower>
        <upper>1.5707963267948966</upper>
      </limit>
    </axis2>
    <physics>
      <ode>
        <cfm_damping>1</cfm_damping>
      </ode>
    </physics>
  </joint>

  

  <link name="link_9">
    <pose>0.4702282018339785 0 0 0 1.5707963267948966 0.9424777960769379</pose>
    <inertial>
      <pose>0 0 0.05 0 0 0</pose>
      <mass>0.05</mass>
      <inertia>
        <ixx>0.0001</ixx>
        <iyy>0.0001</iyy>
        <izz>0.0001</izz>
      </inertia>
    </inertial>
    <collision name="cylinder">
      <pose>0 0 0.05 0 0 0</pose>
      <geometry>
        <cylinder>
          <length>0.1</length>
          <radius>0.01</radius>
        </cylinder>
      </geometry>
      <surface>
        <contact>
          <ode>
            <kp>1e5</kp>
            <kd>1</kd>
            <max_vel>0.1</max_vel>
            <min_depth>0.0015</min_depth>
          </ode>
        </contact>
        <friction>
          <ode>
            <mu>1.0</mu>
            <mu2>1.0</mu2>
          </ode>
        </friction>
      </surface>
    </collision>
    <collision name="sphere">
      <geometry>
        <sphere>
          <radius>0.01</radius>
        </sphere>
      </geometry>
      <surface>
        <contact>
          <ode>
            <kp>1e5</kp>
            <kd>1</kd>
            <max_vel>0.1</max_vel>
            <min_depth>0.0015</min_depth>
          </ode>
        </contact>
        <friction>
          <ode>
            <mu>1.0</mu>
            <mu2>1.0</mu2>
          </ode>
        </friction>
      </surface>
    </collision>
    <visual name="cylinder">
      <pose>0 0 0.05 0 0 0</pose>
      <geometry>
        <cylinder>
          <length>0.1</length>
          <radius>0.01</radius>
        </cylinder>
      </geometry>
      <material>
        <ambient>0 0 0 1</ambient>
        <emissive>0 0 0 1</emissive>
        <diffuse>0.1 0.1 0.1 1</diffuse>
        <specular>1 1 1 1</specular>
      </material>
    </visual>
    <visual name="sphere">
      <geometry>
        <sphere>
          <radius>0.01</radius>
        </sphere>
      </geometry>
      <material>
        <ambient>0 0 0 1</ambient>
        <emissive>0 0 0 1</emissive>
        <diffuse>0.1 0.1 0.1 1</diffuse>
        <specular>1 1 1 1</specular>
      </material>
    </visual>

    

  </link>

  <joint name="joint_9" type="universal">
    <child>link_9</child>
    <parent>link_8</parent>
    <axis>
      <xyz>0 1 0</xyz>
      <limit>
        <lower>-1.5707963267948966</lower>
        <upper>1.5707963267948966</upper>
      </limit>
    </axis>
    <axis2>
      <xyz>-1 0 0</xyz>
      <limit>
        <lower>-1.5707963267948966</lower>
        <upper>1.5707963267948966</upper>
      </limit>
    </axis2>
    <physics>
      <ode>
        <cfm_damping>1</cfm_damping>
      </ode>
    </physics>
  </joint>

  

  <link name="link_10">
    <pose>0.5290067270632258 0.08090169943749476 0 0 1.5707963267948966 -0.9424777960769379</pose>
    <inertial>
      <pose>0 0 0.05 0 0 0</pose>
      <mass>0.05</mass>
      <inertia>
        <ixx>0.0001</ixx>
        <iyy>0.0001</iyy>
        <izz>0.0001</izz>
      </inertia>
    </inertial>
    <collision name="cylinder">
      <pose>0 0 0.05 0 0 0</pose>
      <geometry>
        <cylinder>
          <length>0.1</length>
          <radius>0.01</radius>
        </cylinder>
      </geometry>
      <surface>
        <contact>
          <ode>
            <kp>1e5</kp>
            <kd>1</kd>
            <max_vel>0.1</max_vel>
            <min_depth>0.0015</min_depth>
          </ode>
        </contact>
        <friction>
          <ode>
            <mu>1.0</mu>
            <mu2>1.0</mu2>
          </ode>
        </friction>
      </surface>
    </collision>
    <collision name="sphere">
      <geometry>
        <sphere>
          <radius>0.01</radius>
        </sphere>
      </geometry>
      <surface>
        <contact>
          <ode>
            <kp>1e5</kp>
            <kd>1</kd>
            <max_vel>0.1</max_vel>
            <min_depth>0.0015</min_depth>
          </ode>
        </contact>
        <friction>
          <ode>
            <mu>1.0</mu>
            <mu2>1.0</mu2>
          </ode>
        </friction>
      </surface>
    </collision>
    <visual name="cylinder">
      <pose>0 0 0.05 0 0 0</pose>
      <geometry>
        <cylinder>
          <length>0.1</length>
          <radius>0.01</radius>
        </cylinder>
      </geometry>
      <material>
        <ambient>0 0 0 1</ambient>
        <emissive>0 0 0 1</emissive>
        <diffuse>0.1 0.1 0.1 1</diffuse>
        <specular>1 1 1 1</specular>
      </material>
    </visual>
    <visual name="sphere">
      <geometry>
        <sphere>
          <radius>0.01</radius>
        </sphere>
      </geometry>
      <material>
        <ambient>0 0 0 1</ambient>
        <emissive>0 0 0 1</emissive>
        <diffuse>0.1 0.1 0.1 1</diffuse>
        <specular>1 1 1 1</specular>
      </material>
    </visual>

    

  </link>

  <joint name="joint_10" type="universal">
    <child>link_10</child>
    <parent>link_9</parent>
    <axis>
      <xyz>0 1 0</xyz>
      <limit>
        <lower>-1.5707963267948966</lower>
        <upper>1.5707963267948966</upper>
      </limit>
    </axis>
    <axis2>
      <xyz>-1 0 0</xyz>
      <limit>
        <lower>-1.5707963267948966</lower>
        <upper>1.5707963267948966</upper>
      </limit>
    </axis2>
    <physics>
      <ode>
        <cfm_damping>1</cfm_damping>
      </ode>
    </physics>
  </joint>

  

  <link name="link_11">
    <pose>0.5877852522924731 0 0 0 1.5707963267948966 -0.9424777960769379</pose>
    <inertial>
      <pose>0 0 0.05 0 0 0</pose>
      <mass>0.05</mass>
      <inertia>
        <ixx>0.0001</ixx>
        <iyy>0.0001</iyy>
        <izz>0.0001</izz>
      </inertia>
    </inertial>
    <collision name="cylinder">
      <pose>0 0 0.05 0 0 0</pose>
      <geometry>
        <cylinder>
          <length>0.1</length>
          <radius>0.01</radius>
        </cylinder>
      </geometry>
      <surface>
        <contact>
          <ode>
            <kp>1e5</kp>
            <kd>1</kd>
            <max_vel>0.1</max_vel>
            <min_depth>0.0015</min_depth>
          </ode>
        </contact>
        <friction>
          <ode>
            <mu>1.0</mu>
            <mu2>1.0</mu2>
          </ode>
        </friction>
      </surface>
    </collision>
    <collision name="sphere">
      <geometry>
        <sphere>
          <radius>0.01</radius>
        </sphere>
      </geometry>
      <surface>
        <contact>
          <ode>
            <kp>1e5</kp>
            <kd>1</kd>
            <max_vel>0.1</max_vel>
            <min_depth>0.0015</min_depth>
          </ode>
        </contact>
        <friction>
          <ode>
            <mu>1.0</mu>
            <mu2>1.0</mu2>
          </ode>
        </friction>
      </surface>
    </collision>
    <visual name="cylinder">
      <pose>0 0 0.05 0 0 0</pose>
      <geometry>
        <cylinder>
          <length>0.1</length>
          <radius>0.01</radius>
        </cylinder>
      </geometry>
      <material>
        <ambient>0 0 0 1</ambient>
        <emissive>0 0 0 1</emissive>
        <diffuse>0.1 0.1 0.1 1</diffuse>
        <specular>1 1 1 1</specular>
      </material>
    </visual>
    <visual name="sphere">
      <geometry>
        <sphere>
          <radius>0.01</radius>
        </sphere>
      </geometry>
      <material>
        <ambient>0 0 0 1</ambient>
        <emissive>0 0 0 1</emissive>
        <diffuse>0.1 0.1 0.1 1</diffuse>
        <specular>1 1 1 1</specular>
      </material>
    </visual>

    

  </link>

  <joint name="joint_11" type="universal">
    <child>link_11</child>
    <parent>link_10</parent>
    <axis>
      <xyz>0 1 0</xyz>
      <limit>
        <lower>-1.5707963267948966</lower>
        <upper>1.5707963267948966</upper>
      </limit>
    </axis>
    <axis2>
      <xyz>-1 0 0</xyz>
      <limit>
        <lower>-1.5707963267948966</lower>
        <upper>1.5707963267948966</upper>
      </limit>
    </axis2>
    <physics>
      <ode>
        <cfm_damping>1</cfm_damping>
      </ode>
    </physics>
  </joint>

  

  <link name="link_12">
    <pose>0.6465637775217205 -0.08090169943749476 0 0 1.5707963267948966 0.9424777960769379</pose>
    <inertial>
      <pose>0 0 0.05 0 0 0</pose>
      <mass>0.05</mass>
      <inertia>
        <ixx>0.0001</ixx>
        <iyy>0.0001</iyy>
        <izz>0.0001</izz>
      </inertia>
    </inertial>
    <collision name="cylinder">
      <pose>0 0 0.05 0 0 0</pose>
      <geometry>
        <cylinder>
          <length>0.1</length>
          <radius>0.01</radius>
        </cylinder>
      </geometry>
      <surface>
        <contact>
          <ode>
            <kp>1e5</kp>
            <kd>1</kd>
            <max_vel>0.1</max_vel>
            <min_depth>0.0015</min_depth>
          </ode>
        </contact>
        <friction>
          <ode>
            <mu>1.0</mu>
            <mu2>1.0</mu2>
          </ode>
        </friction>
      </surface>
    </collision>
    <collision name="sphere">
      <geometry>
        <sphere>
          <radius>0.01</radius>
        </sphere>
      </geometry>
      <surface>
        <contact>
          <ode>
            <kp>1e5</kp>
            <kd>1</kd>
            <max_vel>0.1</max_vel>
            <min_depth>0.0015</min_depth>
          </ode>
        </contact>
        <friction>
          <ode>
            <mu>1.0</mu>
            <mu2>1.0</mu2>
          </ode>
        </friction>
      </surface>
    </collision>
    <visual name="cylinder">
      <pose>0 0 0.05 0 0 0</pose>
      <geometry>
        <cylinder>
          <length>0.1</length>
          <radius>0.01</radius>
        </cylinder>
      </geometry>
      <material>
        <ambient>0 0 0 1</ambient>
        <emissive>0 0 0 1</emissive>
        <diffuse>0.1 0.1 0.1 1</diffuse>
        <specular>1 1 1 1</specular>
      </material>
    </visual>
    <visual name="sphere">
      <geometry>
        <sphere>
          <radius>0.01</radius>
        </sphere>
      </geometry>
      <material>
        <ambient>0 0 0 1</ambient>
        <emissive>0 0 0 1</emissive>
        <diffuse>0.1 0.1 0.1 1</diffuse>
        <specular>1 1 1 1</specular>
      </material>
    </visual>

    

  </link>

  <joint name="joint_12" type="universal">
    <child>link_12</child>
    <parent>link_11</parent>
    <axis>
      <xyz>0 1 0</xyz>
      <limit>
        <lower>-1.5707963267948966</lower>
        <upper>1.5707963267948966</upper>
      </limit>
    </axis>
    <axis2>
      <xyz>-1 0 0</xyz>
      <limit>
        <lower>-1.5707963267948966</lower>
        <upper>1.5707963267948966</upper>
      </limit>
    </axis2>
    <physics>
      <ode>
        <cfm_damping>1</cfm_damping>
      </ode>
    </physics>
  </joint>

  

  <link name="link_13">
    <pose>0.7053423027509679 0 0 0 1.5707963267948966 0.9424777960769379</pose>
    <inertial>
      <pose>0 0 0.05 0 0 0</pose>
      <mass>0.05</mass>
      <inertia>
        <ixx>0.0001</ixx>
        <iyy>0.0001</iyy>
        <izz>0.0001</izz>
      </inertia>
    </inertial>
    <collision name="cylinder">
      <pose>0 0 0.05 0 0 0</pose>
      <geometry>
        <cylinder>
          <length>0.1</length>
          <radius>0.01</radius>
        </cylinder>
      </geometry>
      <surface>
        <contact>
          <ode>
            <kp>1e5</kp>
            <kd>1</kd>
            <max_vel>0.1</max_vel>
            <min_depth>0.0015</min_depth>
          </ode>
        </contact>
        <friction>
          <ode>
            <mu>1.0</mu>
            <mu2>1.0</mu2>
          </ode>
        </friction>
      </surface>
    </collision>
    <collision name="sphere">
      <geometry>
        <sphere>
          <radius>0.01</radius>
        </sphere>
      </geometry>
      <surface>
        <contact>
          <ode>
            <kp>1e5</kp>
            <kd>1</kd>
            <max_vel>0.1</max_vel>
            <min_depth>0.0015</min_depth>
          </ode>
        </contact>
        <friction>
          <ode>
            <mu>1.0</mu>
            <mu2>1.0</mu2>
          </ode>
        </friction>
      </surface>
    </collision>
    <visual name="cylinder">
      <pose>0 0 0.05 0 0 0</pose>
      <geometry>
        <cylinder>
          <length>0.1</length>
          <radius>0.01</radius>
        </cylinder>
      </geometry>
      <material>
        <ambient>0 0 0 1</ambient>
        <emissive>0 0 0 1</emissive>
        <diffuse>0.1 0.1 0.1 1</diffuse>
        <specular>1 1 1 1</specular>
      </material>
    </visual>
    <visual name="sphere">
      <geometry>
        <sphere>
          <radius>0.01</radius>
        </sphere>
      </geometry>
      <material>
        <ambient>0 0 0 1</ambient>
        <emissive>0 0 0 1</emissive>
        <diffuse>0.1 0.1 0.1 1</diffuse>
        <specular>1 1 1 1</specular>
      </material>
    </visual>

    

  </link>

  <joint name="joint_13" type="universal">
    <child>link_13</child>
    <parent>link_12</parent>
    <axis>
      <xyz>0 1 0</xyz>
      <limit>
        <lower>-1.5707963267948966</lower>
        <upper>1.5707963267948966</upper>
      </limit>
    </axis>
    <axis2>
      <xyz>-1 0 0</xyz>
      <limit>
        <lower>-1.5707963267948966</lower>
        <upper>1.5707963267948966</upper>
      </limit>
    </axis2>
    <physics>
      <ode>
        <cfm_damping>1</cfm_damping>
      </ode>
    </physics>
  </joint>

  

  <link name="link_14">
    <pose>0.7641208279802151 0.08090169943749476 0 0 1.5707963267948966 -0.9424777960769379</pose>
    <inertial>
      <pose>0 0 0.05 0 0 0</pose>
      <mass>0.05</mass>
      <inertia>
        <ixx>0.0001</ixx>
        <iyy>0.0001</iyy>
        <izz>0.0001</izz>
      </inertia>
    </inertial>
    <collision name="cylinder">
      <pose>0 0 0.05 0 0 0</pose>
      <geometry>
        <cylinder>
          <length>0.1</length>
          <radius>0.01</radius>
        </cylinder>
      </geometry>
      <surface>
        <contact>
          <ode>
            <kp>1e5</kp>
            <kd>1</kd>
            <max_vel>0.1</max_vel>
            <min_depth>0.0015</min_depth>
          </ode>
        </contact>
        <friction>
          <ode>
            <mu>1.0</mu>
            <mu2>1.0</mu2>
          </ode>
        </friction>
      </surface>
    </collision>
    <collision name="sphere">
      <geometry>
        <sphere>
          <radius>0.01</radius>
        </sphere>
      </geometry>
      <surface>
        <contact>
          <ode>
            <kp>1e5</kp>
            <kd>1</kd>
            <max_vel>0.1</max_vel>
            <min_depth>0.0015</min_depth>
          </ode>
        </contact>
        <friction>
          <ode>
            <mu>1.0</mu>
            <mu2>1.0</mu2>
          </ode>
        </friction>
      </surface>
    </collision>
    <visual name="cylinder">
      <pose>0 0 0.05 0 0 0</pose>
      <geometry>
        <cylinder>
          <length>0.1</length>
          <radius>0.01</radius>
        </cylinder>
      </geometry>
      <material>
        <ambient>0 0 0 1</ambient>
        <emissive>0 0 0 1</emissive>
        <diffuse>0.1 0.1 0.1 1</diffuse>
        <specular>1 1 1 1</specular>
      </material>
    </visual>
    <visual name="sphere">
      <geometry>
        <sphere>
          <radius>0.01</radius>
        </sphere>
      </geometry>
      <material>
        <ambient>0 0 0 1</ambient>
        <emissive>0 0 0 1</emissive>
        <diffuse>0.1 0.1 0.1 1</diffuse>
        <specular>1 1 1 1</specular>
      </material>
    </visual>

    

  </link>

  <joint name="joint_14" type="universal">
    <child>link_14</child>
    <parent>link_13</parent>
    <axis>
      <xyz>0 1 0</xyz>
      <limit>
        <lower>-1.5707963267948966</lower>
        <upper>1.5707963267948966</upper>
      </limit>
    </axis>
    <axis2>
      <xyz>-1 0 0</xyz>
      <limit>
        <lower>-1.5707963267948966</lower>
        <upper>1.5707963267948966</upper>
      </limit>
    </axis2>
    <physics>
      <ode>
        <cfm_damping>1</cfm_damping>
      </ode>
    </physics>
  </joint>

  

  <link name="link_15">
    <pose>0.8228993532094625 0 0 0 1.5707963267948966 -0.9424777960769379</pose>
    <inertial>
      <pose>0 0 0.05 0 0 0</pose>
      <mass>0.05</mass>
      <inertia>
        <ixx>0.0001</ixx>
        <iyy>0.0001</iyy>
        <izz>0.0001</izz>
      </inertia>
    </inertial>
    <collision name="cylinder">
      <pose>0 0 0.05 0 0 0</pose>
      <geometry>
        <cylinder>
          <length>0.1</length>
          <radius>0.01</radius>
        </cylinder>
      </geometry>
      <surface>
        <contact>
          <ode>
            <kp>1e5</kp>
            <kd>1</kd>
            <max_vel>0.1</max_vel>
            <min_depth>0.0015</min_depth>
          </ode>
        </contact>
        <friction>
          <ode>
            <mu>1.0</mu>
            <mu2>1.0</mu2>
          </ode>
        </friction>
      </surface>
    </collision>
    <collision name="sphere">
      <geometry>
        <sphere>
          <radius>0.01</radius>
        </sphere>
      </geometry>
      <surface>
        <contact>
          <ode>
            <kp>1e5</kp>
            <kd>1</kd>
            <max_vel>0.1</max_vel>
            <min_depth>0.0015</min_depth>
          </ode>
        </contact>
        <friction>
          <ode>
            <mu>1.0</mu>
            <mu2>1.0</mu2>
          </ode>
        </friction>
      </surface>
    </collision>
    <visual name="cylinder">
      <pose>0 0 0.05 0 0 0</pose>
      <geometry>
        <cylinder>
          <length>0.1</length>
          <radius>0.01</radius>
        </cylinder>
      </geometry>
      <material>
        <ambient>0 0 0 1</ambient>
        <emissive>0 0 0 1</emissive>
        <diffuse>0.1 0.1 0.1 1</diffuse>
        <specular>1 1 1 1</specular>
      </material>
    </visual>
    <visual name="sphere">
      <geometry>
        <sphere>
          <radius>0.01</radius>
        </sphere>
      </geometry>
      <material>
        <ambient>0 0 0 1</ambient>
        <emissive>0 0 0 1</emissive>
        <diffuse>0.1 0.1 0.1 1</diffuse>
        <specular>1 1 1 1</specular>
      </material>
    </visual>

    

  </link>

  <joint name="joint_15" type="universal">
    <child>link_15</child>
    <parent>link_14</parent>
    <axis>
      <xyz>0 1 0</xyz>
      <limit>
        <lower>-1.5707963267948966</lower>
        <upper>1.5707963267948966</upper>
      </limit>
    </axis>
    <axis2>
      <xyz>-1 0 0</xyz>
      <limit>
        <lower>-1.5707963267948966</lower>
        <upper>1.5707963267948966</upper>
      </limit>
    </axis2>
    <physics>
      <ode>
        <cfm_damping>1</cfm_damping>
      </ode>
    </physics>
  </joint>

  

  <link name="link_16">
    <pose>0.8816778784387097 -0.08090169943749476 0 0 1.5707963267948966 0.9424777960769379</pose>
    <inertial>
      <pose>0 0 0.05 0 0 0</pose>
      <mass>0.05</mass>
      <inertia>
        <ixx>0.0001</ixx>
        <iyy>0.0001</iyy>
        <izz>0.0001</izz>
      </inertia>
    </inertial>
    <collision name="cylinder">
      <pose>0 0 0.05 0 0 0</pose>
      <geometry>
        <cylinder>
          <length>0.1</length>
          <radius>0.01</radius>
        </cylinder>
      </geometry>
      <surface>
        <contact>
          <ode>
            <kp>1e5</kp>
            <kd>1</kd>
            <max_vel>0.1</max_vel>
            <min_depth>0.0015</min_depth>
          </ode>
        </contact>
        <friction>
          <ode>
            <mu>1.0</mu>
            <mu2>1.0</mu2>
          </ode>
        </friction>
      </surface>
    </collision>
    <collision name="sphere">
      <geometry>
        <sphere>
          <radius>0.01</radius>
        </sphere>
      </geometry>
      <surface>
        <contact>
          <ode>
            <kp>1e5</kp>
            <kd>1</kd>
            <max_vel>0.1</max_vel>
            <min_depth>0.0015</min_depth>
          </ode>
        </contact>
        <friction>
          <ode>
            <mu>1.0</mu>
            <mu2>1.0</mu2>
          </ode>
        </friction>
      </surface>
    </collision>
    <visual name="cylinder">
      <pose>0 0 0.05 0 0 0</pose>
      <geometry>
        <cylinder>
          <length>0.1</length>
          <radius>0.01</radius>
        </cylinder>
      </geometry>
      <material>
        <ambient>0 0 0 1</ambient>
        <emissive>0 0 0 1</emissive>
        <diffuse>0.1 0.1 0.1 1</diffuse>
        <specular>1 1 1 1</specular>
      </material>
    </visual>
    <visual name="sphere">
      <geometry>
        <sphere>
          <radius>0.01</radius>
        </sphere>
      </geometry>
      <material>
        <ambient>0 0 0 1</ambient>
        <emissive>0 0 0 1</emissive>
        <diffuse>0.1 0.1 0.1 1</diffuse>
        <specular>1 1 1 1</specular>
      </material>
    </visual>

    

    <collision name="plug_collision">
      <pose>0 0 0.1 0 0 0</pose>
      <geometry>
        <cylinder>
          <length>0.010000000000000002</length>
          <radius>0.011000000000000001</radius>
        </cylinder>
      </geometry>
      <surface>
        <contact>
          <ode>
            <kp>1e5</kp>
            <kd>1</kd>
            <max_vel>0.1</max_vel>
            <min_depth>0.0015</min_depth>
          </ode>
        </contact>
        <friction>
          <ode>
            <mu>1.0</mu>
            <mu2>1.0</mu2>
          </ode>
        </friction>
      </surface>
    </collision>

    <visual name="plug_visual">
      <pose>0 0 0.1 0 0 0</pose>
      <geometry>
        <cylinder>
          <length>0.010000000000000002</length>
          <radius>0.011000000000000001</radius>
        </cylinder>
      </geometry>
      <material>
        <ambient>0 0 0.3 1</ambient>
        <emissive>0 0 0.2 1</emissive>
        <diffuse>0 0 0.1 1</diffuse>
        <specular>1 1 1 1</specular>
      </material>
    </visual>

    <sensor name="tip_sensor" type="contact">
      <contact>
        <collision>plug_collision</collision>
        <collision>cylinder</collision>
        <collision>sphere</collision>
      </contact>
    </sensor>

    

  </link>

  <joint name="joint_16" type="universal">
    <child>link_16</child>
    <parent>link_15</parent>
    <axis>
      <xyz>0 1 0</xyz>
      <limit>
        <lower>-1.5707963267948966</lower>
        <upper>1.5707963267948966</upper>
      </limit>
    </axis>
    <axis2>
      <xyz>-1 0 0</xyz>
      <limit>
        <lower>-1.5707963267948966</lower>
        <upper>1.5707963267948966</upper>
      </limit>
    </axis2>
    <physics>
      <ode>
        <cfm_damping>1</cfm_damping>
      </ode>
    </physics>
  </joint>

  

  <joint name="world" type="fixed">
    <child>link_0</child>
    <parent>world</parent>
  </joint>

  <plugin name="touch_valkyrie_cable" filename="libTouchPlugin.so">
    <sensor>tip_sensor</sensor>
    <target>valkyrie</target>
    <time>5</time>
    <namespace>task2/checkpoint4</namespace>
  </plugin>

</model>


    <!-- Checkpoint 2 - Box plugin -->
    

    <plugin name="boxT2CP2" filename="libBoxContainsPlugin.so">
      <entity>solar_panel</entity>
      <namespace>task2/checkpoint2</namespace>
      <pose>
        10.849597521873036
        3.96069559143847
        0.9
        0
        0
        -2.356194490192345
      </pose>
      <size>1.47 0.95 0.45</size>
    </plugin>

    <!-- Bling -->
    

    <!-- Walkway -->
    <include>
      <name>walkway_10</name>
      <pose>
      10.460688792220436
      5.42723505561937
      -0.052151
      0
      0
      -0.7853981633974485
      </pose>
      <uri>model://walkway_metal_straight</uri>
    </include>


    <!-- Bling -->
    <include>
      <name>mars_crate_10</name>
      <pose>
      10.177846079745818
      6.787708502622288
      0
      0
      0
      0.7853981633974481
      </pose>
      <uri>model://mars_crate</uri>
    </include>


    <!-- Bling -->
    <include>
      <name>mars_rock_2_11</name>
      <pose>
      11.891872917342008
      5.073681665026096
      0
      0
      0
      -2.3561944901923453
      </pose>
      <uri>model://mars_rock_2</uri>
    </include>


    <!-- Final Box 2 -->
    <include>
      <name>walkway_11</name>
      <pose>
      12.615950261277034
      7.5824965246759675
      -0.052151
      0
      0
      -2.3561944901923453
      </pose>
      <uri>model://walkway_finish_adjacent</uri>
    </include>


    <!-- Checkpoint 6 - Box plugin -->
    <plugin name="boxT2CP6" filename="libBoxContainsPlugin.so">
      <entity>valkyrie</entity>
      <namespace>task2/checkpoint6</namespace>
      <pose>
        12.615950261277034
        7.5824965246759675
        2.5
        0
        0
        -2.3561944901923453
      </pose>
      <size>3.048 3.048 5.0</size>
    </plugin>

    <!-- Bling -->
    <include>
      <name>mars_rock_2_12</name>
      <pose>
      14.047134386398605
      9.01368064979754
      0
      0
      0
      -0.7853981633974485
      </pose>
      <uri>model://mars_rock_2</uri>
    </include>


    <!-- Bling -->
    <include>
      <name>mars_crate_13</name>
      <pose>
      11.255476814274116
      8.942969971678885
      0
      0
      0
      0.785398163397448
      </pose>
      <uri>model://mars_crate</uri>
    </include>


    

    <!-- /TASK 2 -->
    

    

    <!-- TASK 3 -->

    <!-- Walkway -->
    <include>
      <name>walkway_12</name>
      <pose>
      14.994801788025766
      5.966570918528296
      -0.052151
      0
      0
      1.5707963267948963
      </pose>
      <uri>model://walkway_metal_45</uri>
    </include>


    <!-- Walkway -->
    <include>
      <name>walkway_13</name>
      <pose>
      14.994801788025766
      5.966570918528296
      -0.052151
      0
      0
      -1.570796326794897
      </pose>
      <uri>model://walkway_metal_45</uri>
    </include>


    <!-- Bling -->
    <include>
      <name>mars_crate_long_14</name>
      <pose>
      16.916847212975004
      7.141856343477533
      0
      0
      0
      -4.440892098500626e-16
      </pose>
      <uri>model://mars_crate_long</uri>
    </include>


    <!-- Bling -->
    <include>
      <name>mars_rock_1_15</name>
      <pose>
      15.756801788025767
      7.128570918528296
      0
      0
      0
      -4.0574162479713433e-16
      </pose>
      <uri>model://mars_rock_1</uri>
    </include>


    <!-- Habitat -->
    

    

<!-- Base model - static frame -->

<model name="habitat_base">
  <static>true</static>

  <pose>
  15.27023095530527
  -3.0228252086509464
  0
  0
  0
  -2.3561944901923453
  </pose>

  <link name="link_stairs">
    <collision name="collision">
      <pose>0 0 0 0 0 0</pose>
      <geometry>
        <mesh>
          <uri>model://src_habitat/meshes/hdu.obj</uri>
          <scale>0.0254 0.0254 0.0254</scale>
          <submesh>
            <name>Stairs</name>
          </submesh>
        </mesh>
      </geometry>
    </collision>
    <visual name="visual">
      <pose>0 0 0 0 0 0</pose>
      <geometry>
        <mesh>
          <uri>model://src_habitat/meshes/hdu.obj</uri>
          <scale>0.0254 0.0254 0.0254</scale>
          <submesh>
            <name>Stairs</name>
          </submesh>
        </mesh>
      </geometry>
    </visual>
  </link>

  <link name="link_module_long">
    <collision name="collision">
      <pose>0 0 0 0 0 0</pose>
      <geometry>
        <mesh>
          <uri>model://src_habitat/meshes/hdu.obj</uri>
          <scale>0.0254 0.0254 0.0254</scale>
          <submesh>
            <name>Module_Long</name>
          </submesh>
        </mesh>
      </geometry>
    </collision>
    <visual name="visual">
      <pose>0 0 0 0 0 0</pose>
      <geometry>
        <mesh>
          <uri>model://src_habitat/meshes/hdu.obj</uri>
          <scale>0.0254 0.0254 0.0254</scale>
          <submesh>
            <name>Module_Long</name>
          </submesh>
        </mesh>
      </geometry>
    </visual>
  </link>

  <link name="link_door_04">
    <collision name="collision">
      <pose>0 0 0 0 0 0</pose>
      <geometry>
        <mesh>
          <uri>model://src_habitat/meshes/hdu.obj</uri>
          <scale>0.0254 0.0254 0.0254</scale>
          <submesh>
            <name>Door_04</name>
          </submesh>
        </mesh>
      </geometry>
    </collision>
    <visual name="visual">
      <pose>0 0 0 0 0 0</pose>
      <geometry>
        <mesh>
          <uri>model://src_habitat/meshes/hdu.obj</uri>
          <scale>0.0254 0.0254 0.0254</scale>
          <submesh>
            <name>Door_04</name>
          </submesh>
        </mesh>
      </geometry>
    </visual>
  </link>

  <link name="link_module_large">
    <collision name="collision">
      <pose>0 0 0 0 0 0</pose>
      <geometry>
        <mesh>
          <uri>model://src_habitat/meshes/hdu.obj</uri>
          <scale>0.0254 0.0254 0.0254</scale>
          <submesh>
            <name>Module_Large</name>
          </submesh>
        </mesh>
      </geometry>
    </collision>
    <visual name="visual">
      <pose>0 0 0 0 0 0</pose>
      <geometry>
        <mesh>
          <uri>model://src_habitat/meshes/hdu.obj</uri>
          <scale>0.0254 0.0254 0.0254</scale>
          <submesh>
            <name>Module_Large</name>
          </submesh>
        </mesh>
      </geometry>
    </visual>
  </link>

  <link name="link_door_01">
    <collision name="collision">
      <pose>0 0 0 0 0 0</pose>
      <geometry>
        <mesh>
          <uri>model://src_habitat/meshes/hdu.obj</uri>
          <scale>0.0254 0.0254 0.0254</scale>
          <submesh>
            <name>Door_01</name>
          </submesh>
        </mesh>
      </geometry>
    </collision>
    <visual name="visual">
      <pose>0 0 0 0 0 0</pose>
      <geometry>
        <mesh>
          <uri>model://src_habitat/meshes/hdu.obj</uri>
          <scale>0.0254 0.0254 0.0254</scale>
          <submesh>
            <name>Door_01</name>
          </submesh>
        </mesh>
      </geometry>
    </visual>
  </link>

  <link name="door_03">
    <collision name="collision">
      <pose>0 0 0 0 0 0</pose>
      <geometry>
        <mesh>
          <uri>model://src_habitat/meshes/hdu.obj</uri>
          <scale>0.0254 0.0254 0.0254</scale>
          <submesh>
            <name>Door_03</name>
          </submesh>
        </mesh>
      </geometry>
    </collision>
    <visual name="visual">
      <pose>0 0 0 0 0 0</pose>
      <geometry>
        <mesh>
          <uri>model://src_habitat/meshes/hdu.obj</uri>
          <scale>0.0254 0.0254 0.0254</scale>
          <submesh>
            <name>Door_03</name>
          </submesh>
        </mesh>
      </geometry>
    </visual>
  </link>

  <link name="module_small">
    <collision name="collision">
      <pose>0 0 0 0 0 0</pose>
      <geometry>
        <mesh>
          <uri>model://src_habitat/meshes/hdu.obj</uri>
          <scale>0.0254 0.0254 0.0254</scale>
          <submesh>
            <name>Module_Small</name>
          </submesh>
        </mesh>
      </geometry>
      <surface>
        <contact>
          <!-- Don't collide with door -->
          <collide_bitmask>0x01</collide_bitmask>
        </contact>
      </surface>
    </collision>
    <visual name="visual">
      <pose>0 0 0 0 0 0</pose>
      <geometry>
        <mesh>
          <uri>model://src_habitat/meshes/hdu.obj</uri>
          <scale>0.0254 0.0254 0.0254</scale>
          <submesh>
            <name>Module_Small</name>
          </submesh>
        </mesh>
      </geometry>
    </visual>
  </link>
</model>

<!-- Door -->
<model name="habitat_door">

  <pose>
    19.13456951448975
    2.5597828288168456
    2.88
    0
    0
    -2.3561944901923453
  </pose>

  <!-- door body -->
  <link name="base">

    <inertial>
      <mass>18</mass>
      <inertia>
        <ixx>6.304</ixx>
        <ixy>0</ixy>
        <ixz>0</ixz>
        <iyy>6.9932</iyy>
        <iyz>0</iyz>
        <izz>0.7979</izz>
      </inertia>
    </inertial>

    <collision name="collision">
      <geometry>
        <box>
          <size>1.27 0.25 1.99</size>
        </box>
      </geometry>
      <surface>
        <contact>
          <!-- Don't collide with habitat -->
          <collide_bitmask>0x10</collide_bitmask>
        </contact>
      </surface>
    </collision>

    <visual name="visual">
      <pose>6.68 1.215 -2.88 0 0 0</pose>
      <geometry>
        <mesh>
          <uri>model://src_habitat/meshes/hdu.obj</uri>
          <scale>0.0254 0.0254 0.0254</scale>
          <submesh>
            <name>Door_02</name>
          </submesh>
        </mesh>
      </geometry>
    </visual>
  </link>

  <!-- door valve -->
  <link name="valve">
    <pose>0 -0.12 0.08 0 0 3.14</pose>
    <inertial>
      <mass>7.8219</mass>
      <pose>0 0.0615 0 0 0 0</pose>
      <inertia>
        <ixx>0.0695</ixx>
        <ixy>0.0000</ixy>
        <ixz>0.0000</ixz>
        <iyy>0.1349</iyy>
        <iyz>0.0000</iyz>
        <izz>0.0695</izz>
      </inertia>
    </inertial>
    <collision name="collision">
      <geometry>
        <mesh>
          <uri>model://src_habitat/meshes/wheel_valve_large.dae</uri>
        </mesh>
      </geometry>
      <surface>
        <friction>
          <ode>
            <mu>1</mu>
            <mu2>1</mu2>
          </ode>
        </friction>
        <contact>
          <ode>
            <kp>1000000.0</kp>
            <kd>100.0</kd>
            <max_vel>0.01</max_vel>
            <min_depth>0.001</min_depth>
          </ode>
        </contact>
      </surface>
    </collision>
    <visual name="visual">
      <geometry>
        <mesh>
          <uri>model://src_habitat/meshes/wheel_valve_large.dae</uri>
        </mesh>
      </geometry>
    </visual>
  </link>

  <!-- Joint connecting the valve and the door -->
  <joint name="valve_hinge" type="revolute">
    <parent>base</parent>
    <child>valve</child>
    <axis>
      <xyz>0 1 0</xyz>
      <limit>
        <lower>-12.5663706144</lower>
        <upper>0</upper>
      </limit>
      <dynamics>
        <damping>1.0</damping>
      </dynamics>
    </axis>
    <physics>
      <ode>
        <cfm_damping>1</cfm_damping>
      </ode>
    </physics>
  </joint>

  <!-- Door hinge -->
  <joint name="door_hinge" type="revolute">
    <parent>world</parent>
    <child>base</child>
    <pose>-0.8 0.125 0.2 0 0 0</pose>
    <axis>
      <xyz>0 0 1</xyz>
      <limit>
        <lower>0</lower>
        <upper>1.57</upper>
      </limit>
      <dynamics>
        <damping>0</damping>
        <friction>0</friction>
      </dynamics>
    </axis>
    <physics>
      <ode>
        <cfm_damping>1</cfm_damping>
      </ode>
    </physics>
  </joint>
</model>







    <!-- Lamp inside the habitat -->
    

    <light name='habitat_lamp' type='point'>
      <pose>
        15.27023095530527
        -3.0228252086509464
        4.5
        0
        0
        -2.3561944901923453
      </pose>
      <diffuse>0.5 0.5 0.5 1</diffuse>
      <specular>0.1 0.1 0.1 1</specular>
      <attenuation>
        <range>20</range>
        <constant>0.5</constant>
        <linear>0.01</linear>
        <quadratic>0.001</quadratic>
      </attenuation>
      <cast_shadows>0</cast_shadows>
      <direction>0 0 -1</direction>
    </light>

    <!-- Table -->
    
    <include>
      <pose>
        15.27023095530527
        -3.0228252086509464
        1.8
        0
        0
        -2.3561944901923453
      </pose>
      <uri>model://space_table</uri>
    </include>

    <!-- Air leak detector -->
    

    

<model name="air_leak_detector">

  <pose>
    15.27023095530527
    -3.0228252086509464
    2.59448
    0
    0
    -0.7853981633974487
  </pose>

  <link name="base">

    <inertial>
      <pose>
      0
      -0.00063
      0
      0
      0
      0
      </pose>
      <inertia>
        <ixx>0.0006035883333333333</ixx>
        <iyy>0.003206729933333333</iyy>
        <izz>0.003333989666666666</izz>
      </inertia>
      <mass>1.0</mass>
    </inertial>


    <collision name="collision">

      <pose>0 0 -0.026760000000000003 0 0 -1.5707963267948966</pose>

      <geometry>
        <mesh>
          <scale>0.02 0.02 0.02</scale>
          <uri>model://air_leak_detector/meshes/air_leak_detector.obj</uri>
        </mesh>
      </geometry>
      <surface>
        <contact>
          <ode>
            <kp>1e5</kp>
            <kd>1</kd>
            <max_vel>0.1</max_vel>
            <min_depth>0.0015</min_depth>
          </ode>
        </contact>
      </surface>
    </collision>

    <visual name="visual">

      <pose>0 0 -0.026760000000000003 0 0 -1.5707963267948966</pose>

      <geometry>
        <mesh>
          <scale>0.02 0.02 0.02</scale>
          <uri>model://air_leak_detector/meshes/air_leak_detector.obj</uri>
        </mesh>
      </geometry>
    </visual>

    <sensor name="logical_camera" type="logical_camera">

      <logical_camera>
        <near>0.1</near>
        <far>0.5</far>
        <horizontal_fov>0.5235987755982988</horizontal_fov>
        <aspect_ratio>1</aspect_ratio>
      </logical_camera>

      <visualize>true</visualize>
      <always_on>true</always_on>
      <update_rate>10</update_rate>

    </sensor>

  </link>

</model>



    <!-- Leak patch tool -->
    

    <include>
      <pose>
        15.058098920949305
        -3.2349572430069107
        2.6
        0
        0
        -2.3561944901923453
      </pose>
      <uri>model://leak_patch_tool</uri>
    </include>

    <!-- TODO: Put the box inside the habitat -->

    <!-- Checkpoint 8 - Box plugin -->

    <plugin name="boxT3CP8" filename="libBoxContainsPlugin.so">
      <entity>valkyrie</entity>
      <namespace>task3/checkpoint8</namespace>
      <pose>
        16.295535788025767
        5.427100826528296
        2.5
        0
        0
        -2.3561944901923453
      </pose>
      <size>3.048 3.048 5.0</size>
    </plugin>

    <!-- /TASK 3 -->
    

    <!-- Finals plugin -->
    <plugin name="finals" filename="libFinalsPlugin.so">

      
        <task1>
          <timeout>1800</timeout>

          <checkpoint1>
            <skip_robot_pose>
              2.548
              -5.183721083381576e-16
              1.1
              0
              0
              -2.4492935982947064e-16
            </skip_robot_pose>
          </checkpoint1>

          <checkpoint2>
            <skip_robot_pose>
              2.548
              -5.183721083381576e-16
              1.1
              0
              0
              -2.4492935982947064e-16
            </skip_robot_pose>
          </checkpoint2>

          <checkpoint3>
            <skip_robot_pose>
              1.986000000000001
              3.8099999999999996
              1.1
              0
              0
              -2.449293598294706e-16
            </skip_robot_pose>
          </checkpoint3>
        </task1>
      

      
        <task2>
          <timeout>3600</timeout>

          <checkpoint1>
          </checkpoint1>

          <checkpoint2>
            <skip_robot_pose>
              10.00106938444918
              4.809223728862327
              1.1
              0
              0
              -0.7853981633974484
            </skip_robot_pose>
            <panel_pose>
              10.879477514500334
              4.160416049493293
              0.7
              0
              0
              -2.2157122224546084
            </panel_pose>
          </checkpoint2>

          <checkpoint3>
            <skip_robot_pose>
              10.00106938444918
              4.809223728862327
              1.1
              0
              0
              -0.7853981633974484
            </skip_robot_pose>
          </checkpoint3>

          <checkpoint4>
          </checkpoint4>

          <checkpoint5>
            <skip_robot_pose>
              10.00106938444918
              4.809223728862327
              1.1
              0
              0
              -0.7853981633974484
            </skip_robot_pose>
          </checkpoint5>

          <checkpoint6>
            <skip_robot_pose>
              12.615950261277034
              7.5824965246759675
              1.1
              0
              0
              -0.7853981633974485
            </skip_robot_pose>
          </checkpoint6>

        </task2>

      

      
        <task3>
          <timeout>7200</timeout>

          <checkpoint1>
            <skip_robot_pose>
              12.615950261277034
              7.5824965246759675
              1.1
              0
              0
              -0.7853981633974485
            </skip_robot_pose>
          </checkpoint1>

          <checkpoint2>
            <skip_robot_pose>
              12.615950261277034
              7.5824965246759675
              1.1
              0
              0
              -0.7853981633974485
            </skip_robot_pose>
          </checkpoint2>

          <checkpoint3>
            <skip_robot_pose>
              12.615950261277034
              7.5824965246759675
              1.1
              0
              0
              -0.7853981633974485
            </skip_robot_pose>
          </checkpoint3>

          <checkpoint4>
          </checkpoint4>

          <checkpoint5>
            <skip_robot_pose>
              12.615950261277034
              7.5824965246759675
              1.1
              0
              0
              -0.7853981633974485
            </skip_robot_pose>
          </checkpoint5>

          <checkpoint6>
          </checkpoint6>

          <checkpoint7>
            <skip_robot_pose>
              12.615950261277034
              7.5824965246759675
              1.1
              0
              0
              -0.7853981633974485
            </skip_robot_pose>
          </checkpoint7>

          <checkpoint8>
            <skip_robot_pose>
              12.615950261277034
              7.5824965246759675
              1.1
              0
              0
              -0.7853981633974485
            </skip_robot_pose>
          </checkpoint8>

        </task3>
      

    </plugin>

  </world>
</sdf>
