<?xml version="1.0" ?>

<sdf version="1.6">
  <world name="SRC_finals">

    <physics type="ode">
      <real_time_update_rate>1000.0</real_time_update_rate>
      <max_step_size>0.001</max_step_size>
      <real_time_factor>1</real_time_factor>
      <ode>
        <solver>
          <type>quick</type>
          <iters>150</iters>
          <precon_iters>0</precon_iters>
          <sor>1.400000</sor>
          <use_dynamic_moi_rescaling>1</use_dynamic_moi_rescaling>
        </solver>
        <constraints>
          <cfm>0.000000</cfm>
          <erp>0.800000</erp>
          <contact_max_correcting_vel>2000.000000</contact_max_correcting_vel>
          <contact_surface_layer>0.01000</contact_surface_layer>
        </constraints>
      </ode>
    </physics>

    <!-- GUI -->
    <gui fullscreen='0'>
      <camera name='user_camera'>
        <pose>-4.1 -0.2 3.3 0 0.37 0</pose>
      </camera>
    </gui>

    <!-- Scene -->
    <scene>
      <background>0.968627451 0.690196078 0.384313725 1.0</background>
      <grid>0</grid>
      <origin_visual>0</origin_visual>
    </scene>

    <!-- A global light source -->
    <light type="directional" name="sun">
      <cast_shadows>true</cast_shadows>
      <pose>0 0 1000 0.842148436026636 -0.9856421390318904 0</pose>
      <diffuse>0.8 0.8 0.8 1</diffuse>
      <specular>0.2 0.2 0.2 1</specular>
      <attenuation>
        <range>1000</range>
        <constant>0.9</constant>
        <linear>0.01</linear>
        <quadratic>0.001</quadratic>
      </attenuation>
      <direction>-0.5 0.1 -0.9</direction>
    </light>

    <!-- Background -->
    <include>
      <uri>model://heightmap_mars</uri>
    </include>

    <!-- START WALKWAY -->

    <!-- Walkway -->
    <include>
      <name>walkway_1</name>
      <pose>
      -0.3
      0
      -0.052151
      0
      0
      -1.5707963267948968
      </pose>
      <uri>model://walkway_metal_straight</uri>
    </include>


    <!-- Bling -->
    <include>
      <name>mars_crate_1</name>
      <pose>
      0.46199999999999986
      -1.1620000000000001
      0
      0
      0
      3.141592653589793
      </pose>
      <uri>model://mars_crate</uri>
    </include>


    <!-- Bling -->
    <include>
      <name>mars_rock_3_2</name>
      <pose>
      0.4620000000000004
      1.862
      0
      0
      0
      -2.4492935982947064e-16
      </pose>
      <uri>model://mars_rock_3</uri>
    </include>


    

    <!-- TASK 1 -->

    <!-- Walkway -->
    <include>
      <name>walkway_2</name>
      <pose>
      1.224
      -2.7995425828508494e-16
      -0.052151
      0
      0
      -1.5707963267948968
      </pose>
      <uri>model://walkway_metal_straight</uri>
    </include>


    <!-- Satellite -->
    

    

<model name="satellite_dish">

  <pose>
    1.9859999999999995
    -2.7620000000000005
    0
    0
    0
    3.141592653589793
  </pose>

  <link name="base">
    <inertial>
      <pose>0 -0.6077 0.3193 0 0 0</pose>
      <inertia>
        <ixx>165.1022</ixx>
        <ixy>0</ixy>
        <ixz>0</ixz>
        <iyy>13.8377</iyy>
        <iyz>0</iyz>
        <izz>170.3359</izz>
      </inertia>
      <mass>400</mass>
    </inertial>
    <collision name="collision">
      <geometry>
        <mesh>
          <uri>model://satellite_dish/meshes/satellite_dish.dae</uri>
          <submesh>
            <name>Base</name>
          </submesh>
        </mesh>
      </geometry>
    </collision>
    <visual name="visual">
      <geometry>
        <mesh>
          <uri>model://satellite_dish/meshes/satellite_dish.dae</uri>
          <submesh>
            <name>Base</name>
          </submesh>
        </mesh>
      </geometry>
    </visual>
  </link>

  <link name="pivot">
    <pose>0 0 1.595 0 0 0</pose>
    <inertial>
      <inertia>
        <ixx>0.00073</ixx>
        <ixy>0</ixy>
        <ixz>0</ixz>
        <iyy>0.000598</iyy>
        <iyz>0</iyz>
        <izz>0.00057</izz>
      </inertia>
      <mass>0.82</mass>
    </inertial>
    <collision name="collision">
      <pose>0 0 -1.595 0 0 0</pose>
      <geometry>
        <mesh>
          <uri>model://satellite_dish/meshes/satellite_dish.dae</uri>
          <submesh>
            <name>Pivot</name>
          </submesh>
        </mesh>
      </geometry>
    </collision>
    <visual name="visual">
      <pose>0 0 -1.595 0 0 0</pose>
      <geometry>
        <mesh>
          <uri>model://satellite_dish/meshes/satellite_dish.dae</uri>
          <submesh>
            <name>Pivot</name>
          </submesh>
        </mesh>
      </geometry>
    </visual>
  </link>

  <link name="dish">
    <pose>0 0 1.595 0.43 0 0</pose>
    <inertial>
      <pose>0 0.2 0 0 0 0</pose>
      <inertia>
        <ixx>0.92468</ixx>
        <ixy>0</ixy>
        <ixz>0</ixz>
        <iyy>1.87729</iyy>
        <iyz>0</iyz>
        <izz>0.97826</izz>
      </inertia>
      <mass>17.0</mass>
    </inertial>
    <collision name="collision">
      <pose>0 -0.6519041 -1.451541 -0.43 0 0</pose>
      <geometry>
        <mesh>
          <uri>model://satellite_dish/meshes/satellite_dish.dae</uri>
          <submesh>
            <name>Dish</name>
          </submesh>
        </mesh>
      </geometry>
    </collision>
    <visual name="visual">
      <pose>0 -0.6519041 -1.451541 -0.43 0 0</pose>
      <geometry>
        <mesh>
          <uri>model://satellite_dish/meshes/satellite_dish.dae</uri>
          <submesh>
            <name>Dish</name>
          </submesh>
        </mesh>
      </geometry>
    </visual>
  </link>

  <link name="wheel_yaw">
    <pose>-0.2 -1.725 0.91 0.52 0 0</pose>
    <inertial>
      <inertia>
        <ixx>0.0123</ixx>
        <ixy>0</ixy>
        <ixz>0</ixz>
        <iyy>0.01295</iyy>
        <iyz>0</iyz>
        <izz>0.02500</izz>
      </inertia>
      <mass>2.0</mass>
    </inertial>
    <collision name="collision">
      <pose>0.2 1.060 -1.64 -0.52 0 0</pose>
      <geometry>
        <mesh>
          <uri>model://satellite_dish/meshes/satellite_dish.dae</uri>
          <submesh>
            <name>Wheel_01</name>
          </submesh>
        </mesh>
      </geometry>
    </collision>
    <collision name="collision_sphere">
      <pose>0.002 -0.123 0.082 0 0 0</pose>
      <geometry>
        <sphere>
          <radius>0.029</radius>
        </sphere>
      </geometry>
    </collision>
    <collision name="collision_cylinder">
      <pose>0.002 -0.122 0.025 0 0 0</pose>
      <geometry>
        <cylinder>
          <length>0.06</length>
          <radius>0.0125</radius>
        </cylinder>
      </geometry>
    </collision>
    <visual name="visual">
      <pose>0.2 1.060 -1.64 -0.52 0 0</pose>
      <geometry>
        <mesh>
          <uri>model://satellite_dish/meshes/satellite_dish.dae</uri>
          <submesh>
            <name>Wheel_01</name>
          </submesh>
        </mesh>
      </geometry>
    </visual>
  </link>

  <link name="wheel_pitch">
    <pose>0.2 -1.725 0.91 0.52 0 0</pose>
    <inertial>
      <inertia>
        <ixx>0.0123</ixx>
        <ixy>0</ixy>
        <ixz>0</ixz>
        <iyy>0.01295</iyy>
        <iyz>0</iyz>
        <izz>0.02500</izz>
      </inertia>
      <mass>2.0</mass>
    </inertial>
    <collision name="collision">
      <pose>-0.2 1.060 -1.64 -0.52 0 0</pose>
      <geometry>
        <mesh>
          <uri>model://satellite_dish/meshes/satellite_dish.dae</uri>
          <submesh>
            <name>Wheel_02</name>
          </submesh>
        </mesh>
      </geometry>
    </collision>
    <collision name="collision_sphere">
      <pose>-0.002 -0.123 0.082 0 0 0</pose>
      <geometry>
        <sphere>
          <radius>0.029</radius>
        </sphere>
      </geometry>
    </collision>
    <collision name="collision_cylinder">
      <pose>-0.002 -0.122 0.025 0 0 0</pose>
      <geometry>
        <cylinder>
          <length>0.06</length>
          <radius>0.0125</radius>
        </cylinder>
      </geometry>
    </collision>
    <visual name="visual">
      <pose>-0.2 1.060 -1.64 -0.52 0 0</pose>
      <geometry>
        <mesh>
          <uri>model://satellite_dish/meshes/satellite_dish.dae</uri>
          <submesh>
            <name>Wheel_02</name>
          </submesh>
        </mesh>
      </geometry>
    </visual>
  </link>

  <joint name="dish_yaw" type="revolute">
    <parent>base</parent>
    <child>pivot</child>
    <axis>
      <xyz>0 0 1</xyz>
      <dynamics>
        <damping>1000</damping>
      </dynamics>
    </axis>
  </joint>

  <joint name="dish_pitch" type="revolute">
    <parent>pivot</parent>
    <child>dish</child>
    <axis>
      <xyz>1 0 0</xyz>
      <limit>
        <lower>-0.2</lower>
        <upper>1.57</upper>
      </limit>
      <dynamics>
        <damping>100</damping>
      </dynamics>
    </axis>
  </joint>

  <joint name="wheel_yaw" type="revolute">
    <parent>base</parent>
    <child>wheel_yaw</child>
    <axis>
      <xyz>0 0 1</xyz>
      <dynamics>
        <friction>2.868886116114374</friction>
      </dynamics>
    </axis>
  </joint>

  <joint name="wheel_pitch" type="revolute">
    <parent>base</parent>
    <child>wheel_pitch</child>
    <axis>
      <xyz>0 0 1</xyz>
      <dynamics>
        <friction>2.3260088395574865</friction>
      </dynamics>
    </axis>
  </joint>

  <joint name="satellite_world" type="fixed">
    <parent>world</parent>
    <child>base</child>
  </joint>

  <plugin name="satellite_plugin" filename="libSatellitePlugin.so">

    <yaw_ratio>0.1</yaw_ratio>
    <yaw_pid>1000 0 10</yaw_pid>
    <yaw_target>-0.085548854037518</yaw_target>

    <pitch_ratio>0.1</pitch_ratio>
    <pitch_pid>1000 100 10</pitch_pid>
    <pitch_target>0.8442160259323275</pitch_target>

    <!-- Tolerance in degrees -->
    <tolerance>5</tolerance>

    <!-- Target time to hold position in seconds -->
    <time>5</time>

    <topic>/task1/checkpoint2/satellite</topic>
    <frequency>100</frequency>

  </plugin>

</model>


    <!-- Checkpoint 1 - Box plugin -->
    

    <plugin name="boxT1CP1" filename="libBoxContainsPlugin.so">
      <entity>valkyrie</entity>
      <namespace>task1/checkpoint1</namespace>
      <pose>
        1.9859999999999998
        -0.5620000000000003
        2.5
        0
        0
        -1.5707963267948968
      </pose>
      <size>1 1 5</size>
    </plugin>

    <!-- Bling -->
    <include>
      <name>mars_crate_long_3</name>
      <pose>
      1.9860000000000004
      1.5619999999999996
      0
      0
      0
      0.785398163397448
      </pose>
      <uri>model://mars_crate_long</uri>
    </include>


    <!-- Walkway -->
    <include>
      <name>walkway_3</name>
      <pose>
      2.748
      -5.599085165701699e-16
      -0.052151
      0
      0
      -1.5707963267948968
      </pose>
      <uri>model://walkway_metal_straight</uri>
    </include>


    <!-- Bling -->
    <include>
      <name>mars_rock_2_4</name>
      <pose>
      3.5100000000000002
      1.2619999999999993
      0
      0
      0
      -2.4492935982947064e-16
      </pose>
      <uri>model://mars_rock_2</uri>
    </include>


    <!-- Bling -->
    <include>
      <name>mars_crate_5</name>
      <pose>
      3.5100000000000002
      -1.1620000000000008
      0
      0
      0
      3.141592653589793
      </pose>
      <uri>model://mars_crate</uri>
    </include>


    <!-- Final box 1 -->
    <include>
      <name>walkway_4</name>
      <pose>
      5.796
      -1.1198170331403398e-15
      -0.052151
      0
      0
      3.141592653589793
      </pose>
      <uri>model://walkway_finish_adjacent</uri>
    </include>


    <!-- Checkpoint 3 - Box plugin -->
    <plugin name="boxT1CP3" filename="libBoxContainsPlugin.so">
      <entity>valkyrie</entity>
      <namespace>task1/checkpoint3</namespace>
      <pose>
        5.796
        -1.1198170331403398e-15
        2.5
        0
        0
        3.141592653589793
      </pose>
      <size>3.048 3.048 5</size>
    </plugin>

    <!-- Bling -->
    <include>
      <name>mars_rock_2_6</name>
      <pose>
      7.82
      -1.398301715266448e-15
      0
      0
      0
      -1.5707963267948968
      </pose>
      <uri>model://mars_rock_2</uri>
    </include>


    <!-- Bling -->
    <include>
      <name>mars_rock_3_7</name>
      <pose>
      5.796
      2.6239999999999988
      0
      0
      0
      -2.449293598294706e-16
      </pose>
      <uri>model://mars_rock_3</uri>
    </include>


    <!-- /TASK 1 -->
    

    

    <!-- TASK 2 -->

    <!-- Walkway -->
    <include>
      <name>walkway_5</name>
      <pose>
      5.796
      -1.5240000000000011
      -0.052151
      0
      0
      3.141592653589793
      </pose>
      <uri>model://walkway_metal_straight</uri>
    </include>


    <!-- Bling -->
    <include>
      <name>mars_rock_1_8</name>
      <pose>
      6.958
      -2.2860000000000014
      0
      0
      0
      -1.5707963267948968
      </pose>
      <uri>model://mars_rock_1</uri>
    </include>


    <!-- Bling -->
    <include>
      <name>mars_rock_2_9</name>
      <pose>
      4.534
      -2.286000000000001
      0
      0
      0
      1.5707963267948966
      </pose>
      <uri>model://mars_rock_2</uri>
    </include>


    <!-- Walkway -->
    <include>
      <name>walkway_6</name>
      <pose>
      5.796
      -3.048000000000001
      -0.052151
      0
      0
      3.141592653589793
      </pose>
      <uri>model://walkway_metal_straight</uri>
    </include>


    <!-- Rover -->
    

    <!-- Solar panel -->
    

    

<model name="solar_panel">

  <pose>
    4.034
    -3.810000000000001
    0
    0
    0
    1.5707963267948966
  </pose>

  <link name="base">

    <inertial>
      <pose>
      0
      0
      0.04
      0
      0
      0
      </pose>
      <inertia>
        <ixx>0.0041666666666666675</ixx>
        <iyy>0.05577866666666667</iyy>
        <izz>0.05827866666666667</izz>
      </inertia>
      <mass>4.0</mass>
    </inertial>


    <collision name="collision">
      <geometry>
        <mesh>
          <uri>model://solar_panel/meshes/solar_panel.obj</uri>
          <submesh>
            <name>Base</name>
          </submesh>
          <scale>0.001 0.001 0.001</scale>
        </mesh>
      </geometry>
      <surface>
        <contact>
          <ode>
            <kp>1e5</kp>
            <kd>1</kd>
            <max_vel>0.1</max_vel>
            <min_depth>0.0015</min_depth>
          </ode>
        </contact>
      </surface>
    </collision>
    <visual name="visual">
      <geometry>
        <mesh>
          <uri>model://solar_panel/meshes/solar_panel.obj</uri>
          <submesh>
            <name>Base</name>
          </submesh>
          <scale>0.001 0.001 0.001</scale>
        </mesh>
      </geometry>
    </visual>
  </link>

  <link name="panel_01">

    <inertial>
      <pose>
      0
      0.05
      0.24
      0
      0
      0
      </pose>
      <inertia>
        <ixx>0.00237075</ixx>
        <iyy>0.005786083333333334</iyy>
        <izz>0.003452833333333334</izz>
      </inertia>
      <mass>0.25</mass>
    </inertial>


    <collision name="panel_collision">
      <geometry>
        <mesh>
          <uri>model://solar_panel/meshes/solar_panel.obj</uri>
          <submesh>
            <name>Panel_Large_01</name>
          </submesh>
          <scale>0.001 0.001 0.001</scale>
        </mesh>
      </geometry>
      <surface>
        <contact>
          <ode>
            <kp>1e5</kp>
            <kd>1</kd>
            <max_vel>0.1</max_vel>
            <min_depth>0.0015</min_depth>
          </ode>
        </contact>
      </surface>
    </collision>
    <visual name="panel_visual">
      <geometry>
        <mesh>
          <uri>model://solar_panel/meshes/solar_panel.obj</uri>
          <submesh>
            <name>Panel_Large_01</name>
          </submesh>
          <scale>0.001 0.001 0.001</scale>
        </mesh>
      </geometry>
    </visual>
    <collision name="button_housing_collision">
      <geometry>
        <mesh>
          <uri>model://solar_panel/meshes/solar_panel.obj</uri>
          <submesh>
            <name>ButtonHousing</name>
          </submesh>
          <scale>0.001 0.001 0.001</scale>
        </mesh>
      </geometry>
      <surface>
        <contact>
          <ode>
            <kp>1e5</kp>
            <kd>1</kd>
            <max_vel>0.1</max_vel>
            <min_depth>0.0015</min_depth>
          </ode>
        </contact>
      </surface>
    </collision>
    <visual name="button_housing_visual">
      <geometry>
        <mesh>
          <uri>model://solar_panel/meshes/solar_panel.obj</uri>
          <submesh>
            <name>ButtonHousing</name>
          </submesh>
          <scale>0.001 0.001 0.001</scale>
        </mesh>
      </geometry>
    </visual>
  </link>


  <link name="panel_02">

    <inertial>
      <pose>
      0
      -0.05
      0.24
      0
      0
      0
      </pose>
      <inertia>
        <ixx>0.00237075</ixx>
        <iyy>0.005786083333333334</iyy>
        <izz>0.003452833333333334</izz>
      </inertia>
      <mass>0.25</mass>
    </inertial>


    <collision name="collision">
      <geometry>
        <mesh>
          <uri>model://solar_panel/meshes/solar_panel.obj</uri>
          <submesh>
            <name>Panel_Large_02</name>
          </submesh>
          <scale>0.001 0.001 0.001</scale>
        </mesh>
      </geometry>
      <surface>
        <contact>
          <ode>
            <kp>1e5</kp>
            <kd>1</kd>
            <max_vel>0.1</max_vel>
            <min_depth>0.0015</min_depth>
          </ode>
        </contact>
      </surface>
    </collision>
    <visual name="visual">
      <geometry>
        <mesh>
          <uri>model://solar_panel/meshes/solar_panel.obj</uri>
          <submesh>
            <name>Panel_Large_02</name>
          </submesh>
          <scale>0.001 0.001 0.001</scale>
        </mesh>
      </geometry>
    </visual>
  </link>

  <link name="panel_small_01">

    <pose>0.2 0.03 0.2 0 0 0</pose>

    <inertial>
      <pose>
      -0.1
      -0.015
      0.005
      0
      0
      0
      </pose>
      <inertia>
        <ixx>0.0004852083333333333</ixx>
        <iyy>0.0008133333333333333</iyy>
        <izz>0.00033854166666666673</izz>
      </inertia>
      <mass>0.1</mass>
    </inertial>


    <collision name="collision">
      <pose>-0.2 -0.03 -0.2 0 0 0</pose>
      <geometry>
        <mesh>
          <uri>model://solar_panel/meshes/solar_panel.obj</uri>
          <submesh>
            <name>Panel_Small_01</name>
          </submesh>
          <scale>0.001 0.001 0.001</scale>
        </mesh>
      </geometry>
      <surface>
        <contact>
          <ode>
            <kp>1e5</kp>
            <kd>1</kd>
            <max_vel>0.1</max_vel>
            <min_depth>0.0015</min_depth>
          </ode>
        </contact>
      </surface>
    </collision>
    <visual name="visual">
      <pose>-0.2 -0.03 -0.2 0 0 0</pose>
      <geometry>
        <mesh>
          <uri>model://solar_panel/meshes/solar_panel.obj</uri>
          <submesh>
            <name>Panel_Small_01</name>
          </submesh>
          <scale>0.001 0.001 0.001</scale>
        </mesh>
      </geometry>
    </visual>
  </link>

  <link name="panel_small_02">

    <pose>0.2 -0.03 0.2 0 0 0</pose>

    <inertial>
      <pose>
      -0.1
      0.015
      0.005
      0
      0
      0
      </pose>
      <inertia>
        <ixx>0.0004852083333333333</ixx>
        <iyy>0.0008133333333333333</iyy>
        <izz>0.00033854166666666673</izz>
      </inertia>
      <mass>0.1</mass>
    </inertial>


    <collision name="collision">
      <pose>-0.2 0.03 -0.2 0 0 0</pose>
      <geometry>
        <mesh>
          <uri>model://solar_panel/meshes/solar_panel.obj</uri>
          <submesh>
            <name>Panel_Small_02</name>
          </submesh>
          <scale>0.001 0.001 0.001</scale>
        </mesh>
      </geometry>
      <surface>
        <contact>
          <ode>
            <kp>1e5</kp>
            <kd>1</kd>
            <max_vel>0.1</max_vel>
            <min_depth>0.0015</min_depth>
          </ode>
        </contact>
      </surface>
    </collision>
    <visual name="visual">
      <pose>-0.2 0.03 -0.2 0 0 0</pose>
      <geometry>
        <mesh>
          <uri>model://solar_panel/meshes/solar_panel.obj</uri>
          <submesh>
            <name>Panel_Small_02</name>
          </submesh>
          <scale>0.001 0.001 0.001</scale>
        </mesh>
      </geometry>
    </visual>
  </link>

  <link name="panel_small_03">

    <pose>-0.2 0.03 0.2 0 0 0</pose>

    <inertial>
      <pose>
      0.1
      -0.015
      0.005
      0
      0
      0
      </pose>
      <inertia>
        <ixx>0.0004852083333333333</ixx>
        <iyy>0.0008133333333333333</iyy>
        <izz>0.00033854166666666673</izz>
      </inertia>
      <mass>0.1</mass>
    </inertial>


    <collision name="collision">
      <pose>0.2 -0.03 -0.2 0 0 0</pose>
      <geometry>
        <mesh>
          <uri>model://solar_panel/meshes/solar_panel.obj</uri>
          <submesh>
            <name>Panel_Small_03</name>
          </submesh>
          <scale>0.001 0.001 0.001</scale>
        </mesh>
      </geometry>
      <surface>
        <contact>
          <ode>
            <kp>1e5</kp>
            <kd>1</kd>
            <max_vel>0.1</max_vel>
            <min_depth>0.0015</min_depth>
          </ode>
        </contact>
      </surface>
    </collision>
    <visual name="visual">
      <pose>0.2 -0.03 -0.2 0 0 0</pose>
      <geometry>
        <mesh>
          <uri>model://solar_panel/meshes/solar_panel.obj</uri>
          <submesh>
            <name>Panel_Small_03</name>
          </submesh>
          <scale>0.001 0.001 0.001</scale>
        </mesh>
      </geometry>
    </visual>
  </link>

  <link name="panel_small_04">

    <pose>-0.2 -0.03 0.2 0 0 0</pose>

    <inertial>
      <pose>
      0.1
      0.015
      0.005
      0
      0
      0
      </pose>
      <inertia>
        <ixx>0.0004852083333333333</ixx>
        <iyy>0.0008133333333333333</iyy>
        <izz>0.00033854166666666673</izz>
      </inertia>
      <mass>0.1</mass>
    </inertial>


    <collision name="collision">
      <pose>0.2 0.03 -0.2 0 0 0</pose>
      <geometry>
        <mesh>
          <uri>model://solar_panel/meshes/solar_panel.obj</uri>
          <submesh>
            <name>Panel_Small_04</name>
          </submesh>
          <scale>0.001 0.001 0.001</scale>
        </mesh>
      </geometry>
      <surface>
        <contact>
          <ode>
            <kp>1e5</kp>
            <kd>1</kd>
            <max_vel>0.1</max_vel>
            <min_depth>0.0015</min_depth>
          </ode>
        </contact>
      </surface>
    </collision>
    <visual name="visual">
      <pose>0.2 0.03 -0.2 0 0 0</pose>
      <geometry>
        <mesh>
          <uri>model://solar_panel/meshes/solar_panel.obj</uri>
          <submesh>
            <name>Panel_Small_04</name>
          </submesh>
          <scale>0.001 0.001 0.001</scale>
        </mesh>
      </geometry>
    </visual>
  </link>


  <link name="button">

    <pose>-0.155 0 0.4 0 0 0</pose>

    <inertial>
      <pose>
      0
      0
      0.017
      0
      0
      0
      </pose>
      <inertia>
        <ixx>4.8333333333333334e-05</ixx>
        <iyy>4.8333333333333334e-05</iyy>
        <izz>8.166666666666668e-05</izz>
      </inertia>
      <mass>0.1</mass>
    </inertial>


    <collision name="collision">
      <pose>0.155 0 -0.4 0 0 0</pose>
      <geometry>
        <mesh>
          <uri>model://solar_panel/meshes/solar_panel.obj</uri>
          <submesh>
            <name>Button</name>
          </submesh>
          <scale>0.001 0.001 0.001</scale>
        </mesh>
      </geometry>
      <surface>
        <contact>
          <ode>
            <kp>1e5</kp>
            <kd>1</kd>
            <max_vel>0.1</max_vel>
            <min_depth>0.0015</min_depth>
          </ode>
        </contact>
      </surface>
    </collision>
    <visual name="visual">
      <pose>0.155 0 -0.4 0 0 0</pose>
      <geometry>
        <mesh>
          <uri>model://solar_panel/meshes/solar_panel.obj</uri>
          <submesh>
            <name>Button</name>
          </submesh>
          <scale>0.001 0.001 0.001</scale>
        </mesh>
      </geometry>
    </visual>

    <sensor name="button_contact" type="contact">
      <contact>
        <collision>collision</collision>
      </contact>
    </sensor>

  </link>

  

  <joint name="base_panel_01" type="revolute">
    <pose>0 0.0455 0.095 0 0 0</pose>
    <parent>base</parent>
    <child>panel_01</child>
    <axis>
      <xyz>1 0 0</xyz>
      <limit>
       <lower>-1.5707963267948966</lower>
       <upper>0</upper>
      </limit>
      <dynamics>
        <damping>0.1</damping>
      </dynamics>
    </axis>
  </joint>

  <joint name="base_panel_02" type="revolute">
    <pose>0 -0.0455 0.095 0 0 0</pose>
    <parent>base</parent>
    <child>panel_02</child>
    <axis>
      <xyz>1 0 0</xyz>
      <limit>
       <lower>0</lower>
       <upper>1.5707963267948966</upper>
      </limit>
      <dynamics>
        <damping>0.1</damping>
      </dynamics>
    </axis>
  </joint>

  <joint name="panel_01_panel_small_01" type="revolute">
    <parent>panel_01</parent>
    <child>panel_small_01</child>
    <axis>
      <xyz>0 0 1</xyz>
      <limit>
       <lower>0</lower>
       <upper>3.141592653589793</upper>
      </limit>
      <dynamics>
        <damping>0.1</damping>
      </dynamics>
    </axis>
  </joint>

  <joint name="panel_02_panel_small_02" type="revolute">
    <parent>panel_02</parent>
    <child>panel_small_02</child>
    <axis>
      <xyz>0 0 1</xyz>
      <limit>
       <lower>-3.141592653589793</lower>
       <upper>0</upper>
      </limit>
      <dynamics>
        <damping>0.1</damping>
      </dynamics>
    </axis>
  </joint>

  <joint name="panel_01_panel_small_03" type="revolute">
    <parent>panel_01</parent>
    <child>panel_small_03</child>
    <axis>
      <xyz>0 0 1</xyz>
      <limit>
       <lower>-3.141592653589793</lower>
       <upper>0</upper>
      </limit>
      <dynamics>
        <damping>0.1</damping>
      </dynamics>
    </axis>
  </joint>

  <joint name="panel_02_panel_small_04" type="revolute">
    <parent>panel_02</parent>
    <child>panel_small_04</child>
    <axis>
      <xyz>0 0 1</xyz>
      <limit>
       <lower>0</lower>
       <upper>3.141592653589793</upper>
      </limit>
      <dynamics>
        <damping>0.1</damping>
      </dynamics>
    </axis>
  </joint>

  
  <joint name="button" type="prismatic">
    <pose>0 0 0.005 0 0 0</pose>
    <parent>panel_01</parent>
    <child>button</child>
    <axis>
      <xyz>0 0 1</xyz>
      <limit>
       <lower>-0.005</lower>
       <upper>0</upper>
      </limit>
      <dynamics>
        <damping>10</damping>
        <spring_stiffness>1000</spring_stiffness>
        <spring_reference>0</spring_reference>
      </dynamics>
    </axis>
  </joint>

  <joint name="lock_1" type="fixed">
    <parent>panel_01</parent>
    <child>panel_02</child>
  </joint>

  <joint name="lock_2" type="fixed">
    <parent>panel_small_01</parent>
    <child>panel_small_03</child>
  </joint>

  <joint name="lock_3" type="fixed">
    <parent>panel_small_02</parent>
    <child>panel_small_04</child>
  </joint>

  <plugin name="solar_panel_plugin" filename="libSolarPanelPlugin.so">
  </plugin>

</model>


    <!-- Bling -->
    <include>
      <name>mars_crate_long_10</name>
      <pose>
      7.358
      -3.810000000000001
      0
      0
      0
      -0.7853981633974485
      </pose>
      <uri>model://mars_crate_long</uri>
    </include>


    <!-- Walkway -->
    <include>
      <name>walkway_7</name>
      <pose>
      5.796
      -4.572000000000001
      -0.052151
      0
      0
      3.141592653589793
      </pose>
      <uri>model://walkway_metal_straight</uri>
    </include>


    <!-- Solar Array -->
    

    <!-- Bling -->
    <include>
      <name>mars_crate_11</name>
      <pose>
      6.958
      -5.334000000000001
      0
      0
      0
      -1.5707963267948968
      </pose>
      <uri>model://mars_crate</uri>
    </include>


    <!-- Walkway -->
    <include>
      <name>walkway_8</name>
      <pose>
      5.796
      -6.096000000000001
      -0.052151
      0
      0
      3.141592653589793
      </pose>
      <uri>model://walkway_metal_straight</uri>
    </include>


    <!-- Final Box 2 -->
    <include>
      <name>walkway_9</name>
      <pose>
      5.796
      -9.144000000000002
      -0.052151
      0
      0
      1.5707963267948966
      </pose>
      <uri>model://walkway_finish_opposite</uri>
    </include>


    <!-- Checkpoint 6 - Box plugin -->
    <plugin name="boxT2CP6" filename="libBoxContainsPlugin.so">
      <entity>valkyrie</entity>
      <namespace>task2/checkpoint6</namespace>
      <pose>
        5.796
        -9.144000000000002
        2.5
        0
        0
        1.5707963267948966
      </pose>
      <size>3.048 3.048 5</size>
    </plugin>

    <!-- Bling -->
    <include>
      <name>mars_crate_long_12</name>
      <pose>
      3.4720000000000004
      -9.144000000000002
      0
      0
      0
      2.356194490192345
      </pose>
      <uri>model://mars_crate_long</uri>
    </include>


    <!-- Bling -->
    <include>
      <name>mars_crate_long_13</name>
      <pose>
      8.120000000000001
      -9.144000000000002
      0
      0
      0
      -0.7853981633974485
      </pose>
      <uri>model://mars_crate_long</uri>
    </include>


    <!-- /TASK 2 -->
    

    

    <!-- TASK 3 -->

    <!-- Walkway -->
    <include>
      <name>walkway_10</name>
      <pose>
      5.796
      -10.668000000000003
      -0.052151
      0
      0
      3.141592653589793
      </pose>
      <uri>model://walkway_metal_straight</uri>
    </include>


    <!-- Walkway -->
    <include>
      <name>walkway_11</name>
      <pose>
      6.335470092
      -13.492734000000004
      -0.052151
      0
      0
      0.7853981633974483
      </pose>
      <uri>model://walkway_metal_45</uri>
    </include>


    <!-- Bling -->
    <include>
      <name>mars_rock_1_14</name>
      <pose>
      4.974996644997083
      -13.775576712474622
      0
      0
      0
      2.356194490192345
      </pose>
      <uri>model://mars_rock_1</uri>
    </include>


    <!-- Bling -->
    <include>
      <name>mars_rock_1_15</name>
      <pose>
      4.545326444458495
      -12.964694940081138
      0
      0
      0
      1.5707963267948963
      </pose>
      <uri>model://mars_rock_1</uri>
    </include>


    <!-- Habitat -->
    

    <!-- TODO: Put the table inside the habitat -->

    <!-- Table -->
    
    <include>
      <pose>
        7.749683654373095
        -14.9069475623731
        0
        0
        0
        -2.3561944901923453
      </pose>
      <uri>model://space_table</uri>
    </include>

    <!-- Air leak detector -->
    

    

<model name="air_leak_detector">

  <pose>
    7.749683654373095
    -14.9069475623731
    0.79448
    1.5707963267948966
    0
    -2.3561944901923453
  </pose>

  <link name="base">

    <inertial>
      <pose>
      0
      -0.00063
      0.026760000000000003
      0
      0
      0
      </pose>
      <inertia>
        <ixx>0.003206729933333333</ixx>
        <iyy>0.0006035883333333333</iyy>
        <izz>0.003333989666666666</izz>
      </inertia>
      <mass>1.0</mass>
    </inertial>


    <collision name="collision">
      <geometry>
        <mesh>
          <scale>0.02 0.02 0.02</scale>
          <uri>model://air_leak_detector/meshes/air_leak_detector.obj</uri>
        </mesh>
      </geometry>
      <surface>
        <contact>
          <ode>
            <kp>1e5</kp>
            <kd>1</kd>
            <max_vel>0.1</max_vel>
            <min_depth>0.0015</min_depth>
          </ode>
        </contact>
      </surface>
    </collision>

    <visual name="visual">
      <geometry>
        <mesh>
          <scale>0.02 0.02 0.02</scale>
          <uri>model://air_leak_detector/meshes/air_leak_detector.obj</uri>
        </mesh>
      </geometry>
    </visual>

  </link>

</model>



    <!-- TODO: Put the box inside the habitat -->

    <!-- Checkpoint 8 - Box plugin -->

    <plugin name="boxT3CP8" filename="libBoxContainsPlugin.so">
      <entity>valkyrie</entity>
      <namespace>task3/checkpoint8</namespace>
      <pose>
        6.335470092
        -13.492734000000004
        2.5
        0
        0
        -2.3561944901923453
      </pose>
      <size>3.048 3.048 5</size>
    </plugin>

    <!-- /TASK 3 -->
    

    <!-- Finals plugin -->
    <plugin name="finals" filename="libFinalsPlugin.so">

      
        <task_1_timeout>1800</task_1_timeout>

        <task_1_checkpoint_2_pose>
          1.9859999999999998
          -0.5620000000000003
          1.1
          0
          0
          -1.5707963267948968
        </task_1_checkpoint_2_pose>

        <task_1_checkpoint_3_pose>
          1.9859999999999998
          -0.5620000000000003
          1.1
          0
          0
          -1.5707963267948968
        </task_1_checkpoint_3_pose>
      

      
        <task_2_timeout>3600</task_2_timeout>

        <task_2_checkpoint_1_pose>
          5.796
          -1.1198170331403398e-15
          1.1
          0
          0
          3.141592653589793
        </task_2_checkpoint_1_pose>

        <task_2_checkpoint_2_pose>
          5.796
          -1.5240000000000011
          1.1
          0
          0
          3.141592653589793
        </task_2_checkpoint_2_pose>

        <task_2_checkpoint_3_pose>
          5.796
          -1.5240000000000011
          1.1
          0
          0
          3.141592653589793
        </task_2_checkpoint_3_pose>

        <task_2_checkpoint_4_pose>
          5.796
          -1.5240000000000011
          1.1
          0
          0
          3.141592653589793
        </task_2_checkpoint_4_pose>

        <task_2_checkpoint_5_pose>
          5.796
          -1.5240000000000011
          1.1
          0
          0
          3.141592653589793
        </task_2_checkpoint_5_pose>

        <task_2_checkpoint_6_pose>
          5.796
          -1.5240000000000011
          1.1
          0
          0
          3.141592653589793
        </task_2_checkpoint_6_pose>
      

      
        <task_3_timeout>7200</task_3_timeout>

        <task_3_checkpoint_1_pose>
          5.796
          -9.144000000000002
          1.1
          0
          0
          1.5707963267948966
        </task_3_checkpoint_1_pose>

        <task_3_checkpoint_2_pose>
          5.796
          -9.144000000000002
          1.1
          0
          0
          1.5707963267948966
        </task_3_checkpoint_2_pose>

        <task_3_checkpoint_3_pose>
          5.796
          -9.144000000000002
          1.1
          0
          0
          1.5707963267948966
        </task_3_checkpoint_3_pose>

        <task_3_checkpoint_4_pose>
          5.796
          -9.144000000000002
          1.1
          0
          0
          1.5707963267948966
        </task_3_checkpoint_4_pose>

        <task_3_checkpoint_5_pose>
          5.796
          -9.144000000000002
          1.1
          0
          0
          1.5707963267948966
        </task_3_checkpoint_5_pose>

        <task_3_checkpoint_6_pose>
          5.796
          -9.144000000000002
          1.1
          0
          0
          1.5707963267948966
        </task_3_checkpoint_6_pose>

        <task_3_checkpoint_7_pose>
          5.796
          -9.144000000000002
          1.1
          0
          0
          1.5707963267948966
        </task_3_checkpoint_7_pose>

        <task_3_checkpoint_8_pose>
          5.796
          -9.144000000000002
          1.1
          0
          0
          1.5707963267948966
        </task_3_checkpoint_8_pose>
      

    </plugin>

  </world>
</sdf>
