<?xml version="1.0" ?>

<sdf version="1.6">
  <world name="SRC_finals">

    <physics type="ode">
      <real_time_update_rate>1000.0</real_time_update_rate>
      <max_step_size>0.001</max_step_size>
      <real_time_factor>1</real_time_factor>
      <ode>
        <solver>
          <type>quick</type>
          <iters>150</iters>
          <precon_iters>0</precon_iters>
          <sor>1.400000</sor>
          <use_dynamic_moi_rescaling>1</use_dynamic_moi_rescaling>
        </solver>
        <constraints>
          <cfm>0.000000</cfm>
          <erp>0.800000</erp>
          <contact_max_correcting_vel>2000.000000</contact_max_correcting_vel>
          <contact_surface_layer>0.01000</contact_surface_layer>
        </constraints>
      </ode>
    </physics>

    <!-- GUI -->
    <gui fullscreen='0'>
      <camera name='user_camera'>
        <pose>-4.1 -0.2 3.3 0 0.37 0</pose>
      </camera>
    </gui>

    <!-- Scene -->
    <scene>
      <background>0.968627451 0.690196078 0.384313725 1.0</background>
      <grid>0</grid>
      <origin_visual>0</origin_visual>
    </scene>

    <!-- A global light source -->
    <light type="directional" name="sun">
      <cast_shadows>true</cast_shadows>
      <pose>0 0 1000 -0.08583453749473446 -1.2308108412036807 0</pose>
      <diffuse>0.8 0.8 0.8 1</diffuse>
      <specular>0.2 0.2 0.2 1</specular>
      <attenuation>
        <range>1000</range>
        <constant>0.9</constant>
        <linear>0.01</linear>
        <quadratic>0.001</quadratic>
      </attenuation>
      <direction>-0.5 0.1 -0.9</direction>
    </light>

    <!-- Background -->
    <include>
      <uri>model://heightmap_mars</uri>
    </include>

    <!-- START WALKWAY -->

    <!-- Walkway -->
    <include>
      <name>walkway_1</name>
      <pose>
      -0.3
      0
      -0.052151
      0
      0
      -1.5707963267948968
      </pose>
      <uri>model://walkway_metal_straight</uri>
    </include>


    <!-- Bling -->
    <include>
      <name>mars_crate_long_1</name>
      <pose>
      0.4619999999999998
      -1.5620000000000003
      0
      0
      0
      -2.3561944901923453
      </pose>
      <uri>model://mars_crate_long</uri>
    </include>


    <!-- Bling -->
    <include>
      <name>mars_crate_long_2</name>
      <pose>
      0.46200000000000035
      1.5619999999999998
      0
      0
      0
      0.785398163397448
      </pose>
      <uri>model://mars_crate_long</uri>
    </include>


    

    <!-- TASK 1 -->

    <!-- Walkway -->
    <include>
      <name>walkway_2</name>
      <pose>
      2.524734
      0.5394700919999994
      -0.052151
      0
      0
      2.356194490192345
      </pose>
      <uri>model://walkway_metal_45</uri>
    </include>


    <!-- Satellite -->
    

    

<model name="satellite_dish">

  <pose>
    1.9966949400811331
    -2.8506735555415057
    0
    0
    0
    3.141592653589793
  </pose>

  <link name="base">
    <inertial>
      <pose>0 -0.6077 0.3193 0 0 0</pose>
      <inertia>
        <ixx>165.1022</ixx>
        <ixy>0</ixy>
        <ixz>0</ixz>
        <iyy>13.8377</iyy>
        <iyz>0</iyz>
        <izz>170.3359</izz>
      </inertia>
      <mass>400</mass>
    </inertial>
    <collision name="collision">
      <geometry>
        <mesh>
          <uri>model://satellite_dish/meshes/satellite_dish.dae</uri>
          <submesh>
            <name>Base</name>
          </submesh>
        </mesh>
      </geometry>
    </collision>
    <visual name="visual">
      <geometry>
        <mesh>
          <uri>model://satellite_dish/meshes/satellite_dish.dae</uri>
          <submesh>
            <name>Base</name>
          </submesh>
        </mesh>
      </geometry>
    </visual>
  </link>

  <link name="pivot">
    <pose>0 0 1.595 0 0 0</pose>
    <inertial>
      <inertia>
        <ixx>0.00073</ixx>
        <ixy>0</ixy>
        <ixz>0</ixz>
        <iyy>0.000598</iyy>
        <iyz>0</iyz>
        <izz>0.00057</izz>
      </inertia>
      <mass>0.82</mass>
    </inertial>
    <collision name="collision">
      <pose>0 0 -1.595 0 0 0</pose>
      <geometry>
        <mesh>
          <uri>model://satellite_dish/meshes/satellite_dish.dae</uri>
          <submesh>
            <name>Pivot</name>
          </submesh>
        </mesh>
      </geometry>
    </collision>
    <visual name="visual">
      <pose>0 0 -1.595 0 0 0</pose>
      <geometry>
        <mesh>
          <uri>model://satellite_dish/meshes/satellite_dish.dae</uri>
          <submesh>
            <name>Pivot</name>
          </submesh>
        </mesh>
      </geometry>
    </visual>
  </link>

  <link name="dish">
    <pose>0 0 1.595 0.43 0 0</pose>
    <inertial>
      <pose>0 0.2 0 0 0 0</pose>
      <inertia>
        <ixx>0.92468</ixx>
        <ixy>0</ixy>
        <ixz>0</ixz>
        <iyy>1.87729</iyy>
        <iyz>0</iyz>
        <izz>0.97826</izz>
      </inertia>
      <mass>17.0</mass>
    </inertial>
    <collision name="collision">
      <pose>0 -0.6519041 -1.451541 -0.43 0 0</pose>
      <geometry>
        <mesh>
          <uri>model://satellite_dish/meshes/satellite_dish.dae</uri>
          <submesh>
            <name>Dish</name>
          </submesh>
        </mesh>
      </geometry>
    </collision>
    <visual name="visual">
      <pose>0 -0.6519041 -1.451541 -0.43 0 0</pose>
      <geometry>
        <mesh>
          <uri>model://satellite_dish/meshes/satellite_dish.dae</uri>
          <submesh>
            <name>Dish</name>
          </submesh>
        </mesh>
      </geometry>
    </visual>
  </link>

  <link name="wheel_yaw">
    <pose>-0.2 -1.725 0.91 0.52 0 0</pose>
    <inertial>
      <inertia>
        <ixx>0.0123</ixx>
        <ixy>0</ixy>
        <ixz>0</ixz>
        <iyy>0.01295</iyy>
        <iyz>0</iyz>
        <izz>0.02500</izz>
      </inertia>
      <mass>2.0</mass>
    </inertial>
    <collision name="collision">
      <pose>0.2 1.060 -1.64 -0.52 0 0</pose>
      <geometry>
        <mesh>
          <uri>model://satellite_dish/meshes/satellite_dish.dae</uri>
          <submesh>
            <name>Wheel_01</name>
          </submesh>
        </mesh>
      </geometry>
    </collision>
    <collision name="collision_sphere">
      <pose>0.002 -0.123 0.082 0 0 0</pose>
      <geometry>
        <sphere>
          <radius>0.029</radius>
        </sphere>
      </geometry>
    </collision>
    <collision name="collision_cylinder">
      <pose>0.002 -0.122 0.025 0 0 0</pose>
      <geometry>
        <cylinder>
          <length>0.06</length>
          <radius>0.0125</radius>
        </cylinder>
      </geometry>
    </collision>
    <visual name="visual">
      <pose>0.2 1.060 -1.64 -0.52 0 0</pose>
      <geometry>
        <mesh>
          <uri>model://satellite_dish/meshes/satellite_dish.dae</uri>
          <submesh>
            <name>Wheel_01</name>
          </submesh>
        </mesh>
      </geometry>
    </visual>
  </link>

  <link name="wheel_pitch">
    <pose>0.2 -1.725 0.91 0.52 0 0</pose>
    <inertial>
      <inertia>
        <ixx>0.0123</ixx>
        <ixy>0</ixy>
        <ixz>0</ixz>
        <iyy>0.01295</iyy>
        <iyz>0</iyz>
        <izz>0.02500</izz>
      </inertia>
      <mass>2.0</mass>
    </inertial>
    <collision name="collision">
      <pose>-0.2 1.060 -1.64 -0.52 0 0</pose>
      <geometry>
        <mesh>
          <uri>model://satellite_dish/meshes/satellite_dish.dae</uri>
          <submesh>
            <name>Wheel_02</name>
          </submesh>
        </mesh>
      </geometry>
    </collision>
    <collision name="collision_sphere">
      <pose>-0.002 -0.123 0.082 0 0 0</pose>
      <geometry>
        <sphere>
          <radius>0.029</radius>
        </sphere>
      </geometry>
    </collision>
    <collision name="collision_cylinder">
      <pose>-0.002 -0.122 0.025 0 0 0</pose>
      <geometry>
        <cylinder>
          <length>0.06</length>
          <radius>0.0125</radius>
        </cylinder>
      </geometry>
    </collision>
    <visual name="visual">
      <pose>-0.2 1.060 -1.64 -0.52 0 0</pose>
      <geometry>
        <mesh>
          <uri>model://satellite_dish/meshes/satellite_dish.dae</uri>
          <submesh>
            <name>Wheel_02</name>
          </submesh>
        </mesh>
      </geometry>
    </visual>
  </link>

  <joint name="dish_yaw" type="revolute">
    <parent>base</parent>
    <child>pivot</child>
    <axis>
      <xyz>0 0 1</xyz>
      <dynamics>
        <damping>1000</damping>
      </dynamics>
    </axis>
  </joint>

  <joint name="dish_pitch" type="revolute">
    <parent>pivot</parent>
    <child>dish</child>
    <axis>
      <xyz>1 0 0</xyz>
      <limit>
        <lower>-0.2</lower>
        <upper>1.57</upper>
      </limit>
      <dynamics>
        <damping>100</damping>
      </dynamics>
    </axis>
  </joint>

  <joint name="wheel_yaw" type="revolute">
    <parent>base</parent>
    <child>wheel_yaw</child>
    <axis>
      <xyz>0 0 1</xyz>
      <dynamics>
        <friction>2.730695256532449</friction>
      </dynamics>
    </axis>
  </joint>

  <joint name="wheel_pitch" type="revolute">
    <parent>base</parent>
    <child>wheel_pitch</child>
    <axis>
      <xyz>0 0 1</xyz>
      <dynamics>
        <friction>2.342218905874097</friction>
      </dynamics>
    </axis>
  </joint>

  <joint name="satellite_world" type="fixed">
    <parent>world</parent>
    <child>base</child>
  </joint>

  <plugin name="satellite_plugin" filename="libSatellitePlugin.so">

    <yaw_ratio>0.1</yaw_ratio>
    <yaw_pid>1000 0 10</yaw_pid>
    <yaw_target>0.7290946444793698</yaw_target>

    <pitch_ratio>0.1</pitch_ratio>
    <pitch_pid>1000 100 10</pitch_pid>
    <pitch_target>1.2172919844153272</pitch_target>

    <!-- Tolerance in degrees -->
    <tolerance>5</tolerance>

    <!-- Target time to hold position in seconds -->
    <time>5</time>

    <topic>/task1/checkpoint2/satellite</topic>
    <frequency>100</frequency>

  </plugin>

</model>


    <!-- Checkpoint 1 - Box plugin -->
    

    <plugin name="boxT1CP1" filename="libBoxContainsPlugin.so">
      <entity>valkyrie</entity>
      <namespace>task1/checkpoint1</namespace>
      <pose>
        1.9966949400811336
        -0.6506735555415055
        2.5
        0
        0
        -1.570796326794897
      </pose>
      <size>1 1 5</size>
    </plugin>

    <!-- Bling -->
    <include>
      <name>mars_rock_3_3</name>
      <pose>
      3.302551459305202
      -1.3159781018335013
      0
      0
      0
      -2.356194490192345
      </pose>
      <uri>model://mars_rock_3</uri>
    </include>


    <!-- Walkway -->
    <include>
      <name>walkway_3</name>
      <pose>
      2.524734
      0.5394700919999994
      -0.052151
      0
      0
      -0.7853981633974485
      </pose>
      <uri>model://walkway_metal_straight</uri>
    </include>


    <!-- Bling -->
    <include>
      <name>mars_crate_4</name>
      <pose>
      2.2418912875253816
      1.8999435390029171
      0
      0
      0
      0.7853981633974481
      </pose>
      <uri>model://mars_crate</uri>
    </include>


    <!-- Bling -->
    <include>
      <name>mars_rock_1_5</name>
      <pose>
      3.885207447002917
      0.2566273795253801
      0
      0
      0
      -2.3561944901923453
      </pose>
      <uri>model://mars_rock_1</uri>
    </include>


    <!-- Final box 1 -->
    <include>
      <name>walkway_4</name>
      <pose>
      4.679995469056598
      2.694731561056596
      -0.052151
      0
      0
      -2.3561944901923453
      </pose>
      <uri>model://walkway_finish_opposite</uri>
    </include>


    <!-- Checkpoint 3 - Box plugin -->
    <plugin name="boxT1CP3" filename="libBoxContainsPlugin.so">
      <entity>valkyrie</entity>
      <namespace>task1/checkpoint3</namespace>
      <pose>
        4.679995469056598
        2.694731561056596
        2.5
        0
        0
        -2.3561944901923453
      </pose>
      <size>3.048 3.048 5</size>
    </plugin>

    <!-- Bling -->
    <include>
      <name>mars_rock_1_6</name>
      <pose>
      6.040468916059516
      1.334258114053678
      0
      0
      0
      -2.3561944901923453
      </pose>
      <uri>model://mars_rock_1</uri>
    </include>


    <!-- Bling -->
    <include>
      <name>mars_crate_long_7</name>
      <pose>
      3.036679309579062
      4.338047720534133
      0
      0
      0
      1.5707963267948961
      </pose>
      <uri>model://mars_crate_long</uri>
    </include>


    <!-- /TASK 1 -->
    

    

    <!-- TASK 2 -->
    

    <!-- Walkway -->
    <include>
      <name>walkway_5</name>
      <pose>
      5.757626203584897
      3.772362295584894
      -0.052151
      0
      0
      -0.7853981633974485
      </pose>
      <uri>model://walkway_metal_straight</uri>
    </include>


    <!-- Walkway -->
    <include>
      <name>walkway_6</name>
      <pose>
      6.835256938113195
      4.849993030113192
      -0.052151
      0
      0
      -0.7853981633974485
      </pose>
      <uri>model://walkway_metal_45</uri>
    </include>


    <!-- Rover -->
    

    <include>
      <pose>
        3.6532764227737324
        9.109604279980957
        0
        0
        0
        -2.3561944901923453
      </pose>
      <uri>model://mars_explorer</uri>
    </include>

    <!-- Solar panel -->
    

    

<model name="solar_panel">

  <pose>
    6.976678294350505
    5.786202408404182
    0.46
    0
    0
    -1.1963082642778597
  </pose>

  <link name="base">

    <inertial>
      <pose>
      0
      0
      0.04
      0
      0
      0
      </pose>
      <inertia>
        <ixx>0.0041666666666666675</ixx>
        <iyy>0.05577866666666667</iyy>
        <izz>0.05827866666666667</izz>
      </inertia>
      <mass>4.0</mass>
    </inertial>


    <collision name="collision">
      <geometry>
        <mesh>
          <uri>model://solar_panel/meshes/solar_panel.obj</uri>
          <submesh>
            <name>Base</name>
          </submesh>
          <scale>0.001 0.001 0.001</scale>
        </mesh>
      </geometry>
      <surface>
        <contact>
          <ode>
            <kp>1e5</kp>
            <kd>1</kd>
            <max_vel>0.1</max_vel>
            <min_depth>0.0015</min_depth>
          </ode>
        </contact>
      </surface>
    </collision>
    <visual name="visual">
      <geometry>
        <mesh>
          <uri>model://solar_panel/meshes/solar_panel.obj</uri>
          <submesh>
            <name>Base</name>
          </submesh>
          <scale>0.001 0.001 0.001</scale>
        </mesh>
      </geometry>
    </visual>

    <sensor name="base_sensor" type="contact">
      <contact>
        <collision>collision</collision>
      </contact>
    </sensor>

  </link>

  <link name="panel_01">

    <inertial>
      <pose>
      0
      0.05
      0.24
      0
      0
      0
      </pose>
      <inertia>
        <ixx>0.00237075</ixx>
        <iyy>0.005786083333333334</iyy>
        <izz>0.003452833333333334</izz>
      </inertia>
      <mass>0.25</mass>
    </inertial>


    <collision name="panel_collision">
      <geometry>
        <mesh>
          <uri>model://solar_panel/meshes/solar_panel.obj</uri>
          <submesh>
            <name>Panel_Large_01</name>
          </submesh>
          <scale>0.001 0.001 0.001</scale>
        </mesh>
      </geometry>
      <surface>
        <contact>
          <ode>
            <kp>1e5</kp>
            <kd>1</kd>
            <max_vel>0.1</max_vel>
            <min_depth>0.0015</min_depth>
          </ode>
        </contact>
      </surface>
    </collision>
    <visual name="panel_visual">
      <geometry>
        <mesh>
          <uri>model://solar_panel/meshes/solar_panel.obj</uri>
          <submesh>
            <name>Panel_Large_01</name>
          </submesh>
          <scale>0.001 0.001 0.001</scale>
        </mesh>
      </geometry>
    </visual>
    <collision name="button_housing_collision">
      <geometry>
        <mesh>
          <uri>model://solar_panel/meshes/solar_panel.obj</uri>
          <submesh>
            <name>ButtonHousing</name>
          </submesh>
          <scale>0.001 0.001 0.001</scale>
        </mesh>
      </geometry>
      <surface>
        <contact>
          <ode>
            <kp>1e5</kp>
            <kd>1</kd>
            <max_vel>0.1</max_vel>
            <min_depth>0.0015</min_depth>
          </ode>
        </contact>
      </surface>
    </collision>
    <visual name="button_housing_visual">
      <geometry>
        <mesh>
          <uri>model://solar_panel/meshes/solar_panel.obj</uri>
          <submesh>
            <name>ButtonHousing</name>
          </submesh>
          <scale>0.001 0.001 0.001</scale>
        </mesh>
      </geometry>
    </visual>

    <sensor name="panel1_sensor" type="contact">
      <contact>
        <collision>panel_collision</collision>
      </contact>
    </sensor>

  </link>


  <link name="panel_02">

    <inertial>
      <pose>
      0
      -0.05
      0.24
      0
      0
      0
      </pose>
      <inertia>
        <ixx>0.00237075</ixx>
        <iyy>0.005786083333333334</iyy>
        <izz>0.003452833333333334</izz>
      </inertia>
      <mass>0.25</mass>
    </inertial>


    <collision name="collision">
      <geometry>
        <mesh>
          <uri>model://solar_panel/meshes/solar_panel.obj</uri>
          <submesh>
            <name>Panel_Large_02</name>
          </submesh>
          <scale>0.001 0.001 0.001</scale>
        </mesh>
      </geometry>
      <surface>
        <contact>
          <ode>
            <kp>1e5</kp>
            <kd>1</kd>
            <max_vel>0.1</max_vel>
            <min_depth>0.0015</min_depth>
          </ode>
        </contact>
      </surface>
    </collision>
    <visual name="visual">
      <geometry>
        <mesh>
          <uri>model://solar_panel/meshes/solar_panel.obj</uri>
          <submesh>
            <name>Panel_Large_02</name>
          </submesh>
          <scale>0.001 0.001 0.001</scale>
        </mesh>
      </geometry>
    </visual>

    <sensor name="panel2_sensor" type="contact">
      <contact>
        <collision>collision</collision>
      </contact>
    </sensor>

  </link>

  <link name="panel_small_01">

    <pose>0.2 0.03 0.2 0 0 0</pose>

    <inertial>
      <pose>
      -0.1
      -0.015
      0.005
      0
      0
      0
      </pose>
      <inertia>
        <ixx>0.0004852083333333333</ixx>
        <iyy>0.0008133333333333333</iyy>
        <izz>0.00033854166666666673</izz>
      </inertia>
      <mass>0.1</mass>
    </inertial>


    <collision name="collision">
      <pose>-0.2 -0.03 -0.2 0 0 0</pose>
      <geometry>
        <mesh>
          <uri>model://solar_panel/meshes/solar_panel.obj</uri>
          <submesh>
            <name>Panel_Small_01</name>
          </submesh>
          <scale>0.001 0.001 0.001</scale>
        </mesh>
      </geometry>
      <surface>
        <contact>
          <ode>
            <kp>1e5</kp>
            <kd>1</kd>
            <max_vel>0.1</max_vel>
            <min_depth>0.0015</min_depth>
          </ode>
        </contact>
      </surface>
    </collision>
    <visual name="visual">
      <pose>-0.2 -0.03 -0.2 0 0 0</pose>
      <geometry>
        <mesh>
          <uri>model://solar_panel/meshes/solar_panel.obj</uri>
          <submesh>
            <name>Panel_Small_01</name>
          </submesh>
          <scale>0.001 0.001 0.001</scale>
        </mesh>
      </geometry>
    </visual>
  </link>

  <link name="panel_small_02">

    <pose>0.2 -0.03 0.2 0 0 0</pose>

    <inertial>
      <pose>
      -0.1
      0.015
      0.005
      0
      0
      0
      </pose>
      <inertia>
        <ixx>0.0004852083333333333</ixx>
        <iyy>0.0008133333333333333</iyy>
        <izz>0.00033854166666666673</izz>
      </inertia>
      <mass>0.1</mass>
    </inertial>


    <collision name="collision">
      <pose>-0.2 0.03 -0.2 0 0 0</pose>
      <geometry>
        <mesh>
          <uri>model://solar_panel/meshes/solar_panel.obj</uri>
          <submesh>
            <name>Panel_Small_02</name>
          </submesh>
          <scale>0.001 0.001 0.001</scale>
        </mesh>
      </geometry>
      <surface>
        <contact>
          <ode>
            <kp>1e5</kp>
            <kd>1</kd>
            <max_vel>0.1</max_vel>
            <min_depth>0.0015</min_depth>
          </ode>
        </contact>
      </surface>
    </collision>
    <visual name="visual">
      <pose>-0.2 0.03 -0.2 0 0 0</pose>
      <geometry>
        <mesh>
          <uri>model://solar_panel/meshes/solar_panel.obj</uri>
          <submesh>
            <name>Panel_Small_02</name>
          </submesh>
          <scale>0.001 0.001 0.001</scale>
        </mesh>
      </geometry>
    </visual>
  </link>

  <link name="panel_small_03">

    <pose>-0.2 0.03 0.2 0 0 0</pose>

    <inertial>
      <pose>
      0.1
      -0.015
      0.005
      0
      0
      0
      </pose>
      <inertia>
        <ixx>0.0004852083333333333</ixx>
        <iyy>0.0008133333333333333</iyy>
        <izz>0.00033854166666666673</izz>
      </inertia>
      <mass>0.1</mass>
    </inertial>


    <collision name="collision">
      <pose>0.2 -0.03 -0.2 0 0 0</pose>
      <geometry>
        <mesh>
          <uri>model://solar_panel/meshes/solar_panel.obj</uri>
          <submesh>
            <name>Panel_Small_03</name>
          </submesh>
          <scale>0.001 0.001 0.001</scale>
        </mesh>
      </geometry>
      <surface>
        <contact>
          <ode>
            <kp>1e5</kp>
            <kd>1</kd>
            <max_vel>0.1</max_vel>
            <min_depth>0.0015</min_depth>
          </ode>
        </contact>
      </surface>
    </collision>
    <visual name="visual">
      <pose>0.2 -0.03 -0.2 0 0 0</pose>
      <geometry>
        <mesh>
          <uri>model://solar_panel/meshes/solar_panel.obj</uri>
          <submesh>
            <name>Panel_Small_03</name>
          </submesh>
          <scale>0.001 0.001 0.001</scale>
        </mesh>
      </geometry>
    </visual>
  </link>

  <link name="panel_small_04">

    <pose>-0.2 -0.03 0.2 0 0 0</pose>

    <inertial>
      <pose>
      0.1
      0.015
      0.005
      0
      0
      0
      </pose>
      <inertia>
        <ixx>0.0004852083333333333</ixx>
        <iyy>0.0008133333333333333</iyy>
        <izz>0.00033854166666666673</izz>
      </inertia>
      <mass>0.1</mass>
    </inertial>


    <collision name="collision">
      <pose>0.2 0.03 -0.2 0 0 0</pose>
      <geometry>
        <mesh>
          <uri>model://solar_panel/meshes/solar_panel.obj</uri>
          <submesh>
            <name>Panel_Small_04</name>
          </submesh>
          <scale>0.001 0.001 0.001</scale>
        </mesh>
      </geometry>
      <surface>
        <contact>
          <ode>
            <kp>1e5</kp>
            <kd>1</kd>
            <max_vel>0.1</max_vel>
            <min_depth>0.0015</min_depth>
          </ode>
        </contact>
      </surface>
    </collision>
    <visual name="visual">
      <pose>0.2 0.03 -0.2 0 0 0</pose>
      <geometry>
        <mesh>
          <uri>model://solar_panel/meshes/solar_panel.obj</uri>
          <submesh>
            <name>Panel_Small_04</name>
          </submesh>
          <scale>0.001 0.001 0.001</scale>
        </mesh>
      </geometry>
    </visual>
  </link>


  <link name="button">

    <pose>-0.155 0 0.4 0 0 0</pose>

    <inertial>
      <pose>
      0
      0
      0.017
      0
      0
      0
      </pose>
      <inertia>
        <ixx>4.8333333333333334e-05</ixx>
        <iyy>4.8333333333333334e-05</iyy>
        <izz>8.166666666666668e-05</izz>
      </inertia>
      <mass>0.1</mass>
    </inertial>


    <collision name="collision">
      <pose>0.155 0 -0.4 0 0 0</pose>
      <geometry>
        <mesh>
          <uri>model://solar_panel/meshes/solar_panel.obj</uri>
          <submesh>
            <name>Button</name>
          </submesh>
          <scale>0.001 0.001 0.001</scale>
        </mesh>
      </geometry>
      <surface>
        <contact>
          <ode>
            <kp>1e5</kp>
            <kd>1</kd>
            <max_vel>0.1</max_vel>
            <min_depth>0.0015</min_depth>
          </ode>
        </contact>
      </surface>
    </collision>
    <visual name="visual">
      <pose>0.155 0 -0.4 0 0 0</pose>
      <geometry>
        <mesh>
          <uri>model://solar_panel/meshes/solar_panel.obj</uri>
          <submesh>
            <name>Button</name>
          </submesh>
          <scale>0.001 0.001 0.001</scale>
        </mesh>
      </geometry>
    </visual>

    <sensor name="button_contact" type="contact">
      <contact>
        <collision>collision</collision>
      </contact>
    </sensor>

  </link>

  

  <joint name="base_panel_01" type="revolute">
    <pose>0 0.0455 0.095 0 0 0</pose>
    <parent>base</parent>
    <child>panel_01</child>
    <axis>
      <xyz>1 0 0</xyz>
      <limit>
       <lower>-1.5707963267948966</lower>
       <upper>0</upper>
      </limit>
      <dynamics>
        <damping>0.1</damping>
      </dynamics>
    </axis>
  </joint>

  <joint name="base_panel_02" type="revolute">
    <pose>0 -0.0455 0.095 0 0 0</pose>
    <parent>base</parent>
    <child>panel_02</child>
    <axis>
      <xyz>1 0 0</xyz>
      <limit>
       <lower>0</lower>
       <upper>1.5707963267948966</upper>
      </limit>
      <dynamics>
        <damping>0.1</damping>
      </dynamics>
    </axis>
  </joint>

  <joint name="panel_01_panel_small_01" type="revolute">
    <parent>panel_01</parent>
    <child>panel_small_01</child>
    <axis>
      <xyz>0 0 1</xyz>
      <limit>
       <lower>0</lower>
       <upper>3.141592653589793</upper>
      </limit>
      <dynamics>
        <damping>0.1</damping>
      </dynamics>
    </axis>
  </joint>

  <joint name="panel_02_panel_small_02" type="revolute">
    <parent>panel_02</parent>
    <child>panel_small_02</child>
    <axis>
      <xyz>0 0 1</xyz>
      <limit>
       <lower>-3.141592653589793</lower>
       <upper>0</upper>
      </limit>
      <dynamics>
        <damping>0.1</damping>
      </dynamics>
    </axis>
  </joint>

  <joint name="panel_01_panel_small_03" type="revolute">
    <parent>panel_01</parent>
    <child>panel_small_03</child>
    <axis>
      <xyz>0 0 1</xyz>
      <limit>
       <lower>-3.141592653589793</lower>
       <upper>0</upper>
      </limit>
      <dynamics>
        <damping>0.1</damping>
      </dynamics>
    </axis>
  </joint>

  <joint name="panel_02_panel_small_04" type="revolute">
    <parent>panel_02</parent>
    <child>panel_small_04</child>
    <axis>
      <xyz>0 0 1</xyz>
      <limit>
       <lower>0</lower>
       <upper>3.141592653589793</upper>
      </limit>
      <dynamics>
        <damping>0.1</damping>
      </dynamics>
    </axis>
  </joint>

  
  <joint name="button" type="prismatic">
    <pose>0 0 0.005 0 0 0</pose>
    <parent>panel_01</parent>
    <child>button</child>
    <axis>
      <xyz>0 0 1</xyz>
      <limit>
       <lower>-0.005</lower>
       <upper>0</upper>
      </limit>
      <dynamics>
        <damping>10</damping>
        <spring_stiffness>1000</spring_stiffness>
        <spring_reference>0</spring_reference>
      </dynamics>
    </axis>
  </joint>

  <joint name="lock_1" type="fixed">
    <parent>panel_01</parent>
    <child>panel_02</child>
  </joint>

  <joint name="lock_2" type="fixed">
    <parent>panel_small_01</parent>
    <child>panel_small_03</child>
  </joint>

  <joint name="lock_3" type="fixed">
    <parent>panel_small_02</parent>
    <child>panel_small_04</child>
  </joint>

  <plugin name="solar_panel_plugin" filename="libSolarPanelPlugin.so">
  </plugin>

  <plugin name="touch_valkyrie_panel" filename="libTouchPlugin.so">
    <sensor>base_sensor</sensor>
    <sensor>panel1_sensor</sensor>
    <sensor>panel2_sensor</sensor>
    <target>valkyrie</target>
    <time>0.5</time>
    <namespace>task2/checkpoint1</namespace>
  </plugin>

</model>


    <!-- Walkway -->
    <include>
      <name>walkway_7</name>
      <pose>
      9.43721173033363
      5.9277579937325635
      -0.052151
      0
      0
      2.356194490192345
      </pose>
      <uri>model://walkway_metal_45</uri>
    </include>


    <!-- Walkway -->
    <include>
      <name>walkway_8</name>
      <pose>
      9.43721173033363
      5.9277579937325635
      -0.052151
      0
      0
      -0.7853981633974485
      </pose>
      <uri>model://walkway_metal_straight</uri>
    </include>


    <!-- Bling -->
    <include>
      <name>mars_rock_1_8</name>
      <pose>
      9.154369017859011
      7.288231440735482
      0
      0
      0
      0.7853981633974481
      </pose>
      <uri>model://mars_rock_1</uri>
    </include>


    <!-- Bling -->
    <include>
      <name>mars_rock_2_9</name>
      <pose>
      10.868395855455201
      5.57420460313929
      0
      0
      0
      -2.3561944901923453
      </pose>
      <uri>model://mars_rock_2</uri>
    </include>


    <!-- Walkway -->
    <include>
      <name>walkway_9</name>
      <pose>
      11.053137336481301
      8.306609520481295
      -0.052151
      0
      0
      3.141592653589793
      </pose>
      <uri>model://walkway_metal_45</uri>
    </include>


    <!-- Solar Array -->
    

    <include>
      <pose>
        12.051646066133902
        6.561340790828694
        0
        0
        0
        -2.3561944901923453
      </pose>
      <uri>model://solar_array</uri>
    </include>

    <!-- Cable -->
    

    

<model name="solar_panel_cable">

  <self_collide>true</self_collide>

  <pose>
    12.193067422371211
    5.854234009642147
    0.85
    0
    0
    2.356194490192345
  </pose>

  <link name="link_0">
    <inertial>
      <mass>0.05</mass>
      <inertia>
        <ixx>0.0001</ixx>
        <iyy>0.0001</iyy>
        <izz>0.0001</izz>
      </inertia>
    </inertial>
    <visual name="visual">
      <geometry>
        <sphere>
          <radius>0.02</radius>
        </sphere>
      </geometry>
      <material>
        <ambient>0 0 0 1</ambient>
        <emissive>0 0 0 1</emissive>
        <diffuse>0 0 0 1</diffuse>
        <specular>1 1 1 1</specular>
      </material>
    </visual>
  </link>

  

  <link name="link_1">
    <pose>0.0 0 0 0 1.5707963267948966 0.9424777960769379</pose>
    <inertial>
      <pose>0 0 0.05 0 0 0</pose>
      <mass>0.05</mass>
      <inertia>
        <ixx>0.0001</ixx>
        <iyy>0.0001</iyy>
        <izz>0.0001</izz>
      </inertia>
    </inertial>
    <collision name="cylinder">
      <pose>0 0 0.05 0 0 0</pose>
      <geometry>
        <cylinder>
          <length>0.1</length>
          <radius>0.01</radius>
        </cylinder>
      </geometry>
      <surface>
        <contact>
          <ode>
            <kp>1e5</kp>
            <kd>1</kd>
            <max_vel>0.1</max_vel>
            <min_depth>0.0015</min_depth>
          </ode>
        </contact>
        <friction>
          <ode>
            <mu>1.0</mu>
            <mu2>1.0</mu2>
          </ode>
        </friction>
      </surface>
    </collision>
    <collision name="sphere">
      <geometry>
        <sphere>
          <radius>0.01</radius>
        </sphere>
      </geometry>
      <surface>
        <contact>
          <ode>
            <kp>1e5</kp>
            <kd>1</kd>
            <max_vel>0.1</max_vel>
            <min_depth>0.0015</min_depth>
          </ode>
        </contact>
        <friction>
          <ode>
            <mu>1.0</mu>
            <mu2>1.0</mu2>
          </ode>
        </friction>
      </surface>
    </collision>
    <visual name="cylinder">
      <pose>0 0 0.05 0 0 0</pose>
      <geometry>
        <cylinder>
          <length>0.1</length>
          <radius>0.01</radius>
        </cylinder>
      </geometry>
      <material>
        <ambient>0 0 0 1</ambient>
        <emissive>0 0 0 1</emissive>
        <diffuse>0.1 0.1 0.1 1</diffuse>
        <specular>1 1 1 1</specular>
      </material>
    </visual>
    <visual name="sphere">
      <geometry>
        <sphere>
          <radius>0.01</radius>
        </sphere>
      </geometry>
      <material>
        <ambient>0 0 0 1</ambient>
        <emissive>0 0 0 1</emissive>
        <diffuse>0.1 0.1 0.1 1</diffuse>
        <specular>1 1 1 1</specular>
      </material>
    </visual>

    

  </link>

  <joint name="joint_1" type="universal">
    <child>link_1</child>
    <parent>link_0</parent>
    <axis>
      <xyz>0 1 0</xyz>
      <limit>
        <lower>-1.5707963267948966</lower>
        <upper>1.5707963267948966</upper>
      </limit>
    </axis>
    <axis2>
      <xyz>-1 0 0</xyz>
      <limit>
        <lower>-1.5707963267948966</lower>
        <upper>1.5707963267948966</upper>
      </limit>
    </axis2>
    <physics>
      <ode>
        <cfm_damping>1</cfm_damping>
      </ode>
    </physics>
  </joint>

  

  <link name="link_2">
    <pose>0.058778525229247314 0.08090169943749476 0 0 1.5707963267948966 -0.9424777960769379</pose>
    <inertial>
      <pose>0 0 0.05 0 0 0</pose>
      <mass>0.05</mass>
      <inertia>
        <ixx>0.0001</ixx>
        <iyy>0.0001</iyy>
        <izz>0.0001</izz>
      </inertia>
    </inertial>
    <collision name="cylinder">
      <pose>0 0 0.05 0 0 0</pose>
      <geometry>
        <cylinder>
          <length>0.1</length>
          <radius>0.01</radius>
        </cylinder>
      </geometry>
      <surface>
        <contact>
          <ode>
            <kp>1e5</kp>
            <kd>1</kd>
            <max_vel>0.1</max_vel>
            <min_depth>0.0015</min_depth>
          </ode>
        </contact>
        <friction>
          <ode>
            <mu>1.0</mu>
            <mu2>1.0</mu2>
          </ode>
        </friction>
      </surface>
    </collision>
    <collision name="sphere">
      <geometry>
        <sphere>
          <radius>0.01</radius>
        </sphere>
      </geometry>
      <surface>
        <contact>
          <ode>
            <kp>1e5</kp>
            <kd>1</kd>
            <max_vel>0.1</max_vel>
            <min_depth>0.0015</min_depth>
          </ode>
        </contact>
        <friction>
          <ode>
            <mu>1.0</mu>
            <mu2>1.0</mu2>
          </ode>
        </friction>
      </surface>
    </collision>
    <visual name="cylinder">
      <pose>0 0 0.05 0 0 0</pose>
      <geometry>
        <cylinder>
          <length>0.1</length>
          <radius>0.01</radius>
        </cylinder>
      </geometry>
      <material>
        <ambient>0 0 0 1</ambient>
        <emissive>0 0 0 1</emissive>
        <diffuse>0.1 0.1 0.1 1</diffuse>
        <specular>1 1 1 1</specular>
      </material>
    </visual>
    <visual name="sphere">
      <geometry>
        <sphere>
          <radius>0.01</radius>
        </sphere>
      </geometry>
      <material>
        <ambient>0 0 0 1</ambient>
        <emissive>0 0 0 1</emissive>
        <diffuse>0.1 0.1 0.1 1</diffuse>
        <specular>1 1 1 1</specular>
      </material>
    </visual>

    

  </link>

  <joint name="joint_2" type="universal">
    <child>link_2</child>
    <parent>link_1</parent>
    <axis>
      <xyz>0 1 0</xyz>
      <limit>
        <lower>-1.5707963267948966</lower>
        <upper>1.5707963267948966</upper>
      </limit>
    </axis>
    <axis2>
      <xyz>-1 0 0</xyz>
      <limit>
        <lower>-1.5707963267948966</lower>
        <upper>1.5707963267948966</upper>
      </limit>
    </axis2>
    <physics>
      <ode>
        <cfm_damping>1</cfm_damping>
      </ode>
    </physics>
  </joint>

  

  <link name="link_3">
    <pose>0.11755705045849463 0 0 0 1.5707963267948966 -0.9424777960769379</pose>
    <inertial>
      <pose>0 0 0.05 0 0 0</pose>
      <mass>0.05</mass>
      <inertia>
        <ixx>0.0001</ixx>
        <iyy>0.0001</iyy>
        <izz>0.0001</izz>
      </inertia>
    </inertial>
    <collision name="cylinder">
      <pose>0 0 0.05 0 0 0</pose>
      <geometry>
        <cylinder>
          <length>0.1</length>
          <radius>0.01</radius>
        </cylinder>
      </geometry>
      <surface>
        <contact>
          <ode>
            <kp>1e5</kp>
            <kd>1</kd>
            <max_vel>0.1</max_vel>
            <min_depth>0.0015</min_depth>
          </ode>
        </contact>
        <friction>
          <ode>
            <mu>1.0</mu>
            <mu2>1.0</mu2>
          </ode>
        </friction>
      </surface>
    </collision>
    <collision name="sphere">
      <geometry>
        <sphere>
          <radius>0.01</radius>
        </sphere>
      </geometry>
      <surface>
        <contact>
          <ode>
            <kp>1e5</kp>
            <kd>1</kd>
            <max_vel>0.1</max_vel>
            <min_depth>0.0015</min_depth>
          </ode>
        </contact>
        <friction>
          <ode>
            <mu>1.0</mu>
            <mu2>1.0</mu2>
          </ode>
        </friction>
      </surface>
    </collision>
    <visual name="cylinder">
      <pose>0 0 0.05 0 0 0</pose>
      <geometry>
        <cylinder>
          <length>0.1</length>
          <radius>0.01</radius>
        </cylinder>
      </geometry>
      <material>
        <ambient>0 0 0 1</ambient>
        <emissive>0 0 0 1</emissive>
        <diffuse>0.1 0.1 0.1 1</diffuse>
        <specular>1 1 1 1</specular>
      </material>
    </visual>
    <visual name="sphere">
      <geometry>
        <sphere>
          <radius>0.01</radius>
        </sphere>
      </geometry>
      <material>
        <ambient>0 0 0 1</ambient>
        <emissive>0 0 0 1</emissive>
        <diffuse>0.1 0.1 0.1 1</diffuse>
        <specular>1 1 1 1</specular>
      </material>
    </visual>

    

  </link>

  <joint name="joint_3" type="universal">
    <child>link_3</child>
    <parent>link_2</parent>
    <axis>
      <xyz>0 1 0</xyz>
      <limit>
        <lower>-1.5707963267948966</lower>
        <upper>1.5707963267948966</upper>
      </limit>
    </axis>
    <axis2>
      <xyz>-1 0 0</xyz>
      <limit>
        <lower>-1.5707963267948966</lower>
        <upper>1.5707963267948966</upper>
      </limit>
    </axis2>
    <physics>
      <ode>
        <cfm_damping>1</cfm_damping>
      </ode>
    </physics>
  </joint>

  

  <link name="link_4">
    <pose>0.17633557568774197 -0.08090169943749476 0 0 1.5707963267948966 0.9424777960769379</pose>
    <inertial>
      <pose>0 0 0.05 0 0 0</pose>
      <mass>0.05</mass>
      <inertia>
        <ixx>0.0001</ixx>
        <iyy>0.0001</iyy>
        <izz>0.0001</izz>
      </inertia>
    </inertial>
    <collision name="cylinder">
      <pose>0 0 0.05 0 0 0</pose>
      <geometry>
        <cylinder>
          <length>0.1</length>
          <radius>0.01</radius>
        </cylinder>
      </geometry>
      <surface>
        <contact>
          <ode>
            <kp>1e5</kp>
            <kd>1</kd>
            <max_vel>0.1</max_vel>
            <min_depth>0.0015</min_depth>
          </ode>
        </contact>
        <friction>
          <ode>
            <mu>1.0</mu>
            <mu2>1.0</mu2>
          </ode>
        </friction>
      </surface>
    </collision>
    <collision name="sphere">
      <geometry>
        <sphere>
          <radius>0.01</radius>
        </sphere>
      </geometry>
      <surface>
        <contact>
          <ode>
            <kp>1e5</kp>
            <kd>1</kd>
            <max_vel>0.1</max_vel>
            <min_depth>0.0015</min_depth>
          </ode>
        </contact>
        <friction>
          <ode>
            <mu>1.0</mu>
            <mu2>1.0</mu2>
          </ode>
        </friction>
      </surface>
    </collision>
    <visual name="cylinder">
      <pose>0 0 0.05 0 0 0</pose>
      <geometry>
        <cylinder>
          <length>0.1</length>
          <radius>0.01</radius>
        </cylinder>
      </geometry>
      <material>
        <ambient>0 0 0 1</ambient>
        <emissive>0 0 0 1</emissive>
        <diffuse>0.1 0.1 0.1 1</diffuse>
        <specular>1 1 1 1</specular>
      </material>
    </visual>
    <visual name="sphere">
      <geometry>
        <sphere>
          <radius>0.01</radius>
        </sphere>
      </geometry>
      <material>
        <ambient>0 0 0 1</ambient>
        <emissive>0 0 0 1</emissive>
        <diffuse>0.1 0.1 0.1 1</diffuse>
        <specular>1 1 1 1</specular>
      </material>
    </visual>

    

  </link>

  <joint name="joint_4" type="universal">
    <child>link_4</child>
    <parent>link_3</parent>
    <axis>
      <xyz>0 1 0</xyz>
      <limit>
        <lower>-1.5707963267948966</lower>
        <upper>1.5707963267948966</upper>
      </limit>
    </axis>
    <axis2>
      <xyz>-1 0 0</xyz>
      <limit>
        <lower>-1.5707963267948966</lower>
        <upper>1.5707963267948966</upper>
      </limit>
    </axis2>
    <physics>
      <ode>
        <cfm_damping>1</cfm_damping>
      </ode>
    </physics>
  </joint>

  

  <link name="link_5">
    <pose>0.23511410091698925 0 0 0 1.5707963267948966 0.9424777960769379</pose>
    <inertial>
      <pose>0 0 0.05 0 0 0</pose>
      <mass>0.05</mass>
      <inertia>
        <ixx>0.0001</ixx>
        <iyy>0.0001</iyy>
        <izz>0.0001</izz>
      </inertia>
    </inertial>
    <collision name="cylinder">
      <pose>0 0 0.05 0 0 0</pose>
      <geometry>
        <cylinder>
          <length>0.1</length>
          <radius>0.01</radius>
        </cylinder>
      </geometry>
      <surface>
        <contact>
          <ode>
            <kp>1e5</kp>
            <kd>1</kd>
            <max_vel>0.1</max_vel>
            <min_depth>0.0015</min_depth>
          </ode>
        </contact>
        <friction>
          <ode>
            <mu>1.0</mu>
            <mu2>1.0</mu2>
          </ode>
        </friction>
      </surface>
    </collision>
    <collision name="sphere">
      <geometry>
        <sphere>
          <radius>0.01</radius>
        </sphere>
      </geometry>
      <surface>
        <contact>
          <ode>
            <kp>1e5</kp>
            <kd>1</kd>
            <max_vel>0.1</max_vel>
            <min_depth>0.0015</min_depth>
          </ode>
        </contact>
        <friction>
          <ode>
            <mu>1.0</mu>
            <mu2>1.0</mu2>
          </ode>
        </friction>
      </surface>
    </collision>
    <visual name="cylinder">
      <pose>0 0 0.05 0 0 0</pose>
      <geometry>
        <cylinder>
          <length>0.1</length>
          <radius>0.01</radius>
        </cylinder>
      </geometry>
      <material>
        <ambient>0 0 0 1</ambient>
        <emissive>0 0 0 1</emissive>
        <diffuse>0.1 0.1 0.1 1</diffuse>
        <specular>1 1 1 1</specular>
      </material>
    </visual>
    <visual name="sphere">
      <geometry>
        <sphere>
          <radius>0.01</radius>
        </sphere>
      </geometry>
      <material>
        <ambient>0 0 0 1</ambient>
        <emissive>0 0 0 1</emissive>
        <diffuse>0.1 0.1 0.1 1</diffuse>
        <specular>1 1 1 1</specular>
      </material>
    </visual>

    

  </link>

  <joint name="joint_5" type="universal">
    <child>link_5</child>
    <parent>link_4</parent>
    <axis>
      <xyz>0 1 0</xyz>
      <limit>
        <lower>-1.5707963267948966</lower>
        <upper>1.5707963267948966</upper>
      </limit>
    </axis>
    <axis2>
      <xyz>-1 0 0</xyz>
      <limit>
        <lower>-1.5707963267948966</lower>
        <upper>1.5707963267948966</upper>
      </limit>
    </axis2>
    <physics>
      <ode>
        <cfm_damping>1</cfm_damping>
      </ode>
    </physics>
  </joint>

  

  <link name="link_6">
    <pose>0.29389262614623657 0.08090169943749476 0 0 1.5707963267948966 -0.9424777960769379</pose>
    <inertial>
      <pose>0 0 0.05 0 0 0</pose>
      <mass>0.05</mass>
      <inertia>
        <ixx>0.0001</ixx>
        <iyy>0.0001</iyy>
        <izz>0.0001</izz>
      </inertia>
    </inertial>
    <collision name="cylinder">
      <pose>0 0 0.05 0 0 0</pose>
      <geometry>
        <cylinder>
          <length>0.1</length>
          <radius>0.01</radius>
        </cylinder>
      </geometry>
      <surface>
        <contact>
          <ode>
            <kp>1e5</kp>
            <kd>1</kd>
            <max_vel>0.1</max_vel>
            <min_depth>0.0015</min_depth>
          </ode>
        </contact>
        <friction>
          <ode>
            <mu>1.0</mu>
            <mu2>1.0</mu2>
          </ode>
        </friction>
      </surface>
    </collision>
    <collision name="sphere">
      <geometry>
        <sphere>
          <radius>0.01</radius>
        </sphere>
      </geometry>
      <surface>
        <contact>
          <ode>
            <kp>1e5</kp>
            <kd>1</kd>
            <max_vel>0.1</max_vel>
            <min_depth>0.0015</min_depth>
          </ode>
        </contact>
        <friction>
          <ode>
            <mu>1.0</mu>
            <mu2>1.0</mu2>
          </ode>
        </friction>
      </surface>
    </collision>
    <visual name="cylinder">
      <pose>0 0 0.05 0 0 0</pose>
      <geometry>
        <cylinder>
          <length>0.1</length>
          <radius>0.01</radius>
        </cylinder>
      </geometry>
      <material>
        <ambient>0 0 0 1</ambient>
        <emissive>0 0 0 1</emissive>
        <diffuse>0.1 0.1 0.1 1</diffuse>
        <specular>1 1 1 1</specular>
      </material>
    </visual>
    <visual name="sphere">
      <geometry>
        <sphere>
          <radius>0.01</radius>
        </sphere>
      </geometry>
      <material>
        <ambient>0 0 0 1</ambient>
        <emissive>0 0 0 1</emissive>
        <diffuse>0.1 0.1 0.1 1</diffuse>
        <specular>1 1 1 1</specular>
      </material>
    </visual>

    

  </link>

  <joint name="joint_6" type="universal">
    <child>link_6</child>
    <parent>link_5</parent>
    <axis>
      <xyz>0 1 0</xyz>
      <limit>
        <lower>-1.5707963267948966</lower>
        <upper>1.5707963267948966</upper>
      </limit>
    </axis>
    <axis2>
      <xyz>-1 0 0</xyz>
      <limit>
        <lower>-1.5707963267948966</lower>
        <upper>1.5707963267948966</upper>
      </limit>
    </axis2>
    <physics>
      <ode>
        <cfm_damping>1</cfm_damping>
      </ode>
    </physics>
  </joint>

  

  <link name="link_7">
    <pose>0.35267115137548394 0 0 0 1.5707963267948966 -0.9424777960769379</pose>
    <inertial>
      <pose>0 0 0.05 0 0 0</pose>
      <mass>0.05</mass>
      <inertia>
        <ixx>0.0001</ixx>
        <iyy>0.0001</iyy>
        <izz>0.0001</izz>
      </inertia>
    </inertial>
    <collision name="cylinder">
      <pose>0 0 0.05 0 0 0</pose>
      <geometry>
        <cylinder>
          <length>0.1</length>
          <radius>0.01</radius>
        </cylinder>
      </geometry>
      <surface>
        <contact>
          <ode>
            <kp>1e5</kp>
            <kd>1</kd>
            <max_vel>0.1</max_vel>
            <min_depth>0.0015</min_depth>
          </ode>
        </contact>
        <friction>
          <ode>
            <mu>1.0</mu>
            <mu2>1.0</mu2>
          </ode>
        </friction>
      </surface>
    </collision>
    <collision name="sphere">
      <geometry>
        <sphere>
          <radius>0.01</radius>
        </sphere>
      </geometry>
      <surface>
        <contact>
          <ode>
            <kp>1e5</kp>
            <kd>1</kd>
            <max_vel>0.1</max_vel>
            <min_depth>0.0015</min_depth>
          </ode>
        </contact>
        <friction>
          <ode>
            <mu>1.0</mu>
            <mu2>1.0</mu2>
          </ode>
        </friction>
      </surface>
    </collision>
    <visual name="cylinder">
      <pose>0 0 0.05 0 0 0</pose>
      <geometry>
        <cylinder>
          <length>0.1</length>
          <radius>0.01</radius>
        </cylinder>
      </geometry>
      <material>
        <ambient>0 0 0 1</ambient>
        <emissive>0 0 0 1</emissive>
        <diffuse>0.1 0.1 0.1 1</diffuse>
        <specular>1 1 1 1</specular>
      </material>
    </visual>
    <visual name="sphere">
      <geometry>
        <sphere>
          <radius>0.01</radius>
        </sphere>
      </geometry>
      <material>
        <ambient>0 0 0 1</ambient>
        <emissive>0 0 0 1</emissive>
        <diffuse>0.1 0.1 0.1 1</diffuse>
        <specular>1 1 1 1</specular>
      </material>
    </visual>

    

  </link>

  <joint name="joint_7" type="universal">
    <child>link_7</child>
    <parent>link_6</parent>
    <axis>
      <xyz>0 1 0</xyz>
      <limit>
        <lower>-1.5707963267948966</lower>
        <upper>1.5707963267948966</upper>
      </limit>
    </axis>
    <axis2>
      <xyz>-1 0 0</xyz>
      <limit>
        <lower>-1.5707963267948966</lower>
        <upper>1.5707963267948966</upper>
      </limit>
    </axis2>
    <physics>
      <ode>
        <cfm_damping>1</cfm_damping>
      </ode>
    </physics>
  </joint>

  

  <link name="link_8">
    <pose>0.41144967660473125 -0.08090169943749476 0 0 1.5707963267948966 0.9424777960769379</pose>
    <inertial>
      <pose>0 0 0.05 0 0 0</pose>
      <mass>0.05</mass>
      <inertia>
        <ixx>0.0001</ixx>
        <iyy>0.0001</iyy>
        <izz>0.0001</izz>
      </inertia>
    </inertial>
    <collision name="cylinder">
      <pose>0 0 0.05 0 0 0</pose>
      <geometry>
        <cylinder>
          <length>0.1</length>
          <radius>0.01</radius>
        </cylinder>
      </geometry>
      <surface>
        <contact>
          <ode>
            <kp>1e5</kp>
            <kd>1</kd>
            <max_vel>0.1</max_vel>
            <min_depth>0.0015</min_depth>
          </ode>
        </contact>
        <friction>
          <ode>
            <mu>1.0</mu>
            <mu2>1.0</mu2>
          </ode>
        </friction>
      </surface>
    </collision>
    <collision name="sphere">
      <geometry>
        <sphere>
          <radius>0.01</radius>
        </sphere>
      </geometry>
      <surface>
        <contact>
          <ode>
            <kp>1e5</kp>
            <kd>1</kd>
            <max_vel>0.1</max_vel>
            <min_depth>0.0015</min_depth>
          </ode>
        </contact>
        <friction>
          <ode>
            <mu>1.0</mu>
            <mu2>1.0</mu2>
          </ode>
        </friction>
      </surface>
    </collision>
    <visual name="cylinder">
      <pose>0 0 0.05 0 0 0</pose>
      <geometry>
        <cylinder>
          <length>0.1</length>
          <radius>0.01</radius>
        </cylinder>
      </geometry>
      <material>
        <ambient>0 0 0 1</ambient>
        <emissive>0 0 0 1</emissive>
        <diffuse>0.1 0.1 0.1 1</diffuse>
        <specular>1 1 1 1</specular>
      </material>
    </visual>
    <visual name="sphere">
      <geometry>
        <sphere>
          <radius>0.01</radius>
        </sphere>
      </geometry>
      <material>
        <ambient>0 0 0 1</ambient>
        <emissive>0 0 0 1</emissive>
        <diffuse>0.1 0.1 0.1 1</diffuse>
        <specular>1 1 1 1</specular>
      </material>
    </visual>

    

  </link>

  <joint name="joint_8" type="universal">
    <child>link_8</child>
    <parent>link_7</parent>
    <axis>
      <xyz>0 1 0</xyz>
      <limit>
        <lower>-1.5707963267948966</lower>
        <upper>1.5707963267948966</upper>
      </limit>
    </axis>
    <axis2>
      <xyz>-1 0 0</xyz>
      <limit>
        <lower>-1.5707963267948966</lower>
        <upper>1.5707963267948966</upper>
      </limit>
    </axis2>
    <physics>
      <ode>
        <cfm_damping>1</cfm_damping>
      </ode>
    </physics>
  </joint>

  

  <link name="link_9">
    <pose>0.4702282018339785 0 0 0 1.5707963267948966 0.9424777960769379</pose>
    <inertial>
      <pose>0 0 0.05 0 0 0</pose>
      <mass>0.05</mass>
      <inertia>
        <ixx>0.0001</ixx>
        <iyy>0.0001</iyy>
        <izz>0.0001</izz>
      </inertia>
    </inertial>
    <collision name="cylinder">
      <pose>0 0 0.05 0 0 0</pose>
      <geometry>
        <cylinder>
          <length>0.1</length>
          <radius>0.01</radius>
        </cylinder>
      </geometry>
      <surface>
        <contact>
          <ode>
            <kp>1e5</kp>
            <kd>1</kd>
            <max_vel>0.1</max_vel>
            <min_depth>0.0015</min_depth>
          </ode>
        </contact>
        <friction>
          <ode>
            <mu>1.0</mu>
            <mu2>1.0</mu2>
          </ode>
        </friction>
      </surface>
    </collision>
    <collision name="sphere">
      <geometry>
        <sphere>
          <radius>0.01</radius>
        </sphere>
      </geometry>
      <surface>
        <contact>
          <ode>
            <kp>1e5</kp>
            <kd>1</kd>
            <max_vel>0.1</max_vel>
            <min_depth>0.0015</min_depth>
          </ode>
        </contact>
        <friction>
          <ode>
            <mu>1.0</mu>
            <mu2>1.0</mu2>
          </ode>
        </friction>
      </surface>
    </collision>
    <visual name="cylinder">
      <pose>0 0 0.05 0 0 0</pose>
      <geometry>
        <cylinder>
          <length>0.1</length>
          <radius>0.01</radius>
        </cylinder>
      </geometry>
      <material>
        <ambient>0 0 0 1</ambient>
        <emissive>0 0 0 1</emissive>
        <diffuse>0.1 0.1 0.1 1</diffuse>
        <specular>1 1 1 1</specular>
      </material>
    </visual>
    <visual name="sphere">
      <geometry>
        <sphere>
          <radius>0.01</radius>
        </sphere>
      </geometry>
      <material>
        <ambient>0 0 0 1</ambient>
        <emissive>0 0 0 1</emissive>
        <diffuse>0.1 0.1 0.1 1</diffuse>
        <specular>1 1 1 1</specular>
      </material>
    </visual>

    

  </link>

  <joint name="joint_9" type="universal">
    <child>link_9</child>
    <parent>link_8</parent>
    <axis>
      <xyz>0 1 0</xyz>
      <limit>
        <lower>-1.5707963267948966</lower>
        <upper>1.5707963267948966</upper>
      </limit>
    </axis>
    <axis2>
      <xyz>-1 0 0</xyz>
      <limit>
        <lower>-1.5707963267948966</lower>
        <upper>1.5707963267948966</upper>
      </limit>
    </axis2>
    <physics>
      <ode>
        <cfm_damping>1</cfm_damping>
      </ode>
    </physics>
  </joint>

  

  <link name="link_10">
    <pose>0.5290067270632258 0.08090169943749476 0 0 1.5707963267948966 -0.9424777960769379</pose>
    <inertial>
      <pose>0 0 0.05 0 0 0</pose>
      <mass>0.05</mass>
      <inertia>
        <ixx>0.0001</ixx>
        <iyy>0.0001</iyy>
        <izz>0.0001</izz>
      </inertia>
    </inertial>
    <collision name="cylinder">
      <pose>0 0 0.05 0 0 0</pose>
      <geometry>
        <cylinder>
          <length>0.1</length>
          <radius>0.01</radius>
        </cylinder>
      </geometry>
      <surface>
        <contact>
          <ode>
            <kp>1e5</kp>
            <kd>1</kd>
            <max_vel>0.1</max_vel>
            <min_depth>0.0015</min_depth>
          </ode>
        </contact>
        <friction>
          <ode>
            <mu>1.0</mu>
            <mu2>1.0</mu2>
          </ode>
        </friction>
      </surface>
    </collision>
    <collision name="sphere">
      <geometry>
        <sphere>
          <radius>0.01</radius>
        </sphere>
      </geometry>
      <surface>
        <contact>
          <ode>
            <kp>1e5</kp>
            <kd>1</kd>
            <max_vel>0.1</max_vel>
            <min_depth>0.0015</min_depth>
          </ode>
        </contact>
        <friction>
          <ode>
            <mu>1.0</mu>
            <mu2>1.0</mu2>
          </ode>
        </friction>
      </surface>
    </collision>
    <visual name="cylinder">
      <pose>0 0 0.05 0 0 0</pose>
      <geometry>
        <cylinder>
          <length>0.1</length>
          <radius>0.01</radius>
        </cylinder>
      </geometry>
      <material>
        <ambient>0 0 0 1</ambient>
        <emissive>0 0 0 1</emissive>
        <diffuse>0.1 0.1 0.1 1</diffuse>
        <specular>1 1 1 1</specular>
      </material>
    </visual>
    <visual name="sphere">
      <geometry>
        <sphere>
          <radius>0.01</radius>
        </sphere>
      </geometry>
      <material>
        <ambient>0 0 0 1</ambient>
        <emissive>0 0 0 1</emissive>
        <diffuse>0.1 0.1 0.1 1</diffuse>
        <specular>1 1 1 1</specular>
      </material>
    </visual>

    

  </link>

  <joint name="joint_10" type="universal">
    <child>link_10</child>
    <parent>link_9</parent>
    <axis>
      <xyz>0 1 0</xyz>
      <limit>
        <lower>-1.5707963267948966</lower>
        <upper>1.5707963267948966</upper>
      </limit>
    </axis>
    <axis2>
      <xyz>-1 0 0</xyz>
      <limit>
        <lower>-1.5707963267948966</lower>
        <upper>1.5707963267948966</upper>
      </limit>
    </axis2>
    <physics>
      <ode>
        <cfm_damping>1</cfm_damping>
      </ode>
    </physics>
  </joint>

  

  <link name="link_11">
    <pose>0.5877852522924731 0 0 0 1.5707963267948966 -0.9424777960769379</pose>
    <inertial>
      <pose>0 0 0.05 0 0 0</pose>
      <mass>0.05</mass>
      <inertia>
        <ixx>0.0001</ixx>
        <iyy>0.0001</iyy>
        <izz>0.0001</izz>
      </inertia>
    </inertial>
    <collision name="cylinder">
      <pose>0 0 0.05 0 0 0</pose>
      <geometry>
        <cylinder>
          <length>0.1</length>
          <radius>0.01</radius>
        </cylinder>
      </geometry>
      <surface>
        <contact>
          <ode>
            <kp>1e5</kp>
            <kd>1</kd>
            <max_vel>0.1</max_vel>
            <min_depth>0.0015</min_depth>
          </ode>
        </contact>
        <friction>
          <ode>
            <mu>1.0</mu>
            <mu2>1.0</mu2>
          </ode>
        </friction>
      </surface>
    </collision>
    <collision name="sphere">
      <geometry>
        <sphere>
          <radius>0.01</radius>
        </sphere>
      </geometry>
      <surface>
        <contact>
          <ode>
            <kp>1e5</kp>
            <kd>1</kd>
            <max_vel>0.1</max_vel>
            <min_depth>0.0015</min_depth>
          </ode>
        </contact>
        <friction>
          <ode>
            <mu>1.0</mu>
            <mu2>1.0</mu2>
          </ode>
        </friction>
      </surface>
    </collision>
    <visual name="cylinder">
      <pose>0 0 0.05 0 0 0</pose>
      <geometry>
        <cylinder>
          <length>0.1</length>
          <radius>0.01</radius>
        </cylinder>
      </geometry>
      <material>
        <ambient>0 0 0 1</ambient>
        <emissive>0 0 0 1</emissive>
        <diffuse>0.1 0.1 0.1 1</diffuse>
        <specular>1 1 1 1</specular>
      </material>
    </visual>
    <visual name="sphere">
      <geometry>
        <sphere>
          <radius>0.01</radius>
        </sphere>
      </geometry>
      <material>
        <ambient>0 0 0 1</ambient>
        <emissive>0 0 0 1</emissive>
        <diffuse>0.1 0.1 0.1 1</diffuse>
        <specular>1 1 1 1</specular>
      </material>
    </visual>

    

  </link>

  <joint name="joint_11" type="universal">
    <child>link_11</child>
    <parent>link_10</parent>
    <axis>
      <xyz>0 1 0</xyz>
      <limit>
        <lower>-1.5707963267948966</lower>
        <upper>1.5707963267948966</upper>
      </limit>
    </axis>
    <axis2>
      <xyz>-1 0 0</xyz>
      <limit>
        <lower>-1.5707963267948966</lower>
        <upper>1.5707963267948966</upper>
      </limit>
    </axis2>
    <physics>
      <ode>
        <cfm_damping>1</cfm_damping>
      </ode>
    </physics>
  </joint>

  

  <link name="link_12">
    <pose>0.6465637775217205 -0.08090169943749476 0 0 1.5707963267948966 0.9424777960769379</pose>
    <inertial>
      <pose>0 0 0.05 0 0 0</pose>
      <mass>0.05</mass>
      <inertia>
        <ixx>0.0001</ixx>
        <iyy>0.0001</iyy>
        <izz>0.0001</izz>
      </inertia>
    </inertial>
    <collision name="cylinder">
      <pose>0 0 0.05 0 0 0</pose>
      <geometry>
        <cylinder>
          <length>0.1</length>
          <radius>0.01</radius>
        </cylinder>
      </geometry>
      <surface>
        <contact>
          <ode>
            <kp>1e5</kp>
            <kd>1</kd>
            <max_vel>0.1</max_vel>
            <min_depth>0.0015</min_depth>
          </ode>
        </contact>
        <friction>
          <ode>
            <mu>1.0</mu>
            <mu2>1.0</mu2>
          </ode>
        </friction>
      </surface>
    </collision>
    <collision name="sphere">
      <geometry>
        <sphere>
          <radius>0.01</radius>
        </sphere>
      </geometry>
      <surface>
        <contact>
          <ode>
            <kp>1e5</kp>
            <kd>1</kd>
            <max_vel>0.1</max_vel>
            <min_depth>0.0015</min_depth>
          </ode>
        </contact>
        <friction>
          <ode>
            <mu>1.0</mu>
            <mu2>1.0</mu2>
          </ode>
        </friction>
      </surface>
    </collision>
    <visual name="cylinder">
      <pose>0 0 0.05 0 0 0</pose>
      <geometry>
        <cylinder>
          <length>0.1</length>
          <radius>0.01</radius>
        </cylinder>
      </geometry>
      <material>
        <ambient>0 0 0 1</ambient>
        <emissive>0 0 0 1</emissive>
        <diffuse>0.1 0.1 0.1 1</diffuse>
        <specular>1 1 1 1</specular>
      </material>
    </visual>
    <visual name="sphere">
      <geometry>
        <sphere>
          <radius>0.01</radius>
        </sphere>
      </geometry>
      <material>
        <ambient>0 0 0 1</ambient>
        <emissive>0 0 0 1</emissive>
        <diffuse>0.1 0.1 0.1 1</diffuse>
        <specular>1 1 1 1</specular>
      </material>
    </visual>

    

  </link>

  <joint name="joint_12" type="universal">
    <child>link_12</child>
    <parent>link_11</parent>
    <axis>
      <xyz>0 1 0</xyz>
      <limit>
        <lower>-1.5707963267948966</lower>
        <upper>1.5707963267948966</upper>
      </limit>
    </axis>
    <axis2>
      <xyz>-1 0 0</xyz>
      <limit>
        <lower>-1.5707963267948966</lower>
        <upper>1.5707963267948966</upper>
      </limit>
    </axis2>
    <physics>
      <ode>
        <cfm_damping>1</cfm_damping>
      </ode>
    </physics>
  </joint>

  

  <link name="link_13">
    <pose>0.7053423027509679 0 0 0 1.5707963267948966 0.9424777960769379</pose>
    <inertial>
      <pose>0 0 0.05 0 0 0</pose>
      <mass>0.05</mass>
      <inertia>
        <ixx>0.0001</ixx>
        <iyy>0.0001</iyy>
        <izz>0.0001</izz>
      </inertia>
    </inertial>
    <collision name="cylinder">
      <pose>0 0 0.05 0 0 0</pose>
      <geometry>
        <cylinder>
          <length>0.1</length>
          <radius>0.01</radius>
        </cylinder>
      </geometry>
      <surface>
        <contact>
          <ode>
            <kp>1e5</kp>
            <kd>1</kd>
            <max_vel>0.1</max_vel>
            <min_depth>0.0015</min_depth>
          </ode>
        </contact>
        <friction>
          <ode>
            <mu>1.0</mu>
            <mu2>1.0</mu2>
          </ode>
        </friction>
      </surface>
    </collision>
    <collision name="sphere">
      <geometry>
        <sphere>
          <radius>0.01</radius>
        </sphere>
      </geometry>
      <surface>
        <contact>
          <ode>
            <kp>1e5</kp>
            <kd>1</kd>
            <max_vel>0.1</max_vel>
            <min_depth>0.0015</min_depth>
          </ode>
        </contact>
        <friction>
          <ode>
            <mu>1.0</mu>
            <mu2>1.0</mu2>
          </ode>
        </friction>
      </surface>
    </collision>
    <visual name="cylinder">
      <pose>0 0 0.05 0 0 0</pose>
      <geometry>
        <cylinder>
          <length>0.1</length>
          <radius>0.01</radius>
        </cylinder>
      </geometry>
      <material>
        <ambient>0 0 0 1</ambient>
        <emissive>0 0 0 1</emissive>
        <diffuse>0.1 0.1 0.1 1</diffuse>
        <specular>1 1 1 1</specular>
      </material>
    </visual>
    <visual name="sphere">
      <geometry>
        <sphere>
          <radius>0.01</radius>
        </sphere>
      </geometry>
      <material>
        <ambient>0 0 0 1</ambient>
        <emissive>0 0 0 1</emissive>
        <diffuse>0.1 0.1 0.1 1</diffuse>
        <specular>1 1 1 1</specular>
      </material>
    </visual>

    

  </link>

  <joint name="joint_13" type="universal">
    <child>link_13</child>
    <parent>link_12</parent>
    <axis>
      <xyz>0 1 0</xyz>
      <limit>
        <lower>-1.5707963267948966</lower>
        <upper>1.5707963267948966</upper>
      </limit>
    </axis>
    <axis2>
      <xyz>-1 0 0</xyz>
      <limit>
        <lower>-1.5707963267948966</lower>
        <upper>1.5707963267948966</upper>
      </limit>
    </axis2>
    <physics>
      <ode>
        <cfm_damping>1</cfm_damping>
      </ode>
    </physics>
  </joint>

  

  <link name="link_14">
    <pose>0.7641208279802151 0.08090169943749476 0 0 1.5707963267948966 -0.9424777960769379</pose>
    <inertial>
      <pose>0 0 0.05 0 0 0</pose>
      <mass>0.05</mass>
      <inertia>
        <ixx>0.0001</ixx>
        <iyy>0.0001</iyy>
        <izz>0.0001</izz>
      </inertia>
    </inertial>
    <collision name="cylinder">
      <pose>0 0 0.05 0 0 0</pose>
      <geometry>
        <cylinder>
          <length>0.1</length>
          <radius>0.01</radius>
        </cylinder>
      </geometry>
      <surface>
        <contact>
          <ode>
            <kp>1e5</kp>
            <kd>1</kd>
            <max_vel>0.1</max_vel>
            <min_depth>0.0015</min_depth>
          </ode>
        </contact>
        <friction>
          <ode>
            <mu>1.0</mu>
            <mu2>1.0</mu2>
          </ode>
        </friction>
      </surface>
    </collision>
    <collision name="sphere">
      <geometry>
        <sphere>
          <radius>0.01</radius>
        </sphere>
      </geometry>
      <surface>
        <contact>
          <ode>
            <kp>1e5</kp>
            <kd>1</kd>
            <max_vel>0.1</max_vel>
            <min_depth>0.0015</min_depth>
          </ode>
        </contact>
        <friction>
          <ode>
            <mu>1.0</mu>
            <mu2>1.0</mu2>
          </ode>
        </friction>
      </surface>
    </collision>
    <visual name="cylinder">
      <pose>0 0 0.05 0 0 0</pose>
      <geometry>
        <cylinder>
          <length>0.1</length>
          <radius>0.01</radius>
        </cylinder>
      </geometry>
      <material>
        <ambient>0 0 0 1</ambient>
        <emissive>0 0 0 1</emissive>
        <diffuse>0.1 0.1 0.1 1</diffuse>
        <specular>1 1 1 1</specular>
      </material>
    </visual>
    <visual name="sphere">
      <geometry>
        <sphere>
          <radius>0.01</radius>
        </sphere>
      </geometry>
      <material>
        <ambient>0 0 0 1</ambient>
        <emissive>0 0 0 1</emissive>
        <diffuse>0.1 0.1 0.1 1</diffuse>
        <specular>1 1 1 1</specular>
      </material>
    </visual>

    

  </link>

  <joint name="joint_14" type="universal">
    <child>link_14</child>
    <parent>link_13</parent>
    <axis>
      <xyz>0 1 0</xyz>
      <limit>
        <lower>-1.5707963267948966</lower>
        <upper>1.5707963267948966</upper>
      </limit>
    </axis>
    <axis2>
      <xyz>-1 0 0</xyz>
      <limit>
        <lower>-1.5707963267948966</lower>
        <upper>1.5707963267948966</upper>
      </limit>
    </axis2>
    <physics>
      <ode>
        <cfm_damping>1</cfm_damping>
      </ode>
    </physics>
  </joint>

  

  <link name="link_15">
    <pose>0.8228993532094625 0 0 0 1.5707963267948966 -0.9424777960769379</pose>
    <inertial>
      <pose>0 0 0.05 0 0 0</pose>
      <mass>0.05</mass>
      <inertia>
        <ixx>0.0001</ixx>
        <iyy>0.0001</iyy>
        <izz>0.0001</izz>
      </inertia>
    </inertial>
    <collision name="cylinder">
      <pose>0 0 0.05 0 0 0</pose>
      <geometry>
        <cylinder>
          <length>0.1</length>
          <radius>0.01</radius>
        </cylinder>
      </geometry>
      <surface>
        <contact>
          <ode>
            <kp>1e5</kp>
            <kd>1</kd>
            <max_vel>0.1</max_vel>
            <min_depth>0.0015</min_depth>
          </ode>
        </contact>
        <friction>
          <ode>
            <mu>1.0</mu>
            <mu2>1.0</mu2>
          </ode>
        </friction>
      </surface>
    </collision>
    <collision name="sphere">
      <geometry>
        <sphere>
          <radius>0.01</radius>
        </sphere>
      </geometry>
      <surface>
        <contact>
          <ode>
            <kp>1e5</kp>
            <kd>1</kd>
            <max_vel>0.1</max_vel>
            <min_depth>0.0015</min_depth>
          </ode>
        </contact>
        <friction>
          <ode>
            <mu>1.0</mu>
            <mu2>1.0</mu2>
          </ode>
        </friction>
      </surface>
    </collision>
    <visual name="cylinder">
      <pose>0 0 0.05 0 0 0</pose>
      <geometry>
        <cylinder>
          <length>0.1</length>
          <radius>0.01</radius>
        </cylinder>
      </geometry>
      <material>
        <ambient>0 0 0 1</ambient>
        <emissive>0 0 0 1</emissive>
        <diffuse>0.1 0.1 0.1 1</diffuse>
        <specular>1 1 1 1</specular>
      </material>
    </visual>
    <visual name="sphere">
      <geometry>
        <sphere>
          <radius>0.01</radius>
        </sphere>
      </geometry>
      <material>
        <ambient>0 0 0 1</ambient>
        <emissive>0 0 0 1</emissive>
        <diffuse>0.1 0.1 0.1 1</diffuse>
        <specular>1 1 1 1</specular>
      </material>
    </visual>

    

  </link>

  <joint name="joint_15" type="universal">
    <child>link_15</child>
    <parent>link_14</parent>
    <axis>
      <xyz>0 1 0</xyz>
      <limit>
        <lower>-1.5707963267948966</lower>
        <upper>1.5707963267948966</upper>
      </limit>
    </axis>
    <axis2>
      <xyz>-1 0 0</xyz>
      <limit>
        <lower>-1.5707963267948966</lower>
        <upper>1.5707963267948966</upper>
      </limit>
    </axis2>
    <physics>
      <ode>
        <cfm_damping>1</cfm_damping>
      </ode>
    </physics>
  </joint>

  

  <link name="link_16">
    <pose>0.8816778784387097 -0.08090169943749476 0 0 1.5707963267948966 0.9424777960769379</pose>
    <inertial>
      <pose>0 0 0.05 0 0 0</pose>
      <mass>0.05</mass>
      <inertia>
        <ixx>0.0001</ixx>
        <iyy>0.0001</iyy>
        <izz>0.0001</izz>
      </inertia>
    </inertial>
    <collision name="cylinder">
      <pose>0 0 0.05 0 0 0</pose>
      <geometry>
        <cylinder>
          <length>0.1</length>
          <radius>0.01</radius>
        </cylinder>
      </geometry>
      <surface>
        <contact>
          <ode>
            <kp>1e5</kp>
            <kd>1</kd>
            <max_vel>0.1</max_vel>
            <min_depth>0.0015</min_depth>
          </ode>
        </contact>
        <friction>
          <ode>
            <mu>1.0</mu>
            <mu2>1.0</mu2>
          </ode>
        </friction>
      </surface>
    </collision>
    <collision name="sphere">
      <geometry>
        <sphere>
          <radius>0.01</radius>
        </sphere>
      </geometry>
      <surface>
        <contact>
          <ode>
            <kp>1e5</kp>
            <kd>1</kd>
            <max_vel>0.1</max_vel>
            <min_depth>0.0015</min_depth>
          </ode>
        </contact>
        <friction>
          <ode>
            <mu>1.0</mu>
            <mu2>1.0</mu2>
          </ode>
        </friction>
      </surface>
    </collision>
    <visual name="cylinder">
      <pose>0 0 0.05 0 0 0</pose>
      <geometry>
        <cylinder>
          <length>0.1</length>
          <radius>0.01</radius>
        </cylinder>
      </geometry>
      <material>
        <ambient>0 0 0 1</ambient>
        <emissive>0 0 0 1</emissive>
        <diffuse>0.1 0.1 0.1 1</diffuse>
        <specular>1 1 1 1</specular>
      </material>
    </visual>
    <visual name="sphere">
      <geometry>
        <sphere>
          <radius>0.01</radius>
        </sphere>
      </geometry>
      <material>
        <ambient>0 0 0 1</ambient>
        <emissive>0 0 0 1</emissive>
        <diffuse>0.1 0.1 0.1 1</diffuse>
        <specular>1 1 1 1</specular>
      </material>
    </visual>

    

    <collision name="plug_collision">
      <pose>0 0 0.1 0 0 0</pose>
      <geometry>
        <cylinder>
          <length>0.010000000000000002</length>
          <radius>0.011000000000000001</radius>
        </cylinder>
      </geometry>
      <surface>
        <contact>
          <ode>
            <kp>1e5</kp>
            <kd>1</kd>
            <max_vel>0.1</max_vel>
            <min_depth>0.0015</min_depth>
          </ode>
        </contact>
        <friction>
          <ode>
            <mu>1.0</mu>
            <mu2>1.0</mu2>
          </ode>
        </friction>
      </surface>
    </collision>

    <visual name="plug_visual">
      <pose>0 0 0.1 0 0 0</pose>
      <geometry>
        <cylinder>
          <length>0.010000000000000002</length>
          <radius>0.011000000000000001</radius>
        </cylinder>
      </geometry>
      <material>
        <ambient>0 0 0.3 1</ambient>
        <emissive>0 0 0.2 1</emissive>
        <diffuse>0 0 0.1 1</diffuse>
        <specular>1 1 1 1</specular>
      </material>
    </visual>

    <sensor name="tip_sensor" type="contact">
      <contact>
        <collision>plug_collision</collision>
        <collision>cylinder</collision>
        <collision>sphere</collision>
      </contact>
    </sensor>

    

  </link>

  <joint name="joint_16" type="universal">
    <child>link_16</child>
    <parent>link_15</parent>
    <axis>
      <xyz>0 1 0</xyz>
      <limit>
        <lower>-1.5707963267948966</lower>
        <upper>1.5707963267948966</upper>
      </limit>
    </axis>
    <axis2>
      <xyz>-1 0 0</xyz>
      <limit>
        <lower>-1.5707963267948966</lower>
        <upper>1.5707963267948966</upper>
      </limit>
    </axis2>
    <physics>
      <ode>
        <cfm_damping>1</cfm_damping>
      </ode>
    </physics>
  </joint>

  

  <joint name="world" type="fixed">
    <child>link_0</child>
    <parent>world</parent>
  </joint>

  <plugin name="touch_valkyrie_cable" filename="libTouchPlugin.so">
    <sensor>tip_sensor</sensor>
    <target>valkyrie</target>
    <time>0.5</time>
    <namespace>task2/checkpoint4</namespace>
  </plugin>

</model>


    <!-- Checkpoint 2 - Box plugin -->
    

    <plugin name="boxT2CP2" filename="libBoxContainsPlugin.so">
      <entity>solar_panel</entity>
      <namespace>task2/checkpoint2</namespace>
      <pose>
        12.051646066133902
        6.561340790828694
        0.9
        0
        0
        -2.3561944901923453
      </pose>
      <size>1.47 0.95 0.45</size>
    </plugin>

    <!-- Bling -->
    

    <!-- Walkway -->
    <include>
      <name>walkway_10</name>
      <pose>
      11.053137336481301
      8.306609520481295
      -0.052151
      0
      0
      -3.4450928483976665e-16
      </pose>
      <uri>model://walkway_metal_45</uri>
    </include>


    <!-- Bling -->
    <include>
      <name>mars_rock_3_10</name>
      <pose>
      9.665719877176098
      10.440786979786498
      0
      0
      0
      0.785398163397448
      </pose>
      <uri>model://mars_rock_3</uri>
    </include>


    <!-- Bling -->
    <include>
      <name>mars_crate_long_11</name>
      <pose>
      9.4911373364813
      9.068609520481296
      0
      0
      0
      2.3561944901923444
      </pose>
      <uri>model://mars_crate_long</uri>
    </include>


    <!-- Final Box 2 -->
    <include>
      <name>walkway_11</name>
      <pose>
      12.6702381630096
      10.684974255009594
      -0.052151
      0
      0
      -2.3561944901923453
      </pose>
      <uri>model://walkway_finish_opposite</uri>
    </include>


    <!-- Checkpoint 6 - Box plugin -->
    <plugin name="boxT2CP6" filename="libBoxContainsPlugin.so">
      <entity>valkyrie</entity>
      <namespace>task2/checkpoint6</namespace>
      <pose>
        12.6702381630096
        10.684974255009594
        2.5
        0
        0
        -2.3561944901923453
      </pose>
      <size>3.048 3.048 5</size>
    </plugin>

    <!-- Bling -->
    <include>
      <name>mars_rock_3_12</name>
      <pose>
      14.525686356843101
      8.829526061176093
      0
      0
      0
      -2.3561944901923453
      </pose>
      <uri>model://mars_rock_3</uri>
    </include>


    <!-- Bling -->
    <include>
      <name>mars_rock_3_13</name>
      <pose>
      10.814789969176099
      12.540422448843096
      0
      0
      0
      0.785398163397448
      </pose>
      <uri>model://mars_rock_3</uri>
    </include>


    <!-- /TASK 2 -->
    

    

    <!-- TASK 3 -->

    <!-- Walkway -->
    <include>
      <name>walkway_12</name>
      <pose>
      14.286163769157271
      13.063825781758327
      -0.052151
      0
      0
      3.141592653589793
      </pose>
      <uri>model://walkway_metal_45</uri>
    </include>


    <!-- Walkway -->
    <include>
      <name>walkway_13</name>
      <pose>
      14.286163769157271
      13.063825781758327
      -0.052151
      0
      0
      -3.4450928483976665e-16
      </pose>
      <uri>model://walkway_metal_45</uri>
    </include>


    <!-- Bling -->
    <include>
      <name>mars_rock_3_14</name>
      <pose>
      12.898746309852068
      15.19800324106353
      0
      0
      0
      0.785398163397448
      </pose>
      <uri>model://mars_rock_3</uri>
    </include>


    <!-- Bling -->
    <include>
      <name>mars_rock_1_15</name>
      <pose>
      13.12416376915727
      13.825825781758327
      0
      0
      0
      1.5707963267948961
      </pose>
      <uri>model://mars_rock_1</uri>
    </include>


    <!-- Habitat -->
    

    <!-- TODO: Put the table inside the habitat -->

    <!-- Table -->
    
    <include>
      <pose>
        15.179187251750545
        14.7181131723516
        0
        0
        0
        -0.7853981633974485
      </pose>
      <uri>model://space_table</uri>
    </include>

    <!-- Air leak detector -->
    

    

<model name="air_leak_detector">

  <pose>
    15.179187251750545
    14.7181131723516
    0.79448
    0
    0
    0.7853981633974481
  </pose>

  <link name="base">

    <inertial>
      <pose>
      0
      -0.00063
      0
      0
      0
      0
      </pose>
      <inertia>
        <ixx>0.0006035883333333333</ixx>
        <iyy>0.003206729933333333</iyy>
        <izz>0.003333989666666666</izz>
      </inertia>
      <mass>1.0</mass>
    </inertial>


    <collision name="collision">

      <pose>0 0 -0.026760000000000003 0 0 -1.5707963267948966</pose>

      <geometry>
        <mesh>
          <scale>0.02 0.02 0.02</scale>
          <uri>model://air_leak_detector/meshes/air_leak_detector.obj</uri>
        </mesh>
      </geometry>
      <surface>
        <contact>
          <ode>
            <kp>1e5</kp>
            <kd>1</kd>
            <max_vel>0.1</max_vel>
            <min_depth>0.0015</min_depth>
          </ode>
        </contact>
      </surface>
    </collision>

    <visual name="visual">

      <pose>0 0 -0.026760000000000003 0 0 -1.5707963267948966</pose>

      <geometry>
        <mesh>
          <scale>0.02 0.02 0.02</scale>
          <uri>model://air_leak_detector/meshes/air_leak_detector.obj</uri>
        </mesh>
      </geometry>
    </visual>

    <sensor name="logical_camera" type="logical_camera">

      <logical_camera>
        <near>0.1</near>
        <far>0.5</far>
        <horizontal_fov>0.5235987755982988</horizontal_fov>
        <aspect_ratio>1</aspect_ratio>
      </logical_camera>

      <visualize>true</visualize>
      <always_on>true</always_on>
      <update_rate>10</update_rate>

    </sensor>

  </link>

</model>



    <!-- Leak -->
    

<model name="leak">
  <static>true</static>

  <pose>14.825633861157272 14.364559781758327 0.87 0 0 0</pose>

  <link name="base">

    <visual name="visual">

      <geometry>
        <sphere>
          <radius>0.05</radius>
        </sphere>
      </geometry>

      <material>
        <ambient>1 0 0 1</ambient>
        <emissive>1 0 0 1</emissive>
        <diffuse>1 0 0 1</diffuse>
        <specular>1 1 1 1</specular>
      </material>

      <meta>
        <layer>1</layer>
      </meta>

    </visual>

    <collision name="collision">

      <geometry>
        <sphere>
          <radius>0.05</radius>
        </sphere>
      </geometry>

    </collision>

  </link>

</model>



    <!-- TODO: Put the box inside the habitat -->

    <!-- Checkpoint 8 - Box plugin -->

    <plugin name="boxT3CP8" filename="libBoxContainsPlugin.so">
      <entity>valkyrie</entity>
      <namespace>task3/checkpoint8</namespace>
      <pose>
        14.825633861157272
        14.364559781758327
        2.5
        0
        0
        -0.7853981633974485
      </pose>
      <size>3.048 3.048 5</size>
    </plugin>

    <!-- /TASK 3 -->
    

    <!-- Finals plugin -->
    <plugin name="finals" filename="libFinalsPlugin.so">

      
        <task_1_timeout>1800</task_1_timeout>

        <task_1_checkpoint_2_pose>
          1.9966949400811336
          -0.6506735555415055
          1.1
          0
          0
          -1.570796326794897
        </task_1_checkpoint_2_pose>

        <task_1_checkpoint_3_pose>
          1.9966949400811336
          -0.6506735555415055
          1.1
          0
          0
          -1.570796326794897
        </task_1_checkpoint_3_pose>
      

      
        <task_2_timeout>3600</task_2_timeout>

        <task_2_checkpoint_1_pose>
          4.679995469056598
          2.694731561056596
          1.1
          0
          0
          0.7853981633974481
        </task_2_checkpoint_1_pose>

        <task_2_checkpoint_3_pose>
          11.203117928710045
          7.409868928252551
          1.1
          0
          0
          -0.7853981633974485
        </task_2_checkpoint_3_pose>

        <task_2_checkpoint_4_pose>
          11.203117928710045
          7.409868928252551
          1.1
          0
          0
          -0.7853981633974485
        </task_2_checkpoint_4_pose>

        <task_2_checkpoint_5_pose>
          11.203117928710045
          7.409868928252551
          1.1
          0
          0
          -0.7853981633974485
        </task_2_checkpoint_5_pose>

        <task_2_checkpoint_6_pose>
          11.203117928710045
          7.409868928252551
          1.1
          0
          0
          -0.7853981633974485
        </task_2_checkpoint_6_pose>
      

      
        <task_3_timeout>7200</task_3_timeout>

        <task_3_checkpoint_1_pose>
          12.6702381630096
          10.684974255009594
          1.1
          0
          0
          -2.3561944901923453
        </task_3_checkpoint_1_pose>

        <task_3_checkpoint_2_pose>
          12.6702381630096
          10.684974255009594
          1.1
          0
          0
          -2.3561944901923453
        </task_3_checkpoint_2_pose>

        <task_3_checkpoint_3_pose>
          12.6702381630096
          10.684974255009594
          1.1
          0
          0
          -2.3561944901923453
        </task_3_checkpoint_3_pose>

        <task_3_checkpoint_4_pose>
          12.6702381630096
          10.684974255009594
          1.1
          0
          0
          -2.3561944901923453
        </task_3_checkpoint_4_pose>

        <task_3_checkpoint_5_pose>
          12.6702381630096
          10.684974255009594
          1.1
          0
          0
          -2.3561944901923453
        </task_3_checkpoint_5_pose>

        <task_3_checkpoint_6_pose>
          12.6702381630096
          10.684974255009594
          1.1
          0
          0
          -2.3561944901923453
        </task_3_checkpoint_6_pose>

        <task_3_checkpoint_7_pose>
          12.6702381630096
          10.684974255009594
          1.1
          0
          0
          -2.3561944901923453
        </task_3_checkpoint_7_pose>

        <task_3_checkpoint_8_pose>
          12.6702381630096
          10.684974255009594
          1.1
          0
          0
          -2.3561944901923453
        </task_3_checkpoint_8_pose>
      

    </plugin>

  </world>
</sdf>
