<?xml version="1.0" ?>

<sdf version="1.6">
  <world name="SRC_finals">

    <physics type="ode">
      <real_time_update_rate>1000.0</real_time_update_rate>
      <max_step_size>0.001</max_step_size>
      <real_time_factor>1</real_time_factor>
      <ode>
        <solver>
          <type>quick</type>
          <iters>150</iters>
          <precon_iters>0</precon_iters>
          <sor>1.400000</sor>
          <use_dynamic_moi_rescaling>1</use_dynamic_moi_rescaling>
        </solver>
        <constraints>
          <cfm>0.000000</cfm>
          <erp>0.800000</erp>
          <contact_max_correcting_vel>2000.000000</contact_max_correcting_vel>
          <contact_surface_layer>0.01000</contact_surface_layer>
        </constraints>
      </ode>
    </physics>

    <!-- GUI -->
    <gui fullscreen='0'>
      <camera name='user_camera'>
        <pose>-4.1 -0.2 3.3 0 0.37 0</pose>
      </camera>
    </gui>

    <!-- Scene -->
    <scene>
      <background>0.968627451 0.690196078 0.384313725 1.0</background>
      <grid>0</grid>
      <origin_visual>0</origin_visual>
    </scene>

    <!-- A global light source -->
    <light type="directional" name="sun">
      <cast_shadows>true</cast_shadows>
      <pose>0 0 1000 -0.9763763250810842 -1.0828660042812976 0</pose>
      <diffuse>0.8 0.8 0.8 1</diffuse>
      <specular>0.2 0.2 0.2 1</specular>
      <attenuation>
        <range>1000</range>
        <constant>0.9</constant>
        <linear>0.01</linear>
        <quadratic>0.001</quadratic>
      </attenuation>
      <direction>-0.5 0.1 -0.9</direction>
    </light>

    <!-- Background -->
    <include>
      <uri>model://heightmap_mars</uri>
    </include>

    <!-- START WALKWAY -->

    <!-- Walkway -->
    <include>
      <name>walkway_1</name>
      <pose>
      -0.3
      0
      -0.052151
      0
      0
      -1.5707963267948968
      </pose>
      <uri>model://walkway_metal_straight</uri>
    </include>


    <!-- Bling -->
    <include>
      <name>mars_crate_long_1</name>
      <pose>
      0.4619999999999998
      -1.5620000000000003
      0
      0
      0
      -2.3561944901923453
      </pose>
      <uri>model://mars_crate_long</uri>
    </include>


    <!-- Bling -->
    <include>
      <name>mars_crate_long_2</name>
      <pose>
      0.46200000000000035
      1.5619999999999998
      0
      0
      0
      0.785398163397448
      </pose>
      <uri>model://mars_crate_long</uri>
    </include>


    

    <!-- TASK 1 -->

    <!-- Walkway -->
    <include>
      <name>walkway_2</name>
      <pose>
      1.224
      -2.7995425828508494e-16
      -0.052151
      0
      0
      -1.5707963267948968
      </pose>
      <uri>model://walkway_metal_straight</uri>
    </include>


    <!-- Satellite -->
    

    

<model name="satellite_dish">

  <pose>
    1.9860000000000007
    2.7619999999999996
    0
    0
    0
    -2.4492935982947064e-16
  </pose>

  <link name="base">
    <inertial>
      <pose>0 -0.6077 0.3193 0 0 0</pose>
      <inertia>
        <ixx>165.1022</ixx>
        <ixy>0</ixy>
        <ixz>0</ixz>
        <iyy>13.8377</iyy>
        <iyz>0</iyz>
        <izz>170.3359</izz>
      </inertia>
      <mass>400</mass>
    </inertial>
    <collision name="collision">
      <geometry>
        <mesh>
          <uri>model://satellite_dish/meshes/satellite_dish.dae</uri>
          <submesh>
            <name>Base</name>
          </submesh>
        </mesh>
      </geometry>
    </collision>
    <visual name="visual">
      <geometry>
        <mesh>
          <uri>model://satellite_dish/meshes/satellite_dish.dae</uri>
          <submesh>
            <name>Base</name>
          </submesh>
        </mesh>
      </geometry>
    </visual>
  </link>

  <link name="pivot">
    <pose>0 0 1.595 0 0 0</pose>
    <inertial>
      <inertia>
        <ixx>0.00073</ixx>
        <ixy>0</ixy>
        <ixz>0</ixz>
        <iyy>0.000598</iyy>
        <iyz>0</iyz>
        <izz>0.00057</izz>
      </inertia>
      <mass>0.82</mass>
    </inertial>
    <collision name="collision">
      <pose>0 0 -1.595 0 0 0</pose>
      <geometry>
        <mesh>
          <uri>model://satellite_dish/meshes/satellite_dish.dae</uri>
          <submesh>
            <name>Pivot</name>
          </submesh>
        </mesh>
      </geometry>
    </collision>
    <visual name="visual">
      <pose>0 0 -1.595 0 0 0</pose>
      <geometry>
        <mesh>
          <uri>model://satellite_dish/meshes/satellite_dish.dae</uri>
          <submesh>
            <name>Pivot</name>
          </submesh>
        </mesh>
      </geometry>
    </visual>
  </link>

  <link name="dish">
    <pose>0 0 1.595 0.43 0 0</pose>
    <inertial>
      <pose>0 0.2 0 0 0 0</pose>
      <inertia>
        <ixx>0.92468</ixx>
        <ixy>0</ixy>
        <ixz>0</ixz>
        <iyy>1.87729</iyy>
        <iyz>0</iyz>
        <izz>0.97826</izz>
      </inertia>
      <mass>17.0</mass>
    </inertial>
    <collision name="collision">
      <pose>0 -0.6519041 -1.451541 -0.43 0 0</pose>
      <geometry>
        <mesh>
          <uri>model://satellite_dish/meshes/satellite_dish.dae</uri>
          <submesh>
            <name>Dish</name>
          </submesh>
        </mesh>
      </geometry>
    </collision>
    <visual name="visual">
      <pose>0 -0.6519041 -1.451541 -0.43 0 0</pose>
      <geometry>
        <mesh>
          <uri>model://satellite_dish/meshes/satellite_dish.dae</uri>
          <submesh>
            <name>Dish</name>
          </submesh>
        </mesh>
      </geometry>
    </visual>
  </link>

  <link name="wheel_yaw">
    <pose>-0.2 -1.725 0.91 0.52 0 0</pose>
    <inertial>
      <inertia>
        <ixx>0.0123</ixx>
        <ixy>0</ixy>
        <ixz>0</ixz>
        <iyy>0.01295</iyy>
        <iyz>0</iyz>
        <izz>0.02500</izz>
      </inertia>
      <mass>2.0</mass>
    </inertial>
    <collision name="collision">
      <pose>0.2 1.060 -1.64 -0.52 0 0</pose>
      <geometry>
        <mesh>
          <uri>model://satellite_dish/meshes/satellite_dish.dae</uri>
          <submesh>
            <name>Wheel_01</name>
          </submesh>
        </mesh>
      </geometry>
    </collision>
    <collision name="collision_sphere">
      <pose>0.002 -0.123 0.082 0 0 0</pose>
      <geometry>
        <sphere>
          <radius>0.029</radius>
        </sphere>
      </geometry>
    </collision>
    <collision name="collision_cylinder">
      <pose>0.002 -0.122 0.025 0 0 0</pose>
      <geometry>
        <cylinder>
          <length>0.06</length>
          <radius>0.0125</radius>
        </cylinder>
      </geometry>
    </collision>
    <visual name="visual">
      <pose>0.2 1.060 -1.64 -0.52 0 0</pose>
      <geometry>
        <mesh>
          <uri>model://satellite_dish/meshes/satellite_dish.dae</uri>
          <submesh>
            <name>Wheel_01</name>
          </submesh>
        </mesh>
      </geometry>
    </visual>
  </link>

  <link name="wheel_pitch">
    <pose>0.2 -1.725 0.91 0.52 0 0</pose>
    <inertial>
      <inertia>
        <ixx>0.0123</ixx>
        <ixy>0</ixy>
        <ixz>0</ixz>
        <iyy>0.01295</iyy>
        <iyz>0</iyz>
        <izz>0.02500</izz>
      </inertia>
      <mass>2.0</mass>
    </inertial>
    <collision name="collision">
      <pose>-0.2 1.060 -1.64 -0.52 0 0</pose>
      <geometry>
        <mesh>
          <uri>model://satellite_dish/meshes/satellite_dish.dae</uri>
          <submesh>
            <name>Wheel_02</name>
          </submesh>
        </mesh>
      </geometry>
    </collision>
    <collision name="collision_sphere">
      <pose>-0.002 -0.123 0.082 0 0 0</pose>
      <geometry>
        <sphere>
          <radius>0.029</radius>
        </sphere>
      </geometry>
    </collision>
    <collision name="collision_cylinder">
      <pose>-0.002 -0.122 0.025 0 0 0</pose>
      <geometry>
        <cylinder>
          <length>0.06</length>
          <radius>0.0125</radius>
        </cylinder>
      </geometry>
    </collision>
    <visual name="visual">
      <pose>-0.2 1.060 -1.64 -0.52 0 0</pose>
      <geometry>
        <mesh>
          <uri>model://satellite_dish/meshes/satellite_dish.dae</uri>
          <submesh>
            <name>Wheel_02</name>
          </submesh>
        </mesh>
      </geometry>
    </visual>
  </link>

  <joint name="dish_yaw" type="revolute">
    <parent>base</parent>
    <child>pivot</child>
    <axis>
      <xyz>0 0 1</xyz>
      <dynamics>
        <damping>1000</damping>
      </dynamics>
    </axis>
  </joint>

  <joint name="dish_pitch" type="revolute">
    <parent>pivot</parent>
    <child>dish</child>
    <axis>
      <xyz>1 0 0</xyz>
      <limit>
        <lower>-0.2</lower>
        <upper>1.57</upper>
      </limit>
      <dynamics>
        <damping>100</damping>
      </dynamics>
    </axis>
  </joint>

  <joint name="wheel_yaw" type="revolute">
    <parent>base</parent>
    <child>wheel_yaw</child>
    <axis>
      <xyz>0 0 1</xyz>
      <dynamics>
        <friction>2.0790153313505306</friction>
      </dynamics>
    </axis>
  </joint>

  <joint name="wheel_pitch" type="revolute">
    <parent>base</parent>
    <child>wheel_pitch</child>
    <axis>
      <xyz>0 0 1</xyz>
      <dynamics>
        <friction>2.7711241266723015</friction>
      </dynamics>
    </axis>
  </joint>

  <joint name="satellite_world" type="fixed">
    <parent>world</parent>
    <child>base</child>
  </joint>

  <plugin name="satellite_plugin" filename="libSatellitePlugin.so">

    <yaw_ratio>0.1</yaw_ratio>
    <yaw_pid>1000 0 10</yaw_pid>
    <yaw_target>-0.5742926633280723</yaw_target>

    <pitch_ratio>0.1</pitch_ratio>
    <pitch_pid>1000 100 10</pitch_pid>
    <pitch_target>1.0487358924979095</pitch_target>

    <!-- Tolerance in degrees -->
    <tolerance>5</tolerance>

    <!-- Target time to hold position in seconds -->
    <time>5</time>

    <topic>/task1/checkpoint2/satellite</topic>
    <frequency>100</frequency>

  </plugin>

</model>


    <!-- Checkpoint 1 - Box plugin -->
    

    <plugin name="boxT1CP1" filename="libBoxContainsPlugin.so">
      <entity>valkyrie</entity>
      <namespace>task1/checkpoint1</namespace>
      <pose>
        1.9860000000000002
        0.5619999999999994
        2.5
        0
        0
        1.5707963267948963
      </pose>
      <size>1 1 5</size>
    </plugin>

    <!-- Bling -->
    <include>
      <name>mars_crate_long_3</name>
      <pose>
      1.9859999999999998
      -1.5620000000000005
      0
      0
      0
      -2.3561944901923453
      </pose>
      <uri>model://mars_crate_long</uri>
    </include>


    <!-- Walkway -->
    <include>
      <name>walkway_3</name>
      <pose>
      2.748
      -5.599085165701699e-16
      -0.052151
      0
      0
      -1.5707963267948968
      </pose>
      <uri>model://walkway_metal_45</uri>
    </include>


    <!-- Bling -->
    <include>
      <name>mars_rock_1_4</name>
      <pose>
      4.38720271247462
      0.8924427124746181
      0
      0
      0
      -0.7853981633974485
      </pose>
      <uri>model://mars_rock_1</uri>
    </include>


    <!-- Bling -->
    <include>
      <name>mars_rock_3_5</name>
      <pose>
      3.5100000000000007
      1.8619999999999994
      0
      0
      0
      -2.4492935982947064e-16
      </pose>
      <uri>model://mars_rock_3</uri>
    </include>


    <!-- Final box 1 -->
    <include>
      <name>walkway_4</name>
      <pose>
      5.126364734528298
      -1.6171008265282993
      -0.052151
      0
      0
      2.356194490192345
      </pose>
      <uri>model://walkway_finish_opposite</uri>
    </include>


    <!-- Checkpoint 3 - Box plugin -->
    <plugin name="boxT1CP3" filename="libBoxContainsPlugin.so">
      <entity>valkyrie</entity>
      <namespace>task1/checkpoint3</namespace>
      <pose>
        5.126364734528298
        -1.6171008265282993
        2.5
        0
        0
        2.356194490192345
      </pose>
      <size>3.048 3.048 5</size>
    </plugin>

    <!-- Bling -->
    <include>
      <name>mars_rock_2_6</name>
      <pose>
      3.6951806094067257
      -3.0482849516498716
      0
      0
      0
      2.356194490192345
      </pose>
      <uri>model://mars_rock_2</uri>
    </include>


    <!-- Bling -->
    <include>
      <name>mars_crate_7</name>
      <pose>
      6.486838181531216
      -0.2566273795253821
      0
      0
      0
      -0.7853981633974485
      </pose>
      <uri>model://mars_crate</uri>
    </include>


    <!-- /TASK 1 -->
    

    

    <!-- TASK 2 -->

    <!-- Walkway -->
    <include>
      <name>walkway_5</name>
      <pose>
      6.203995469056597
      -2.6947315610565976
      -0.052151
      0
      0
      -2.356194490192345
      </pose>
      <uri>model://walkway_metal_straight</uri>
    </include>


    <!-- Bling -->
    <include>
      <name>mars_rock_2_8</name>
      <pose>
      7.63517959417817
      -2.3411781704633237
      0
      0
      0
      -0.7853981633974484
      </pose>
      <uri>model://mars_rock_2</uri>
    </include>


    <!-- Bling -->
    <include>
      <name>mars_rock_3_9</name>
      <pose>
      5.4261780097513945
      -4.550179754890098
      0
      0
      0
      2.356194490192345
      </pose>
      <uri>model://mars_rock_3</uri>
    </include>


    <!-- Walkway -->
    <include>
      <name>walkway_6</name>
      <pose>
      7.281626203584896
      -3.7723622955848963
      -0.052151
      0
      0
      -2.356194490192345
      </pose>
      <uri>model://walkway_metal_straight</uri>
    </include>


    <!-- Rover -->
    

    <!-- Bling -->
    <include>
      <name>mars_rock_3_10</name>
      <pose>
      9.137074397418397
      -2.994544836279694
      0
      0
      0
      -0.7853981633974484
      </pose>
      <uri>model://mars_rock_3</uri>
    </include>


    <!-- Walkway -->
    <include>
      <name>walkway_7</name>
      <pose>
      9.436887672641493
      -4.849993030113195
      -0.052151
      0
      0
      2.356194490192345
      </pose>
      <uri>model://walkway_metal_90</uri>
    </include>


    <!-- Solar Array -->
    

    <!-- Bling -->
    <include>
      <name>mars_rock_2_11</name>
      <pose>
      9.790441063234766
      -6.281177155234768
      0
      0
      0
      -2.356194490192345
      </pose>
      <uri>model://mars_rock_2</uri>
    </include>


    <!-- Walkway -->
    <include>
      <name>walkway_8</name>
      <pose>
      9.436887672641493
      -4.849993030113195
      -0.052151
      0
      0
      -0.7853981633974485
      </pose>
      <uri>model://walkway_metal_45</uri>
    </include>


    <!-- Final Box 2 -->
    <include>
      <name>walkway_9</name>
      <pose>
      12.262108464861928
      -4.311698158493823
      -0.052151
      0
      0
      3.141592653589793
      </pose>
      <uri>model://walkway_finish_opposite</uri>
    </include>


    <!-- Checkpoint 6 - Box plugin -->
    <plugin name="boxT2CP6" filename="libBoxContainsPlugin.so">
      <entity>valkyrie</entity>
      <namespace>task2/checkpoint6</namespace>
      <pose>
        12.262108464861928
        -4.311698158493823
        2.5
        0
        0
        3.141592653589793
      </pose>
      <size>3.048 3.048 5</size>
    </plugin>

    <!-- Bling -->
    <include>
      <name>mars_crate_12</name>
      <pose>
      12.262108464861928
      -2.3876981584938233
      0
      0
      0
      -2.83276944882399e-16
      </pose>
      <uri>model://mars_crate</uri>
    </include>


    <!-- Bling -->
    <include>
      <name>mars_rock_2_13</name>
      <pose>
      12.262108464861928
      -6.335698158493823
      0
      0
      0
      3.141592653589793
      </pose>
      <uri>model://mars_rock_2</uri>
    </include>


    <!-- /TASK 2 -->
    

    

    <!-- TASK 3 -->

    <!-- Walkway -->
    <include>
      <name>walkway_10</name>
      <pose>
      15.08684246486193
      -3.7722280664938235
      -0.052151
      0
      0
      2.356194490192345
      </pose>
      <uri>model://walkway_metal_45</uri>
    </include>


    <!-- Walkway -->
    <include>
      <name>walkway_11</name>
      <pose>
      15.08684246486193
      -3.7722280664938235
      -0.052151
      0
      0
      -0.7853981633974485
      </pose>
      <uri>model://walkway_metal_45</uri>
    </include>


    <!-- Bling -->
    <include>
      <name>mars_rock_3_14</name>
      <pose>
      14.309025005556727
      -1.9167798726603227
      0
      0
      0
      0.7853981633974481
      </pose>
      <uri>model://mars_rock_3</uri>
    </include>


    <!-- Bling -->
    <include>
      <name>mars_rock_2_15</name>
      <pose>
      15.614881524780795
      -1.8820844189523185
      0
      0
      0
      -2.7755575615628914e-16
      </pose>
      <uri>model://mars_rock_2</uri>
    </include>


    <!-- Habitat -->
    

    <!-- TODO: Put the box inside the habitat -->

    <!-- Checkpoint 8 - Box plugin -->

    <plugin name="boxT3CP8" filename="libBoxContainsPlugin.so">
      <entity>valkyrie</entity>
      <namespace>task3/checkpoint8</namespace>
      <pose>
        15.08684246486193
        -3.7722280664938235
        2.5
        0
        0
        -0.7853981633974485
      </pose>
      <size>3.048 3.048 5</size>
    </plugin>

    <!-- /TASK 3 -->
    

    <!-- Finals plugin -->
    <plugin name="finals" filename="libFinalsPlugin.so">

      
        <task_1_timeout>1800</task_1_timeout>

        <task_1_checkpoint_2_pose>
          1.9860000000000002
          0.5619999999999994
          1.1
          0
          0
          1.5707963267948963
        </task_1_checkpoint_2_pose>

        <task_1_checkpoint_3_pose>
          1.9860000000000002
          0.5619999999999994
          1.1
          0
          0
          1.5707963267948963
        </task_1_checkpoint_3_pose>
      

      
        <task_2_timeout>3600</task_2_timeout>

        <task_2_checkpoint_1_pose>
          5.126364734528298
          -1.6171008265282993
          1.1
          0
          0
          2.356194490192345
        </task_2_checkpoint_1_pose>

        <task_2_checkpoint_2_pose>
          6.203995469056597
          -2.6947315610565976
          1.1
          0
          0
          -2.356194490192345
        </task_2_checkpoint_2_pose>

        <task_2_checkpoint_3_pose>
          6.203995469056597
          -2.6947315610565976
          1.1
          0
          0
          -2.356194490192345
        </task_2_checkpoint_3_pose>

        <task_2_checkpoint_4_pose>
          6.203995469056597
          -2.6947315610565976
          1.1
          0
          0
          -2.356194490192345
        </task_2_checkpoint_4_pose>

        <task_2_checkpoint_5_pose>
          6.203995469056597
          -2.6947315610565976
          1.1
          0
          0
          -2.356194490192345
        </task_2_checkpoint_5_pose>

        <task_2_checkpoint_6_pose>
          6.203995469056597
          -2.6947315610565976
          1.1
          0
          0
          -2.356194490192345
        </task_2_checkpoint_6_pose>
      

      
        <task_3_timeout>7200</task_3_timeout>

        <task_3_checkpoint_1_pose>
          12.262108464861928
          -4.311698158493823
          1.1
          0
          0
          3.141592653589793
        </task_3_checkpoint_1_pose>

        <task_3_checkpoint_2_pose>
          12.262108464861928
          -4.311698158493823
          1.1
          0
          0
          3.141592653589793
        </task_3_checkpoint_2_pose>

        <task_3_checkpoint_3_pose>
          12.262108464861928
          -4.311698158493823
          1.1
          0
          0
          3.141592653589793
        </task_3_checkpoint_3_pose>

        <task_3_checkpoint_4_pose>
          12.262108464861928
          -4.311698158493823
          1.1
          0
          0
          3.141592653589793
        </task_3_checkpoint_4_pose>

        <task_3_checkpoint_5_pose>
          12.262108464861928
          -4.311698158493823
          1.1
          0
          0
          3.141592653589793
        </task_3_checkpoint_5_pose>

        <task_3_checkpoint_6_pose>
          12.262108464861928
          -4.311698158493823
          1.1
          0
          0
          3.141592653589793
        </task_3_checkpoint_6_pose>

        <task_3_checkpoint_7_pose>
          12.262108464861928
          -4.311698158493823
          1.1
          0
          0
          3.141592653589793
        </task_3_checkpoint_7_pose>

        <task_3_checkpoint_8_pose>
          12.262108464861928
          -4.311698158493823
          1.1
          0
          0
          3.141592653589793
        </task_3_checkpoint_8_pose>
      

    </plugin>

  </world>
</sdf>
